WARNING 2016-12-29 14:35:56,745 Not Found: /api
WARNING 2016-12-29 14:35:56,745 Not Found: /api
WARNING 2016-12-29 14:35:57,056 Not Found: /favicon.ico
WARNING 2016-12-29 14:35:57,056 Not Found: /favicon.ico
ERROR 2016-12-29 14:37:49,143 Internal Server Error: /API/job/
Traceback (most recent call last):
  File "C:\Python34\lib\site-packages\django\core\handlers\base.py", line 132, in get_response
    response = wrapped_callback(request, *callback_args, **callback_kwargs)
  File "C:\Python34\lib\site-packages\django\views\decorators\csrf.py", line 58, in wrapped_view
    return view_func(*args, **kwargs)
  File "C:\Python34\lib\site-packages\django\views\generic\base.py", line 71, in view
    return self.dispatch(request, *args, **kwargs)
  File "C:\Python34\lib\site-packages\rest_framework\views.py", line 466, in dispatch
    response = self.handle_exception(exc)
  File "C:\Python34\lib\site-packages\rest_framework\views.py", line 463, in dispatch
    response = handler(request, *args, **kwargs)
  File "C:\Python34\lib\site-packages\rest_framework\generics.py", line 243, in get
    return self.list(request, *args, **kwargs)
  File "C:\uav\model\views.py", line 270, in list
    queryset = Job.objects.filter(user=self.request.user)
  File "C:\Python34\lib\site-packages\django\db\models\manager.py", line 127, in manager_method
    return getattr(self.get_queryset(), name)(*args, **kwargs)
  File "C:\Python34\lib\site-packages\django\db\models\query.py", line 679, in filter
    return self._filter_or_exclude(False, *args, **kwargs)
  File "C:\Python34\lib\site-packages\django\db\models\query.py", line 697, in _filter_or_exclude
    clone.query.add_q(Q(*args, **kwargs))
  File "C:\Python34\lib\site-packages\django\db\models\sql\query.py", line 1304, in add_q
    clause, require_inner = self._add_q(where_part, self.used_aliases)
  File "C:\Python34\lib\site-packages\django\db\models\sql\query.py", line 1331, in _add_q
    current_negated=current_negated, connector=connector, allow_joins=allow_joins)
  File "C:\Python34\lib\site-packages\django\db\models\sql\query.py", line 1194, in build_filter
    lookups, value)
  File "C:\Python34\lib\site-packages\django\db\models\fields\related.py", line 1740, in get_lookup_constraint
    lookup_class(target.get_col(alias, source), val), AND)
  File "C:\Python34\lib\site-packages\django\db\models\lookups.py", line 96, in __init__
    self.rhs = self.get_prep_lookup()
  File "C:\Python34\lib\site-packages\django\db\models\lookups.py", line 134, in get_prep_lookup
    return self.lhs.output_field.get_prep_lookup(self.lookup_name, self.rhs)
  File "C:\Python34\lib\site-packages\django\db\models\fields\__init__.py", line 727, in get_prep_lookup
    return self.get_prep_value(value)
  File "C:\Python34\lib\site-packages\django\db\models\fields\__init__.py", line 985, in get_prep_value
    return int(value)
TypeError: int() argument must be a string, a bytes-like object or a number, not 'AnonymousUser'
ERROR 2016-12-29 14:37:49,143 Internal Server Error: /API/job/
Traceback (most recent call last):
  File "C:\Python34\lib\site-packages\django\core\handlers\base.py", line 132, in get_response
    response = wrapped_callback(request, *callback_args, **callback_kwargs)
  File "C:\Python34\lib\site-packages\django\views\decorators\csrf.py", line 58, in wrapped_view
    return view_func(*args, **kwargs)
  File "C:\Python34\lib\site-packages\django\views\generic\base.py", line 71, in view
    return self.dispatch(request, *args, **kwargs)
  File "C:\Python34\lib\site-packages\rest_framework\views.py", line 466, in dispatch
    response = self.handle_exception(exc)
  File "C:\Python34\lib\site-packages\rest_framework\views.py", line 463, in dispatch
    response = handler(request, *args, **kwargs)
  File "C:\Python34\lib\site-packages\rest_framework\generics.py", line 243, in get
    return self.list(request, *args, **kwargs)
  File "C:\uav\model\views.py", line 270, in list
    queryset = Job.objects.filter(user=self.request.user)
  File "C:\Python34\lib\site-packages\django\db\models\manager.py", line 127, in manager_method
    return getattr(self.get_queryset(), name)(*args, **kwargs)
  File "C:\Python34\lib\site-packages\django\db\models\query.py", line 679, in filter
    return self._filter_or_exclude(False, *args, **kwargs)
  File "C:\Python34\lib\site-packages\django\db\models\query.py", line 697, in _filter_or_exclude
    clone.query.add_q(Q(*args, **kwargs))
  File "C:\Python34\lib\site-packages\django\db\models\sql\query.py", line 1304, in add_q
    clause, require_inner = self._add_q(where_part, self.used_aliases)
  File "C:\Python34\lib\site-packages\django\db\models\sql\query.py", line 1331, in _add_q
    current_negated=current_negated, connector=connector, allow_joins=allow_joins)
  File "C:\Python34\lib\site-packages\django\db\models\sql\query.py", line 1194, in build_filter
    lookups, value)
  File "C:\Python34\lib\site-packages\django\db\models\fields\related.py", line 1740, in get_lookup_constraint
    lookup_class(target.get_col(alias, source), val), AND)
  File "C:\Python34\lib\site-packages\django\db\models\lookups.py", line 96, in __init__
    self.rhs = self.get_prep_lookup()
  File "C:\Python34\lib\site-packages\django\db\models\lookups.py", line 134, in get_prep_lookup
    return self.lhs.output_field.get_prep_lookup(self.lookup_name, self.rhs)
  File "C:\Python34\lib\site-packages\django\db\models\fields\__init__.py", line 727, in get_prep_lookup
    return self.get_prep_value(value)
  File "C:\Python34\lib\site-packages\django\db\models\fields\__init__.py", line 985, in get_prep_value
    return int(value)
TypeError: int() argument must be a string, a bytes-like object or a number, not 'AnonymousUser'
ERROR 2016-12-29 14:38:05,589 Internal Server Error: /API/job/
Traceback (most recent call last):
  File "C:\Python34\lib\site-packages\django\core\handlers\base.py", line 132, in get_response
    response = wrapped_callback(request, *callback_args, **callback_kwargs)
  File "C:\Python34\lib\site-packages\django\views\decorators\csrf.py", line 58, in wrapped_view
    return view_func(*args, **kwargs)
  File "C:\Python34\lib\site-packages\django\views\generic\base.py", line 71, in view
    return self.dispatch(request, *args, **kwargs)
  File "C:\Python34\lib\site-packages\rest_framework\views.py", line 466, in dispatch
    response = self.handle_exception(exc)
  File "C:\Python34\lib\site-packages\rest_framework\views.py", line 463, in dispatch
    response = handler(request, *args, **kwargs)
  File "C:\Python34\lib\site-packages\rest_framework\generics.py", line 243, in get
    return self.list(request, *args, **kwargs)
  File "C:\uav\model\views.py", line 270, in list
    queryset = Job.objects.filter(user=self.request.user)
  File "C:\Python34\lib\site-packages\django\db\models\manager.py", line 127, in manager_method
    return getattr(self.get_queryset(), name)(*args, **kwargs)
  File "C:\Python34\lib\site-packages\django\db\models\query.py", line 679, in filter
    return self._filter_or_exclude(False, *args, **kwargs)
  File "C:\Python34\lib\site-packages\django\db\models\query.py", line 697, in _filter_or_exclude
    clone.query.add_q(Q(*args, **kwargs))
  File "C:\Python34\lib\site-packages\django\db\models\sql\query.py", line 1304, in add_q
    clause, require_inner = self._add_q(where_part, self.used_aliases)
  File "C:\Python34\lib\site-packages\django\db\models\sql\query.py", line 1331, in _add_q
    current_negated=current_negated, connector=connector, allow_joins=allow_joins)
  File "C:\Python34\lib\site-packages\django\db\models\sql\query.py", line 1194, in build_filter
    lookups, value)
  File "C:\Python34\lib\site-packages\django\db\models\fields\related.py", line 1740, in get_lookup_constraint
    lookup_class(target.get_col(alias, source), val), AND)
  File "C:\Python34\lib\site-packages\django\db\models\lookups.py", line 96, in __init__
    self.rhs = self.get_prep_lookup()
  File "C:\Python34\lib\site-packages\django\db\models\lookups.py", line 134, in get_prep_lookup
    return self.lhs.output_field.get_prep_lookup(self.lookup_name, self.rhs)
  File "C:\Python34\lib\site-packages\django\db\models\fields\__init__.py", line 727, in get_prep_lookup
    return self.get_prep_value(value)
  File "C:\Python34\lib\site-packages\django\db\models\fields\__init__.py", line 985, in get_prep_value
    return int(value)
TypeError: int() argument must be a string, a bytes-like object or a number, not 'AnonymousUser'
ERROR 2016-12-29 14:38:05,589 Internal Server Error: /API/job/
Traceback (most recent call last):
  File "C:\Python34\lib\site-packages\django\core\handlers\base.py", line 132, in get_response
    response = wrapped_callback(request, *callback_args, **callback_kwargs)
  File "C:\Python34\lib\site-packages\django\views\decorators\csrf.py", line 58, in wrapped_view
    return view_func(*args, **kwargs)
  File "C:\Python34\lib\site-packages\django\views\generic\base.py", line 71, in view
    return self.dispatch(request, *args, **kwargs)
  File "C:\Python34\lib\site-packages\rest_framework\views.py", line 466, in dispatch
    response = self.handle_exception(exc)
  File "C:\Python34\lib\site-packages\rest_framework\views.py", line 463, in dispatch
    response = handler(request, *args, **kwargs)
  File "C:\Python34\lib\site-packages\rest_framework\generics.py", line 243, in get
    return self.list(request, *args, **kwargs)
  File "C:\uav\model\views.py", line 270, in list
    queryset = Job.objects.filter(user=self.request.user)
  File "C:\Python34\lib\site-packages\django\db\models\manager.py", line 127, in manager_method
    return getattr(self.get_queryset(), name)(*args, **kwargs)
  File "C:\Python34\lib\site-packages\django\db\models\query.py", line 679, in filter
    return self._filter_or_exclude(False, *args, **kwargs)
  File "C:\Python34\lib\site-packages\django\db\models\query.py", line 697, in _filter_or_exclude
    clone.query.add_q(Q(*args, **kwargs))
  File "C:\Python34\lib\site-packages\django\db\models\sql\query.py", line 1304, in add_q
    clause, require_inner = self._add_q(where_part, self.used_aliases)
  File "C:\Python34\lib\site-packages\django\db\models\sql\query.py", line 1331, in _add_q
    current_negated=current_negated, connector=connector, allow_joins=allow_joins)
  File "C:\Python34\lib\site-packages\django\db\models\sql\query.py", line 1194, in build_filter
    lookups, value)
  File "C:\Python34\lib\site-packages\django\db\models\fields\related.py", line 1740, in get_lookup_constraint
    lookup_class(target.get_col(alias, source), val), AND)
  File "C:\Python34\lib\site-packages\django\db\models\lookups.py", line 96, in __init__
    self.rhs = self.get_prep_lookup()
  File "C:\Python34\lib\site-packages\django\db\models\lookups.py", line 134, in get_prep_lookup
    return self.lhs.output_field.get_prep_lookup(self.lookup_name, self.rhs)
  File "C:\Python34\lib\site-packages\django\db\models\fields\__init__.py", line 727, in get_prep_lookup
    return self.get_prep_value(value)
  File "C:\Python34\lib\site-packages\django\db\models\fields\__init__.py", line 985, in get_prep_value
    return int(value)
TypeError: int() argument must be a string, a bytes-like object or a number, not 'AnonymousUser'
WARNING 2016-12-29 14:39:05,052 Not Found: /upload/job/border/LLHT.txt
WARNING 2016-12-29 14:39:05,052 Not Found: /upload/job/border/LLHT.txt
ERROR 2016-12-29 14:39:09,572 Internal Server Error: /API/jobdetail/1/pois/
Traceback (most recent call last):
  File "C:\Python34\lib\site-packages\django\core\handlers\base.py", line 132, in get_response
    response = wrapped_callback(request, *callback_args, **callback_kwargs)
  File "C:\Python34\lib\site-packages\django\views\decorators\csrf.py", line 58, in wrapped_view
    return view_func(*args, **kwargs)
  File "C:\Python34\lib\site-packages\django\views\generic\base.py", line 71, in view
    return self.dispatch(request, *args, **kwargs)
  File "C:\Python34\lib\site-packages\rest_framework\views.py", line 466, in dispatch
    response = self.handle_exception(exc)
  File "C:\Python34\lib\site-packages\rest_framework\views.py", line 463, in dispatch
    response = handler(request, *args, **kwargs)
  File "C:\Python34\lib\site-packages\rest_framework\generics.py", line 210, in get
    return self.retrieve(request, *args, **kwargs)
  File "C:\uav\model\views.py", line 370, in retrieve
    return self.get_paginated_response(serializer.data)
  File "C:\Python34\lib\site-packages\rest_framework\serializers.py", line 674, in data
    ret = super(ListSerializer, self).data
  File "C:\Python34\lib\site-packages\rest_framework\serializers.py", line 239, in data
    self._data = self.to_representation(self.instance)
  File "C:\Python34\lib\site-packages\rest_framework\serializers.py", line 614, in to_representation
    self.child.to_representation(item) for item in iterable
  File "C:\Python34\lib\site-packages\rest_framework\serializers.py", line 614, in <listcomp>
    self.child.to_representation(item) for item in iterable
  File "C:\Python34\lib\site-packages\rest_framework\serializers.py", line 459, in to_representation
    fields = self._readable_fields
  File "C:\Python34\lib\site-packages\django\utils\functional.py", line 60, in __get__
    res = instance.__dict__[self.name] = self.func(instance)
  File "C:\Python34\lib\site-packages\rest_framework\serializers.py", line 353, in _readable_fields
    field for field in self.fields.values()
  File "C:\Python34\lib\site-packages\rest_framework\serializers.py", line 339, in fields
    for key, value in self.get_fields().items():
  File "C:\Python34\lib\site-packages\rest_framework\serializers.py", line 939, in get_fields
    field_name, info, model, depth
  File "C:\Python34\lib\site-packages\rest_framework\serializers.py", line 1076, in build_field
    return self.build_unknown_field(field_name, model_class)
  File "C:\Python34\lib\site-packages\rest_framework\serializers.py", line 1182, in build_unknown_field
    (field_name, model_class.__name__)
django.core.exceptions.ImproperlyConfigured: Field name `angle` is not valid for model `UAV_Job_Desc`.
ERROR 2016-12-29 14:39:09,572 Internal Server Error: /API/jobdetail/1/pois/
Traceback (most recent call last):
  File "C:\Python34\lib\site-packages\django\core\handlers\base.py", line 132, in get_response
    response = wrapped_callback(request, *callback_args, **callback_kwargs)
  File "C:\Python34\lib\site-packages\django\views\decorators\csrf.py", line 58, in wrapped_view
    return view_func(*args, **kwargs)
  File "C:\Python34\lib\site-packages\django\views\generic\base.py", line 71, in view
    return self.dispatch(request, *args, **kwargs)
  File "C:\Python34\lib\site-packages\rest_framework\views.py", line 466, in dispatch
    response = self.handle_exception(exc)
  File "C:\Python34\lib\site-packages\rest_framework\views.py", line 463, in dispatch
    response = handler(request, *args, **kwargs)
  File "C:\Python34\lib\site-packages\rest_framework\generics.py", line 210, in get
    return self.retrieve(request, *args, **kwargs)
  File "C:\uav\model\views.py", line 370, in retrieve
    return self.get_paginated_response(serializer.data)
  File "C:\Python34\lib\site-packages\rest_framework\serializers.py", line 674, in data
    ret = super(ListSerializer, self).data
  File "C:\Python34\lib\site-packages\rest_framework\serializers.py", line 239, in data
    self._data = self.to_representation(self.instance)
  File "C:\Python34\lib\site-packages\rest_framework\serializers.py", line 614, in to_representation
    self.child.to_representation(item) for item in iterable
  File "C:\Python34\lib\site-packages\rest_framework\serializers.py", line 614, in <listcomp>
    self.child.to_representation(item) for item in iterable
  File "C:\Python34\lib\site-packages\rest_framework\serializers.py", line 459, in to_representation
    fields = self._readable_fields
  File "C:\Python34\lib\site-packages\django\utils\functional.py", line 60, in __get__
    res = instance.__dict__[self.name] = self.func(instance)
  File "C:\Python34\lib\site-packages\rest_framework\serializers.py", line 353, in _readable_fields
    field for field in self.fields.values()
  File "C:\Python34\lib\site-packages\rest_framework\serializers.py", line 339, in fields
    for key, value in self.get_fields().items():
  File "C:\Python34\lib\site-packages\rest_framework\serializers.py", line 939, in get_fields
    field_name, info, model, depth
  File "C:\Python34\lib\site-packages\rest_framework\serializers.py", line 1076, in build_field
    return self.build_unknown_field(field_name, model_class)
  File "C:\Python34\lib\site-packages\rest_framework\serializers.py", line 1182, in build_unknown_field
    (field_name, model_class.__name__)
django.core.exceptions.ImproperlyConfigured: Field name `angle` is not valid for model `UAV_Job_Desc`.
ERROR 2016-12-29 14:39:13,625 Internal Server Error: /API/jobdetail/1/pois/
Traceback (most recent call last):
  File "C:\Python34\lib\site-packages\django\core\handlers\base.py", line 132, in get_response
    response = wrapped_callback(request, *callback_args, **callback_kwargs)
  File "C:\Python34\lib\site-packages\django\views\decorators\csrf.py", line 58, in wrapped_view
    return view_func(*args, **kwargs)
  File "C:\Python34\lib\site-packages\django\views\generic\base.py", line 71, in view
    return self.dispatch(request, *args, **kwargs)
  File "C:\Python34\lib\site-packages\rest_framework\views.py", line 466, in dispatch
    response = self.handle_exception(exc)
  File "C:\Python34\lib\site-packages\rest_framework\views.py", line 463, in dispatch
    response = handler(request, *args, **kwargs)
  File "C:\Python34\lib\site-packages\rest_framework\generics.py", line 210, in get
    return self.retrieve(request, *args, **kwargs)
  File "C:\uav\model\views.py", line 370, in retrieve
    return self.get_paginated_response(serializer.data)
  File "C:\Python34\lib\site-packages\rest_framework\serializers.py", line 674, in data
    ret = super(ListSerializer, self).data
  File "C:\Python34\lib\site-packages\rest_framework\serializers.py", line 239, in data
    self._data = self.to_representation(self.instance)
  File "C:\Python34\lib\site-packages\rest_framework\serializers.py", line 614, in to_representation
    self.child.to_representation(item) for item in iterable
  File "C:\Python34\lib\site-packages\rest_framework\serializers.py", line 614, in <listcomp>
    self.child.to_representation(item) for item in iterable
  File "C:\Python34\lib\site-packages\rest_framework\serializers.py", line 459, in to_representation
    fields = self._readable_fields
  File "C:\Python34\lib\site-packages\django\utils\functional.py", line 60, in __get__
    res = instance.__dict__[self.name] = self.func(instance)
  File "C:\Python34\lib\site-packages\rest_framework\serializers.py", line 353, in _readable_fields
    field for field in self.fields.values()
  File "C:\Python34\lib\site-packages\rest_framework\serializers.py", line 339, in fields
    for key, value in self.get_fields().items():
  File "C:\Python34\lib\site-packages\rest_framework\serializers.py", line 939, in get_fields
    field_name, info, model, depth
  File "C:\Python34\lib\site-packages\rest_framework\serializers.py", line 1076, in build_field
    return self.build_unknown_field(field_name, model_class)
  File "C:\Python34\lib\site-packages\rest_framework\serializers.py", line 1182, in build_unknown_field
    (field_name, model_class.__name__)
django.core.exceptions.ImproperlyConfigured: Field name `angle` is not valid for model `UAV_Job_Desc`.
ERROR 2016-12-29 14:39:13,625 Internal Server Error: /API/jobdetail/1/pois/
Traceback (most recent call last):
  File "C:\Python34\lib\site-packages\django\core\handlers\base.py", line 132, in get_response
    response = wrapped_callback(request, *callback_args, **callback_kwargs)
  File "C:\Python34\lib\site-packages\django\views\decorators\csrf.py", line 58, in wrapped_view
    return view_func(*args, **kwargs)
  File "C:\Python34\lib\site-packages\django\views\generic\base.py", line 71, in view
    return self.dispatch(request, *args, **kwargs)
  File "C:\Python34\lib\site-packages\rest_framework\views.py", line 466, in dispatch
    response = self.handle_exception(exc)
  File "C:\Python34\lib\site-packages\rest_framework\views.py", line 463, in dispatch
    response = handler(request, *args, **kwargs)
  File "C:\Python34\lib\site-packages\rest_framework\generics.py", line 210, in get
    return self.retrieve(request, *args, **kwargs)
  File "C:\uav\model\views.py", line 370, in retrieve
    return self.get_paginated_response(serializer.data)
  File "C:\Python34\lib\site-packages\rest_framework\serializers.py", line 674, in data
    ret = super(ListSerializer, self).data
  File "C:\Python34\lib\site-packages\rest_framework\serializers.py", line 239, in data
    self._data = self.to_representation(self.instance)
  File "C:\Python34\lib\site-packages\rest_framework\serializers.py", line 614, in to_representation
    self.child.to_representation(item) for item in iterable
  File "C:\Python34\lib\site-packages\rest_framework\serializers.py", line 614, in <listcomp>
    self.child.to_representation(item) for item in iterable
  File "C:\Python34\lib\site-packages\rest_framework\serializers.py", line 459, in to_representation
    fields = self._readable_fields
  File "C:\Python34\lib\site-packages\django\utils\functional.py", line 60, in __get__
    res = instance.__dict__[self.name] = self.func(instance)
  File "C:\Python34\lib\site-packages\rest_framework\serializers.py", line 353, in _readable_fields
    field for field in self.fields.values()
  File "C:\Python34\lib\site-packages\rest_framework\serializers.py", line 339, in fields
    for key, value in self.get_fields().items():
  File "C:\Python34\lib\site-packages\rest_framework\serializers.py", line 939, in get_fields
    field_name, info, model, depth
  File "C:\Python34\lib\site-packages\rest_framework\serializers.py", line 1076, in build_field
    return self.build_unknown_field(field_name, model_class)
  File "C:\Python34\lib\site-packages\rest_framework\serializers.py", line 1182, in build_unknown_field
    (field_name, model_class.__name__)
django.core.exceptions.ImproperlyConfigured: Field name `angle` is not valid for model `UAV_Job_Desc`.
ERROR 2016-12-29 14:39:28,795 Internal Server Error: /API/jobdetail/1/pois/
Traceback (most recent call last):
  File "C:\Python34\lib\site-packages\django\core\handlers\base.py", line 132, in get_response
    response = wrapped_callback(request, *callback_args, **callback_kwargs)
  File "C:\Python34\lib\site-packages\django\views\decorators\csrf.py", line 58, in wrapped_view
    return view_func(*args, **kwargs)
  File "C:\Python34\lib\site-packages\django\views\generic\base.py", line 71, in view
    return self.dispatch(request, *args, **kwargs)
  File "C:\Python34\lib\site-packages\rest_framework\views.py", line 466, in dispatch
    response = self.handle_exception(exc)
  File "C:\Python34\lib\site-packages\rest_framework\views.py", line 463, in dispatch
    response = handler(request, *args, **kwargs)
  File "C:\Python34\lib\site-packages\rest_framework\generics.py", line 210, in get
    return self.retrieve(request, *args, **kwargs)
  File "C:\uav\model\views.py", line 370, in retrieve
    return self.get_paginated_response(serializer.data)
  File "C:\Python34\lib\site-packages\rest_framework\serializers.py", line 674, in data
    ret = super(ListSerializer, self).data
  File "C:\Python34\lib\site-packages\rest_framework\serializers.py", line 239, in data
    self._data = self.to_representation(self.instance)
  File "C:\Python34\lib\site-packages\rest_framework\serializers.py", line 614, in to_representation
    self.child.to_representation(item) for item in iterable
  File "C:\Python34\lib\site-packages\rest_framework\serializers.py", line 614, in <listcomp>
    self.child.to_representation(item) for item in iterable
  File "C:\Python34\lib\site-packages\rest_framework\serializers.py", line 459, in to_representation
    fields = self._readable_fields
  File "C:\Python34\lib\site-packages\django\utils\functional.py", line 60, in __get__
    res = instance.__dict__[self.name] = self.func(instance)
  File "C:\Python34\lib\site-packages\rest_framework\serializers.py", line 353, in _readable_fields
    field for field in self.fields.values()
  File "C:\Python34\lib\site-packages\rest_framework\serializers.py", line 339, in fields
    for key, value in self.get_fields().items():
  File "C:\Python34\lib\site-packages\rest_framework\serializers.py", line 939, in get_fields
    field_name, info, model, depth
  File "C:\Python34\lib\site-packages\rest_framework\serializers.py", line 1076, in build_field
    return self.build_unknown_field(field_name, model_class)
  File "C:\Python34\lib\site-packages\rest_framework\serializers.py", line 1182, in build_unknown_field
    (field_name, model_class.__name__)
django.core.exceptions.ImproperlyConfigured: Field name `angle` is not valid for model `UAV_Job_Desc`.
ERROR 2016-12-29 14:39:28,795 Internal Server Error: /API/jobdetail/1/pois/
Traceback (most recent call last):
  File "C:\Python34\lib\site-packages\django\core\handlers\base.py", line 132, in get_response
    response = wrapped_callback(request, *callback_args, **callback_kwargs)
  File "C:\Python34\lib\site-packages\django\views\decorators\csrf.py", line 58, in wrapped_view
    return view_func(*args, **kwargs)
  File "C:\Python34\lib\site-packages\django\views\generic\base.py", line 71, in view
    return self.dispatch(request, *args, **kwargs)
  File "C:\Python34\lib\site-packages\rest_framework\views.py", line 466, in dispatch
    response = self.handle_exception(exc)
  File "C:\Python34\lib\site-packages\rest_framework\views.py", line 463, in dispatch
    response = handler(request, *args, **kwargs)
  File "C:\Python34\lib\site-packages\rest_framework\generics.py", line 210, in get
    return self.retrieve(request, *args, **kwargs)
  File "C:\uav\model\views.py", line 370, in retrieve
    return self.get_paginated_response(serializer.data)
  File "C:\Python34\lib\site-packages\rest_framework\serializers.py", line 674, in data
    ret = super(ListSerializer, self).data
  File "C:\Python34\lib\site-packages\rest_framework\serializers.py", line 239, in data
    self._data = self.to_representation(self.instance)
  File "C:\Python34\lib\site-packages\rest_framework\serializers.py", line 614, in to_representation
    self.child.to_representation(item) for item in iterable
  File "C:\Python34\lib\site-packages\rest_framework\serializers.py", line 614, in <listcomp>
    self.child.to_representation(item) for item in iterable
  File "C:\Python34\lib\site-packages\rest_framework\serializers.py", line 459, in to_representation
    fields = self._readable_fields
  File "C:\Python34\lib\site-packages\django\utils\functional.py", line 60, in __get__
    res = instance.__dict__[self.name] = self.func(instance)
  File "C:\Python34\lib\site-packages\rest_framework\serializers.py", line 353, in _readable_fields
    field for field in self.fields.values()
  File "C:\Python34\lib\site-packages\rest_framework\serializers.py", line 339, in fields
    for key, value in self.get_fields().items():
  File "C:\Python34\lib\site-packages\rest_framework\serializers.py", line 939, in get_fields
    field_name, info, model, depth
  File "C:\Python34\lib\site-packages\rest_framework\serializers.py", line 1076, in build_field
    return self.build_unknown_field(field_name, model_class)
  File "C:\Python34\lib\site-packages\rest_framework\serializers.py", line 1182, in build_unknown_field
    (field_name, model_class.__name__)
django.core.exceptions.ImproperlyConfigured: Field name `angle` is not valid for model `UAV_Job_Desc`.
ERROR 2016-12-29 14:45:37,737 Internal Server Error: /API/job/
Traceback (most recent call last):
  File "C:\Python34\lib\site-packages\django\core\handlers\base.py", line 132, in get_response
    response = wrapped_callback(request, *callback_args, **callback_kwargs)
  File "C:\Python34\lib\site-packages\django\views\decorators\csrf.py", line 58, in wrapped_view
    return view_func(*args, **kwargs)
  File "C:\Python34\lib\site-packages\django\views\generic\base.py", line 71, in view
    return self.dispatch(request, *args, **kwargs)
  File "C:\Python34\lib\site-packages\rest_framework\views.py", line 466, in dispatch
    response = self.handle_exception(exc)
  File "C:\Python34\lib\site-packages\rest_framework\views.py", line 463, in dispatch
    response = handler(request, *args, **kwargs)
  File "C:\Python34\lib\site-packages\rest_framework\generics.py", line 243, in get
    return self.list(request, *args, **kwargs)
  File "C:\uav\model\views.py", line 270, in list
    queryset = Job.objects.filter(user=self.request.user)
  File "C:\Python34\lib\site-packages\django\db\models\manager.py", line 127, in manager_method
    return getattr(self.get_queryset(), name)(*args, **kwargs)
  File "C:\Python34\lib\site-packages\django\db\models\query.py", line 679, in filter
    return self._filter_or_exclude(False, *args, **kwargs)
  File "C:\Python34\lib\site-packages\django\db\models\query.py", line 697, in _filter_or_exclude
    clone.query.add_q(Q(*args, **kwargs))
  File "C:\Python34\lib\site-packages\django\db\models\sql\query.py", line 1304, in add_q
    clause, require_inner = self._add_q(where_part, self.used_aliases)
  File "C:\Python34\lib\site-packages\django\db\models\sql\query.py", line 1331, in _add_q
    current_negated=current_negated, connector=connector, allow_joins=allow_joins)
  File "C:\Python34\lib\site-packages\django\db\models\sql\query.py", line 1194, in build_filter
    lookups, value)
  File "C:\Python34\lib\site-packages\django\db\models\fields\related.py", line 1740, in get_lookup_constraint
    lookup_class(target.get_col(alias, source), val), AND)
  File "C:\Python34\lib\site-packages\django\db\models\lookups.py", line 96, in __init__
    self.rhs = self.get_prep_lookup()
  File "C:\Python34\lib\site-packages\django\db\models\lookups.py", line 134, in get_prep_lookup
    return self.lhs.output_field.get_prep_lookup(self.lookup_name, self.rhs)
  File "C:\Python34\lib\site-packages\django\db\models\fields\__init__.py", line 727, in get_prep_lookup
    return self.get_prep_value(value)
  File "C:\Python34\lib\site-packages\django\db\models\fields\__init__.py", line 985, in get_prep_value
    return int(value)
TypeError: int() argument must be a string, a bytes-like object or a number, not 'AnonymousUser'
ERROR 2016-12-29 14:45:37,737 Internal Server Error: /API/job/
Traceback (most recent call last):
  File "C:\Python34\lib\site-packages\django\core\handlers\base.py", line 132, in get_response
    response = wrapped_callback(request, *callback_args, **callback_kwargs)
  File "C:\Python34\lib\site-packages\django\views\decorators\csrf.py", line 58, in wrapped_view
    return view_func(*args, **kwargs)
  File "C:\Python34\lib\site-packages\django\views\generic\base.py", line 71, in view
    return self.dispatch(request, *args, **kwargs)
  File "C:\Python34\lib\site-packages\rest_framework\views.py", line 466, in dispatch
    response = self.handle_exception(exc)
  File "C:\Python34\lib\site-packages\rest_framework\views.py", line 463, in dispatch
    response = handler(request, *args, **kwargs)
  File "C:\Python34\lib\site-packages\rest_framework\generics.py", line 243, in get
    return self.list(request, *args, **kwargs)
  File "C:\uav\model\views.py", line 270, in list
    queryset = Job.objects.filter(user=self.request.user)
  File "C:\Python34\lib\site-packages\django\db\models\manager.py", line 127, in manager_method
    return getattr(self.get_queryset(), name)(*args, **kwargs)
  File "C:\Python34\lib\site-packages\django\db\models\query.py", line 679, in filter
    return self._filter_or_exclude(False, *args, **kwargs)
  File "C:\Python34\lib\site-packages\django\db\models\query.py", line 697, in _filter_or_exclude
    clone.query.add_q(Q(*args, **kwargs))
  File "C:\Python34\lib\site-packages\django\db\models\sql\query.py", line 1304, in add_q
    clause, require_inner = self._add_q(where_part, self.used_aliases)
  File "C:\Python34\lib\site-packages\django\db\models\sql\query.py", line 1331, in _add_q
    current_negated=current_negated, connector=connector, allow_joins=allow_joins)
  File "C:\Python34\lib\site-packages\django\db\models\sql\query.py", line 1194, in build_filter
    lookups, value)
  File "C:\Python34\lib\site-packages\django\db\models\fields\related.py", line 1740, in get_lookup_constraint
    lookup_class(target.get_col(alias, source), val), AND)
  File "C:\Python34\lib\site-packages\django\db\models\lookups.py", line 96, in __init__
    self.rhs = self.get_prep_lookup()
  File "C:\Python34\lib\site-packages\django\db\models\lookups.py", line 134, in get_prep_lookup
    return self.lhs.output_field.get_prep_lookup(self.lookup_name, self.rhs)
  File "C:\Python34\lib\site-packages\django\db\models\fields\__init__.py", line 727, in get_prep_lookup
    return self.get_prep_value(value)
  File "C:\Python34\lib\site-packages\django\db\models\fields\__init__.py", line 985, in get_prep_value
    return int(value)
TypeError: int() argument must be a string, a bytes-like object or a number, not 'AnonymousUser'
WARNING 2016-12-29 14:47:27,637 Not Found: /announce.php
WARNING 2016-12-29 14:47:27,638 Not Found: /announce.php
WARNING 2016-12-29 14:47:27,637 Not Found: /announce.php
WARNING 2016-12-29 14:47:27,638 Not Found: /announce.php
WARNING 2016-12-29 14:47:29,474 Not Found: /announce.php
WARNING 2016-12-29 14:47:29,474 Not Found: /announce.php
WARNING 2016-12-29 14:47:32,475 Not Found: /announce.php
WARNING 2016-12-29 14:47:32,477 Not Found: /announce.php
WARNING 2016-12-29 14:47:32,479 Not Found: /announce.php
WARNING 2016-12-29 14:47:32,475 Not Found: /announce.php
WARNING 2016-12-29 14:47:32,477 Not Found: /announce.php
WARNING 2016-12-29 14:47:32,479 Not Found: /announce.php
WARNING 2016-12-29 14:47:34,448 Not Found: /announce.php
WARNING 2016-12-29 14:47:34,448 Not Found: /announce.php
ERROR 2016-12-29 14:48:25,746 Internal Server Error: /API/job/
Traceback (most recent call last):
  File "C:\Python34\lib\site-packages\django\core\handlers\base.py", line 132, in get_response
    response = wrapped_callback(request, *callback_args, **callback_kwargs)
  File "C:\Python34\lib\site-packages\django\views\decorators\csrf.py", line 58, in wrapped_view
    return view_func(*args, **kwargs)
  File "C:\Python34\lib\site-packages\django\views\generic\base.py", line 71, in view
    return self.dispatch(request, *args, **kwargs)
  File "C:\Python34\lib\site-packages\rest_framework\views.py", line 466, in dispatch
    response = self.handle_exception(exc)
  File "C:\Python34\lib\site-packages\rest_framework\views.py", line 463, in dispatch
    response = handler(request, *args, **kwargs)
  File "C:\Python34\lib\site-packages\rest_framework\generics.py", line 243, in get
    return self.list(request, *args, **kwargs)
  File "C:\uav\model\views.py", line 270, in list
    queryset = Job.objects.filter(user=self.request.user)
  File "C:\Python34\lib\site-packages\django\db\models\manager.py", line 127, in manager_method
    return getattr(self.get_queryset(), name)(*args, **kwargs)
  File "C:\Python34\lib\site-packages\django\db\models\query.py", line 679, in filter
    return self._filter_or_exclude(False, *args, **kwargs)
  File "C:\Python34\lib\site-packages\django\db\models\query.py", line 697, in _filter_or_exclude
    clone.query.add_q(Q(*args, **kwargs))
  File "C:\Python34\lib\site-packages\django\db\models\sql\query.py", line 1304, in add_q
    clause, require_inner = self._add_q(where_part, self.used_aliases)
  File "C:\Python34\lib\site-packages\django\db\models\sql\query.py", line 1331, in _add_q
    current_negated=current_negated, connector=connector, allow_joins=allow_joins)
  File "C:\Python34\lib\site-packages\django\db\models\sql\query.py", line 1194, in build_filter
    lookups, value)
  File "C:\Python34\lib\site-packages\django\db\models\fields\related.py", line 1740, in get_lookup_constraint
    lookup_class(target.get_col(alias, source), val), AND)
  File "C:\Python34\lib\site-packages\django\db\models\lookups.py", line 96, in __init__
    self.rhs = self.get_prep_lookup()
  File "C:\Python34\lib\site-packages\django\db\models\lookups.py", line 134, in get_prep_lookup
    return self.lhs.output_field.get_prep_lookup(self.lookup_name, self.rhs)
  File "C:\Python34\lib\site-packages\django\db\models\fields\__init__.py", line 727, in get_prep_lookup
    return self.get_prep_value(value)
  File "C:\Python34\lib\site-packages\django\db\models\fields\__init__.py", line 985, in get_prep_value
    return int(value)
TypeError: int() argument must be a string, a bytes-like object or a number, not 'AnonymousUser'
ERROR 2016-12-29 14:48:25,746 Internal Server Error: /API/job/
Traceback (most recent call last):
  File "C:\Python34\lib\site-packages\django\core\handlers\base.py", line 132, in get_response
    response = wrapped_callback(request, *callback_args, **callback_kwargs)
  File "C:\Python34\lib\site-packages\django\views\decorators\csrf.py", line 58, in wrapped_view
    return view_func(*args, **kwargs)
  File "C:\Python34\lib\site-packages\django\views\generic\base.py", line 71, in view
    return self.dispatch(request, *args, **kwargs)
  File "C:\Python34\lib\site-packages\rest_framework\views.py", line 466, in dispatch
    response = self.handle_exception(exc)
  File "C:\Python34\lib\site-packages\rest_framework\views.py", line 463, in dispatch
    response = handler(request, *args, **kwargs)
  File "C:\Python34\lib\site-packages\rest_framework\generics.py", line 243, in get
    return self.list(request, *args, **kwargs)
  File "C:\uav\model\views.py", line 270, in list
    queryset = Job.objects.filter(user=self.request.user)
  File "C:\Python34\lib\site-packages\django\db\models\manager.py", line 127, in manager_method
    return getattr(self.get_queryset(), name)(*args, **kwargs)
  File "C:\Python34\lib\site-packages\django\db\models\query.py", line 679, in filter
    return self._filter_or_exclude(False, *args, **kwargs)
  File "C:\Python34\lib\site-packages\django\db\models\query.py", line 697, in _filter_or_exclude
    clone.query.add_q(Q(*args, **kwargs))
  File "C:\Python34\lib\site-packages\django\db\models\sql\query.py", line 1304, in add_q
    clause, require_inner = self._add_q(where_part, self.used_aliases)
  File "C:\Python34\lib\site-packages\django\db\models\sql\query.py", line 1331, in _add_q
    current_negated=current_negated, connector=connector, allow_joins=allow_joins)
  File "C:\Python34\lib\site-packages\django\db\models\sql\query.py", line 1194, in build_filter
    lookups, value)
  File "C:\Python34\lib\site-packages\django\db\models\fields\related.py", line 1740, in get_lookup_constraint
    lookup_class(target.get_col(alias, source), val), AND)
  File "C:\Python34\lib\site-packages\django\db\models\lookups.py", line 96, in __init__
    self.rhs = self.get_prep_lookup()
  File "C:\Python34\lib\site-packages\django\db\models\lookups.py", line 134, in get_prep_lookup
    return self.lhs.output_field.get_prep_lookup(self.lookup_name, self.rhs)
  File "C:\Python34\lib\site-packages\django\db\models\fields\__init__.py", line 727, in get_prep_lookup
    return self.get_prep_value(value)
  File "C:\Python34\lib\site-packages\django\db\models\fields\__init__.py", line 985, in get_prep_value
    return int(value)
TypeError: int() argument must be a string, a bytes-like object or a number, not 'AnonymousUser'
ERROR 2016-12-29 14:48:41,528 Internal Server Error: /API/job/
Traceback (most recent call last):
  File "C:\Python34\lib\site-packages\django\core\handlers\base.py", line 132, in get_response
    response = wrapped_callback(request, *callback_args, **callback_kwargs)
  File "C:\Python34\lib\site-packages\django\views\decorators\csrf.py", line 58, in wrapped_view
    return view_func(*args, **kwargs)
  File "C:\Python34\lib\site-packages\django\views\generic\base.py", line 71, in view
    return self.dispatch(request, *args, **kwargs)
  File "C:\Python34\lib\site-packages\rest_framework\views.py", line 466, in dispatch
    response = self.handle_exception(exc)
  File "C:\Python34\lib\site-packages\rest_framework\views.py", line 463, in dispatch
    response = handler(request, *args, **kwargs)
  File "C:\Python34\lib\site-packages\rest_framework\generics.py", line 243, in get
    return self.list(request, *args, **kwargs)
  File "C:\uav\model\views.py", line 270, in list
    queryset = Job.objects.filter(user=self.request.user)
  File "C:\Python34\lib\site-packages\django\db\models\manager.py", line 127, in manager_method
    return getattr(self.get_queryset(), name)(*args, **kwargs)
  File "C:\Python34\lib\site-packages\django\db\models\query.py", line 679, in filter
    return self._filter_or_exclude(False, *args, **kwargs)
  File "C:\Python34\lib\site-packages\django\db\models\query.py", line 697, in _filter_or_exclude
    clone.query.add_q(Q(*args, **kwargs))
  File "C:\Python34\lib\site-packages\django\db\models\sql\query.py", line 1304, in add_q
    clause, require_inner = self._add_q(where_part, self.used_aliases)
  File "C:\Python34\lib\site-packages\django\db\models\sql\query.py", line 1331, in _add_q
    current_negated=current_negated, connector=connector, allow_joins=allow_joins)
  File "C:\Python34\lib\site-packages\django\db\models\sql\query.py", line 1194, in build_filter
    lookups, value)
  File "C:\Python34\lib\site-packages\django\db\models\fields\related.py", line 1740, in get_lookup_constraint
    lookup_class(target.get_col(alias, source), val), AND)
  File "C:\Python34\lib\site-packages\django\db\models\lookups.py", line 96, in __init__
    self.rhs = self.get_prep_lookup()
  File "C:\Python34\lib\site-packages\django\db\models\lookups.py", line 134, in get_prep_lookup
    return self.lhs.output_field.get_prep_lookup(self.lookup_name, self.rhs)
  File "C:\Python34\lib\site-packages\django\db\models\fields\__init__.py", line 727, in get_prep_lookup
    return self.get_prep_value(value)
  File "C:\Python34\lib\site-packages\django\db\models\fields\__init__.py", line 985, in get_prep_value
    return int(value)
TypeError: int() argument must be a string, a bytes-like object or a number, not 'AnonymousUser'
ERROR 2016-12-29 14:48:41,528 Internal Server Error: /API/job/
Traceback (most recent call last):
  File "C:\Python34\lib\site-packages\django\core\handlers\base.py", line 132, in get_response
    response = wrapped_callback(request, *callback_args, **callback_kwargs)
  File "C:\Python34\lib\site-packages\django\views\decorators\csrf.py", line 58, in wrapped_view
    return view_func(*args, **kwargs)
  File "C:\Python34\lib\site-packages\django\views\generic\base.py", line 71, in view
    return self.dispatch(request, *args, **kwargs)
  File "C:\Python34\lib\site-packages\rest_framework\views.py", line 466, in dispatch
    response = self.handle_exception(exc)
  File "C:\Python34\lib\site-packages\rest_framework\views.py", line 463, in dispatch
    response = handler(request, *args, **kwargs)
  File "C:\Python34\lib\site-packages\rest_framework\generics.py", line 243, in get
    return self.list(request, *args, **kwargs)
  File "C:\uav\model\views.py", line 270, in list
    queryset = Job.objects.filter(user=self.request.user)
  File "C:\Python34\lib\site-packages\django\db\models\manager.py", line 127, in manager_method
    return getattr(self.get_queryset(), name)(*args, **kwargs)
  File "C:\Python34\lib\site-packages\django\db\models\query.py", line 679, in filter
    return self._filter_or_exclude(False, *args, **kwargs)
  File "C:\Python34\lib\site-packages\django\db\models\query.py", line 697, in _filter_or_exclude
    clone.query.add_q(Q(*args, **kwargs))
  File "C:\Python34\lib\site-packages\django\db\models\sql\query.py", line 1304, in add_q
    clause, require_inner = self._add_q(where_part, self.used_aliases)
  File "C:\Python34\lib\site-packages\django\db\models\sql\query.py", line 1331, in _add_q
    current_negated=current_negated, connector=connector, allow_joins=allow_joins)
  File "C:\Python34\lib\site-packages\django\db\models\sql\query.py", line 1194, in build_filter
    lookups, value)
  File "C:\Python34\lib\site-packages\django\db\models\fields\related.py", line 1740, in get_lookup_constraint
    lookup_class(target.get_col(alias, source), val), AND)
  File "C:\Python34\lib\site-packages\django\db\models\lookups.py", line 96, in __init__
    self.rhs = self.get_prep_lookup()
  File "C:\Python34\lib\site-packages\django\db\models\lookups.py", line 134, in get_prep_lookup
    return self.lhs.output_field.get_prep_lookup(self.lookup_name, self.rhs)
  File "C:\Python34\lib\site-packages\django\db\models\fields\__init__.py", line 727, in get_prep_lookup
    return self.get_prep_value(value)
  File "C:\Python34\lib\site-packages\django\db\models\fields\__init__.py", line 985, in get_prep_value
    return int(value)
TypeError: int() argument must be a string, a bytes-like object or a number, not 'AnonymousUser'
WARNING 2016-12-29 14:49:29,469 Not Found: /announce.php
WARNING 2016-12-29 14:49:29,470 Not Found: /announce.php
WARNING 2016-12-29 14:49:29,469 Not Found: /announce.php
WARNING 2016-12-29 14:49:29,470 Not Found: /announce.php
WARNING 2016-12-29 14:49:32,474 Not Found: /announce.php
WARNING 2016-12-29 14:49:32,474 Not Found: /announce.php
WARNING 2016-12-29 14:49:32,480 Not Found: /announce.php
WARNING 2016-12-29 14:49:32,481 Not Found: /announce.php
WARNING 2016-12-29 14:49:32,480 Not Found: /announce.php
WARNING 2016-12-29 14:49:32,481 Not Found: /announce.php
WARNING 2016-12-29 14:49:35,473 Not Found: /announce.php
WARNING 2016-12-29 14:49:35,473 Not Found: /announce.php
WARNING 2016-12-29 14:49:38,464 Not Found: /announce.php
WARNING 2016-12-29 14:49:38,464 Not Found: /announce.php
WARNING 2016-12-29 14:50:59,472 Not Found: /announce.php
WARNING 2016-12-29 14:50:59,472 Not Found: /announce.php
WARNING 2016-12-29 14:51:20,462 Not Found: /announce.php
WARNING 2016-12-29 14:51:20,462 Not Found: /announce.php
WARNING 2016-12-29 14:51:50,479 Not Found: /announce.php
WARNING 2016-12-29 14:51:50,481 Not Found: /announce.php
WARNING 2016-12-29 14:51:50,483 Not Found: /announce.php
WARNING 2016-12-29 14:51:50,485 Not Found: /announce.php
WARNING 2016-12-29 14:51:50,479 Not Found: /announce.php
WARNING 2016-12-29 14:51:50,481 Not Found: /announce.php
WARNING 2016-12-29 14:51:50,483 Not Found: /announce.php
WARNING 2016-12-29 14:51:50,485 Not Found: /announce.php
WARNING 2016-12-29 14:51:53,472 Not Found: /announce.php
WARNING 2016-12-29 14:51:53,472 Not Found: /announce.php
WARNING 2016-12-29 14:51:59,460 Not Found: /announce.php
WARNING 2016-12-29 14:51:59,460 Not Found: /announce.php
ERROR 2016-12-29 14:52:01,726 Internal Server Error: /API/job/
Traceback (most recent call last):
  File "C:\Python34\lib\site-packages\django\core\handlers\base.py", line 132, in get_response
    response = wrapped_callback(request, *callback_args, **callback_kwargs)
  File "C:\Python34\lib\site-packages\django\views\decorators\csrf.py", line 58, in wrapped_view
    return view_func(*args, **kwargs)
  File "C:\Python34\lib\site-packages\django\views\generic\base.py", line 71, in view
    return self.dispatch(request, *args, **kwargs)
  File "C:\Python34\lib\site-packages\rest_framework\views.py", line 466, in dispatch
    response = self.handle_exception(exc)
  File "C:\Python34\lib\site-packages\rest_framework\views.py", line 463, in dispatch
    response = handler(request, *args, **kwargs)
  File "C:\Python34\lib\site-packages\rest_framework\generics.py", line 243, in get
    return self.list(request, *args, **kwargs)
  File "C:\uav\model\views.py", line 270, in list
    queryset = Job.objects.filter(user=self.request.user)
  File "C:\Python34\lib\site-packages\django\db\models\manager.py", line 127, in manager_method
    return getattr(self.get_queryset(), name)(*args, **kwargs)
  File "C:\Python34\lib\site-packages\django\db\models\query.py", line 679, in filter
    return self._filter_or_exclude(False, *args, **kwargs)
  File "C:\Python34\lib\site-packages\django\db\models\query.py", line 697, in _filter_or_exclude
    clone.query.add_q(Q(*args, **kwargs))
  File "C:\Python34\lib\site-packages\django\db\models\sql\query.py", line 1304, in add_q
    clause, require_inner = self._add_q(where_part, self.used_aliases)
  File "C:\Python34\lib\site-packages\django\db\models\sql\query.py", line 1331, in _add_q
    current_negated=current_negated, connector=connector, allow_joins=allow_joins)
  File "C:\Python34\lib\site-packages\django\db\models\sql\query.py", line 1194, in build_filter
    lookups, value)
  File "C:\Python34\lib\site-packages\django\db\models\fields\related.py", line 1740, in get_lookup_constraint
    lookup_class(target.get_col(alias, source), val), AND)
  File "C:\Python34\lib\site-packages\django\db\models\lookups.py", line 96, in __init__
    self.rhs = self.get_prep_lookup()
  File "C:\Python34\lib\site-packages\django\db\models\lookups.py", line 134, in get_prep_lookup
    return self.lhs.output_field.get_prep_lookup(self.lookup_name, self.rhs)
  File "C:\Python34\lib\site-packages\django\db\models\fields\__init__.py", line 727, in get_prep_lookup
    return self.get_prep_value(value)
  File "C:\Python34\lib\site-packages\django\db\models\fields\__init__.py", line 985, in get_prep_value
    return int(value)
TypeError: int() argument must be a string, a bytes-like object or a number, not 'AnonymousUser'
ERROR 2016-12-29 14:52:01,726 Internal Server Error: /API/job/
Traceback (most recent call last):
  File "C:\Python34\lib\site-packages\django\core\handlers\base.py", line 132, in get_response
    response = wrapped_callback(request, *callback_args, **callback_kwargs)
  File "C:\Python34\lib\site-packages\django\views\decorators\csrf.py", line 58, in wrapped_view
    return view_func(*args, **kwargs)
  File "C:\Python34\lib\site-packages\django\views\generic\base.py", line 71, in view
    return self.dispatch(request, *args, **kwargs)
  File "C:\Python34\lib\site-packages\rest_framework\views.py", line 466, in dispatch
    response = self.handle_exception(exc)
  File "C:\Python34\lib\site-packages\rest_framework\views.py", line 463, in dispatch
    response = handler(request, *args, **kwargs)
  File "C:\Python34\lib\site-packages\rest_framework\generics.py", line 243, in get
    return self.list(request, *args, **kwargs)
  File "C:\uav\model\views.py", line 270, in list
    queryset = Job.objects.filter(user=self.request.user)
  File "C:\Python34\lib\site-packages\django\db\models\manager.py", line 127, in manager_method
    return getattr(self.get_queryset(), name)(*args, **kwargs)
  File "C:\Python34\lib\site-packages\django\db\models\query.py", line 679, in filter
    return self._filter_or_exclude(False, *args, **kwargs)
  File "C:\Python34\lib\site-packages\django\db\models\query.py", line 697, in _filter_or_exclude
    clone.query.add_q(Q(*args, **kwargs))
  File "C:\Python34\lib\site-packages\django\db\models\sql\query.py", line 1304, in add_q
    clause, require_inner = self._add_q(where_part, self.used_aliases)
  File "C:\Python34\lib\site-packages\django\db\models\sql\query.py", line 1331, in _add_q
    current_negated=current_negated, connector=connector, allow_joins=allow_joins)
  File "C:\Python34\lib\site-packages\django\db\models\sql\query.py", line 1194, in build_filter
    lookups, value)
  File "C:\Python34\lib\site-packages\django\db\models\fields\related.py", line 1740, in get_lookup_constraint
    lookup_class(target.get_col(alias, source), val), AND)
  File "C:\Python34\lib\site-packages\django\db\models\lookups.py", line 96, in __init__
    self.rhs = self.get_prep_lookup()
  File "C:\Python34\lib\site-packages\django\db\models\lookups.py", line 134, in get_prep_lookup
    return self.lhs.output_field.get_prep_lookup(self.lookup_name, self.rhs)
  File "C:\Python34\lib\site-packages\django\db\models\fields\__init__.py", line 727, in get_prep_lookup
    return self.get_prep_value(value)
  File "C:\Python34\lib\site-packages\django\db\models\fields\__init__.py", line 985, in get_prep_value
    return int(value)
TypeError: int() argument must be a string, a bytes-like object or a number, not 'AnonymousUser'
ERROR 2016-12-29 14:52:05,791 Internal Server Error: /API/job/
Traceback (most recent call last):
  File "C:\Python34\lib\site-packages\django\core\handlers\base.py", line 132, in get_response
    response = wrapped_callback(request, *callback_args, **callback_kwargs)
  File "C:\Python34\lib\site-packages\django\views\decorators\csrf.py", line 58, in wrapped_view
    return view_func(*args, **kwargs)
  File "C:\Python34\lib\site-packages\django\views\generic\base.py", line 71, in view
    return self.dispatch(request, *args, **kwargs)
  File "C:\Python34\lib\site-packages\rest_framework\views.py", line 466, in dispatch
    response = self.handle_exception(exc)
  File "C:\Python34\lib\site-packages\rest_framework\views.py", line 463, in dispatch
    response = handler(request, *args, **kwargs)
  File "C:\Python34\lib\site-packages\rest_framework\generics.py", line 243, in get
    return self.list(request, *args, **kwargs)
  File "C:\uav\model\views.py", line 270, in list
    queryset = Job.objects.filter(user=self.request.user)
  File "C:\Python34\lib\site-packages\django\db\models\manager.py", line 127, in manager_method
    return getattr(self.get_queryset(), name)(*args, **kwargs)
  File "C:\Python34\lib\site-packages\django\db\models\query.py", line 679, in filter
    return self._filter_or_exclude(False, *args, **kwargs)
  File "C:\Python34\lib\site-packages\django\db\models\query.py", line 697, in _filter_or_exclude
    clone.query.add_q(Q(*args, **kwargs))
  File "C:\Python34\lib\site-packages\django\db\models\sql\query.py", line 1304, in add_q
    clause, require_inner = self._add_q(where_part, self.used_aliases)
  File "C:\Python34\lib\site-packages\django\db\models\sql\query.py", line 1331, in _add_q
    current_negated=current_negated, connector=connector, allow_joins=allow_joins)
  File "C:\Python34\lib\site-packages\django\db\models\sql\query.py", line 1194, in build_filter
    lookups, value)
  File "C:\Python34\lib\site-packages\django\db\models\fields\related.py", line 1740, in get_lookup_constraint
    lookup_class(target.get_col(alias, source), val), AND)
  File "C:\Python34\lib\site-packages\django\db\models\lookups.py", line 96, in __init__
    self.rhs = self.get_prep_lookup()
  File "C:\Python34\lib\site-packages\django\db\models\lookups.py", line 134, in get_prep_lookup
    return self.lhs.output_field.get_prep_lookup(self.lookup_name, self.rhs)
  File "C:\Python34\lib\site-packages\django\db\models\fields\__init__.py", line 727, in get_prep_lookup
    return self.get_prep_value(value)
  File "C:\Python34\lib\site-packages\django\db\models\fields\__init__.py", line 985, in get_prep_value
    return int(value)
TypeError: int() argument must be a string, a bytes-like object or a number, not 'AnonymousUser'
ERROR 2016-12-29 14:52:05,791 Internal Server Error: /API/job/
Traceback (most recent call last):
  File "C:\Python34\lib\site-packages\django\core\handlers\base.py", line 132, in get_response
    response = wrapped_callback(request, *callback_args, **callback_kwargs)
  File "C:\Python34\lib\site-packages\django\views\decorators\csrf.py", line 58, in wrapped_view
    return view_func(*args, **kwargs)
  File "C:\Python34\lib\site-packages\django\views\generic\base.py", line 71, in view
    return self.dispatch(request, *args, **kwargs)
  File "C:\Python34\lib\site-packages\rest_framework\views.py", line 466, in dispatch
    response = self.handle_exception(exc)
  File "C:\Python34\lib\site-packages\rest_framework\views.py", line 463, in dispatch
    response = handler(request, *args, **kwargs)
  File "C:\Python34\lib\site-packages\rest_framework\generics.py", line 243, in get
    return self.list(request, *args, **kwargs)
  File "C:\uav\model\views.py", line 270, in list
    queryset = Job.objects.filter(user=self.request.user)
  File "C:\Python34\lib\site-packages\django\db\models\manager.py", line 127, in manager_method
    return getattr(self.get_queryset(), name)(*args, **kwargs)
  File "C:\Python34\lib\site-packages\django\db\models\query.py", line 679, in filter
    return self._filter_or_exclude(False, *args, **kwargs)
  File "C:\Python34\lib\site-packages\django\db\models\query.py", line 697, in _filter_or_exclude
    clone.query.add_q(Q(*args, **kwargs))
  File "C:\Python34\lib\site-packages\django\db\models\sql\query.py", line 1304, in add_q
    clause, require_inner = self._add_q(where_part, self.used_aliases)
  File "C:\Python34\lib\site-packages\django\db\models\sql\query.py", line 1331, in _add_q
    current_negated=current_negated, connector=connector, allow_joins=allow_joins)
  File "C:\Python34\lib\site-packages\django\db\models\sql\query.py", line 1194, in build_filter
    lookups, value)
  File "C:\Python34\lib\site-packages\django\db\models\fields\related.py", line 1740, in get_lookup_constraint
    lookup_class(target.get_col(alias, source), val), AND)
  File "C:\Python34\lib\site-packages\django\db\models\lookups.py", line 96, in __init__
    self.rhs = self.get_prep_lookup()
  File "C:\Python34\lib\site-packages\django\db\models\lookups.py", line 134, in get_prep_lookup
    return self.lhs.output_field.get_prep_lookup(self.lookup_name, self.rhs)
  File "C:\Python34\lib\site-packages\django\db\models\fields\__init__.py", line 727, in get_prep_lookup
    return self.get_prep_value(value)
  File "C:\Python34\lib\site-packages\django\db\models\fields\__init__.py", line 985, in get_prep_value
    return int(value)
TypeError: int() argument must be a string, a bytes-like object or a number, not 'AnonymousUser'
ERROR 2016-12-29 14:52:07,268 Internal Server Error: /API/job/
Traceback (most recent call last):
  File "C:\Python34\lib\site-packages\django\core\handlers\base.py", line 132, in get_response
    response = wrapped_callback(request, *callback_args, **callback_kwargs)
  File "C:\Python34\lib\site-packages\django\views\decorators\csrf.py", line 58, in wrapped_view
    return view_func(*args, **kwargs)
  File "C:\Python34\lib\site-packages\django\views\generic\base.py", line 71, in view
    return self.dispatch(request, *args, **kwargs)
  File "C:\Python34\lib\site-packages\rest_framework\views.py", line 466, in dispatch
    response = self.handle_exception(exc)
  File "C:\Python34\lib\site-packages\rest_framework\views.py", line 463, in dispatch
    response = handler(request, *args, **kwargs)
  File "C:\Python34\lib\site-packages\rest_framework\generics.py", line 243, in get
    return self.list(request, *args, **kwargs)
  File "C:\uav\model\views.py", line 270, in list
    queryset = Job.objects.filter(user=self.request.user)
  File "C:\Python34\lib\site-packages\django\db\models\manager.py", line 127, in manager_method
    return getattr(self.get_queryset(), name)(*args, **kwargs)
  File "C:\Python34\lib\site-packages\django\db\models\query.py", line 679, in filter
    return self._filter_or_exclude(False, *args, **kwargs)
  File "C:\Python34\lib\site-packages\django\db\models\query.py", line 697, in _filter_or_exclude
    clone.query.add_q(Q(*args, **kwargs))
  File "C:\Python34\lib\site-packages\django\db\models\sql\query.py", line 1304, in add_q
    clause, require_inner = self._add_q(where_part, self.used_aliases)
  File "C:\Python34\lib\site-packages\django\db\models\sql\query.py", line 1331, in _add_q
    current_negated=current_negated, connector=connector, allow_joins=allow_joins)
  File "C:\Python34\lib\site-packages\django\db\models\sql\query.py", line 1194, in build_filter
    lookups, value)
  File "C:\Python34\lib\site-packages\django\db\models\fields\related.py", line 1740, in get_lookup_constraint
    lookup_class(target.get_col(alias, source), val), AND)
  File "C:\Python34\lib\site-packages\django\db\models\lookups.py", line 96, in __init__
    self.rhs = self.get_prep_lookup()
  File "C:\Python34\lib\site-packages\django\db\models\lookups.py", line 134, in get_prep_lookup
    return self.lhs.output_field.get_prep_lookup(self.lookup_name, self.rhs)
  File "C:\Python34\lib\site-packages\django\db\models\fields\__init__.py", line 727, in get_prep_lookup
    return self.get_prep_value(value)
  File "C:\Python34\lib\site-packages\django\db\models\fields\__init__.py", line 985, in get_prep_value
    return int(value)
TypeError: int() argument must be a string, a bytes-like object or a number, not 'AnonymousUser'
ERROR 2016-12-29 14:52:07,268 Internal Server Error: /API/job/
Traceback (most recent call last):
  File "C:\Python34\lib\site-packages\django\core\handlers\base.py", line 132, in get_response
    response = wrapped_callback(request, *callback_args, **callback_kwargs)
  File "C:\Python34\lib\site-packages\django\views\decorators\csrf.py", line 58, in wrapped_view
    return view_func(*args, **kwargs)
  File "C:\Python34\lib\site-packages\django\views\generic\base.py", line 71, in view
    return self.dispatch(request, *args, **kwargs)
  File "C:\Python34\lib\site-packages\rest_framework\views.py", line 466, in dispatch
    response = self.handle_exception(exc)
  File "C:\Python34\lib\site-packages\rest_framework\views.py", line 463, in dispatch
    response = handler(request, *args, **kwargs)
  File "C:\Python34\lib\site-packages\rest_framework\generics.py", line 243, in get
    return self.list(request, *args, **kwargs)
  File "C:\uav\model\views.py", line 270, in list
    queryset = Job.objects.filter(user=self.request.user)
  File "C:\Python34\lib\site-packages\django\db\models\manager.py", line 127, in manager_method
    return getattr(self.get_queryset(), name)(*args, **kwargs)
  File "C:\Python34\lib\site-packages\django\db\models\query.py", line 679, in filter
    return self._filter_or_exclude(False, *args, **kwargs)
  File "C:\Python34\lib\site-packages\django\db\models\query.py", line 697, in _filter_or_exclude
    clone.query.add_q(Q(*args, **kwargs))
  File "C:\Python34\lib\site-packages\django\db\models\sql\query.py", line 1304, in add_q
    clause, require_inner = self._add_q(where_part, self.used_aliases)
  File "C:\Python34\lib\site-packages\django\db\models\sql\query.py", line 1331, in _add_q
    current_negated=current_negated, connector=connector, allow_joins=allow_joins)
  File "C:\Python34\lib\site-packages\django\db\models\sql\query.py", line 1194, in build_filter
    lookups, value)
  File "C:\Python34\lib\site-packages\django\db\models\fields\related.py", line 1740, in get_lookup_constraint
    lookup_class(target.get_col(alias, source), val), AND)
  File "C:\Python34\lib\site-packages\django\db\models\lookups.py", line 96, in __init__
    self.rhs = self.get_prep_lookup()
  File "C:\Python34\lib\site-packages\django\db\models\lookups.py", line 134, in get_prep_lookup
    return self.lhs.output_field.get_prep_lookup(self.lookup_name, self.rhs)
  File "C:\Python34\lib\site-packages\django\db\models\fields\__init__.py", line 727, in get_prep_lookup
    return self.get_prep_value(value)
  File "C:\Python34\lib\site-packages\django\db\models\fields\__init__.py", line 985, in get_prep_value
    return int(value)
TypeError: int() argument must be a string, a bytes-like object or a number, not 'AnonymousUser'
ERROR 2016-12-29 14:52:07,765 Internal Server Error: /API/job/
Traceback (most recent call last):
  File "C:\Python34\lib\site-packages\django\core\handlers\base.py", line 132, in get_response
    response = wrapped_callback(request, *callback_args, **callback_kwargs)
  File "C:\Python34\lib\site-packages\django\views\decorators\csrf.py", line 58, in wrapped_view
    return view_func(*args, **kwargs)
  File "C:\Python34\lib\site-packages\django\views\generic\base.py", line 71, in view
    return self.dispatch(request, *args, **kwargs)
  File "C:\Python34\lib\site-packages\rest_framework\views.py", line 466, in dispatch
    response = self.handle_exception(exc)
  File "C:\Python34\lib\site-packages\rest_framework\views.py", line 463, in dispatch
    response = handler(request, *args, **kwargs)
  File "C:\Python34\lib\site-packages\rest_framework\generics.py", line 243, in get
    return self.list(request, *args, **kwargs)
  File "C:\uav\model\views.py", line 270, in list
    queryset = Job.objects.filter(user=self.request.user)
  File "C:\Python34\lib\site-packages\django\db\models\manager.py", line 127, in manager_method
    return getattr(self.get_queryset(), name)(*args, **kwargs)
  File "C:\Python34\lib\site-packages\django\db\models\query.py", line 679, in filter
    return self._filter_or_exclude(False, *args, **kwargs)
  File "C:\Python34\lib\site-packages\django\db\models\query.py", line 697, in _filter_or_exclude
    clone.query.add_q(Q(*args, **kwargs))
  File "C:\Python34\lib\site-packages\django\db\models\sql\query.py", line 1304, in add_q
    clause, require_inner = self._add_q(where_part, self.used_aliases)
  File "C:\Python34\lib\site-packages\django\db\models\sql\query.py", line 1331, in _add_q
    current_negated=current_negated, connector=connector, allow_joins=allow_joins)
  File "C:\Python34\lib\site-packages\django\db\models\sql\query.py", line 1194, in build_filter
    lookups, value)
  File "C:\Python34\lib\site-packages\django\db\models\fields\related.py", line 1740, in get_lookup_constraint
    lookup_class(target.get_col(alias, source), val), AND)
  File "C:\Python34\lib\site-packages\django\db\models\lookups.py", line 96, in __init__
    self.rhs = self.get_prep_lookup()
  File "C:\Python34\lib\site-packages\django\db\models\lookups.py", line 134, in get_prep_lookup
    return self.lhs.output_field.get_prep_lookup(self.lookup_name, self.rhs)
  File "C:\Python34\lib\site-packages\django\db\models\fields\__init__.py", line 727, in get_prep_lookup
    return self.get_prep_value(value)
  File "C:\Python34\lib\site-packages\django\db\models\fields\__init__.py", line 985, in get_prep_value
    return int(value)
TypeError: int() argument must be a string, a bytes-like object or a number, not 'AnonymousUser'
ERROR 2016-12-29 14:52:07,765 Internal Server Error: /API/job/
Traceback (most recent call last):
  File "C:\Python34\lib\site-packages\django\core\handlers\base.py", line 132, in get_response
    response = wrapped_callback(request, *callback_args, **callback_kwargs)
  File "C:\Python34\lib\site-packages\django\views\decorators\csrf.py", line 58, in wrapped_view
    return view_func(*args, **kwargs)
  File "C:\Python34\lib\site-packages\django\views\generic\base.py", line 71, in view
    return self.dispatch(request, *args, **kwargs)
  File "C:\Python34\lib\site-packages\rest_framework\views.py", line 466, in dispatch
    response = self.handle_exception(exc)
  File "C:\Python34\lib\site-packages\rest_framework\views.py", line 463, in dispatch
    response = handler(request, *args, **kwargs)
  File "C:\Python34\lib\site-packages\rest_framework\generics.py", line 243, in get
    return self.list(request, *args, **kwargs)
  File "C:\uav\model\views.py", line 270, in list
    queryset = Job.objects.filter(user=self.request.user)
  File "C:\Python34\lib\site-packages\django\db\models\manager.py", line 127, in manager_method
    return getattr(self.get_queryset(), name)(*args, **kwargs)
  File "C:\Python34\lib\site-packages\django\db\models\query.py", line 679, in filter
    return self._filter_or_exclude(False, *args, **kwargs)
  File "C:\Python34\lib\site-packages\django\db\models\query.py", line 697, in _filter_or_exclude
    clone.query.add_q(Q(*args, **kwargs))
  File "C:\Python34\lib\site-packages\django\db\models\sql\query.py", line 1304, in add_q
    clause, require_inner = self._add_q(where_part, self.used_aliases)
  File "C:\Python34\lib\site-packages\django\db\models\sql\query.py", line 1331, in _add_q
    current_negated=current_negated, connector=connector, allow_joins=allow_joins)
  File "C:\Python34\lib\site-packages\django\db\models\sql\query.py", line 1194, in build_filter
    lookups, value)
  File "C:\Python34\lib\site-packages\django\db\models\fields\related.py", line 1740, in get_lookup_constraint
    lookup_class(target.get_col(alias, source), val), AND)
  File "C:\Python34\lib\site-packages\django\db\models\lookups.py", line 96, in __init__
    self.rhs = self.get_prep_lookup()
  File "C:\Python34\lib\site-packages\django\db\models\lookups.py", line 134, in get_prep_lookup
    return self.lhs.output_field.get_prep_lookup(self.lookup_name, self.rhs)
  File "C:\Python34\lib\site-packages\django\db\models\fields\__init__.py", line 727, in get_prep_lookup
    return self.get_prep_value(value)
  File "C:\Python34\lib\site-packages\django\db\models\fields\__init__.py", line 985, in get_prep_value
    return int(value)
TypeError: int() argument must be a string, a bytes-like object or a number, not 'AnonymousUser'
ERROR 2016-12-29 14:52:08,590 Internal Server Error: /API/job/
Traceback (most recent call last):
  File "C:\Python34\lib\site-packages\django\core\handlers\base.py", line 132, in get_response
    response = wrapped_callback(request, *callback_args, **callback_kwargs)
  File "C:\Python34\lib\site-packages\django\views\decorators\csrf.py", line 58, in wrapped_view
    return view_func(*args, **kwargs)
  File "C:\Python34\lib\site-packages\django\views\generic\base.py", line 71, in view
    return self.dispatch(request, *args, **kwargs)
  File "C:\Python34\lib\site-packages\rest_framework\views.py", line 466, in dispatch
    response = self.handle_exception(exc)
  File "C:\Python34\lib\site-packages\rest_framework\views.py", line 463, in dispatch
    response = handler(request, *args, **kwargs)
  File "C:\Python34\lib\site-packages\rest_framework\generics.py", line 243, in get
    return self.list(request, *args, **kwargs)
  File "C:\uav\model\views.py", line 270, in list
    queryset = Job.objects.filter(user=self.request.user)
  File "C:\Python34\lib\site-packages\django\db\models\manager.py", line 127, in manager_method
    return getattr(self.get_queryset(), name)(*args, **kwargs)
  File "C:\Python34\lib\site-packages\django\db\models\query.py", line 679, in filter
    return self._filter_or_exclude(False, *args, **kwargs)
  File "C:\Python34\lib\site-packages\django\db\models\query.py", line 697, in _filter_or_exclude
    clone.query.add_q(Q(*args, **kwargs))
  File "C:\Python34\lib\site-packages\django\db\models\sql\query.py", line 1304, in add_q
    clause, require_inner = self._add_q(where_part, self.used_aliases)
  File "C:\Python34\lib\site-packages\django\db\models\sql\query.py", line 1331, in _add_q
    current_negated=current_negated, connector=connector, allow_joins=allow_joins)
  File "C:\Python34\lib\site-packages\django\db\models\sql\query.py", line 1194, in build_filter
    lookups, value)
  File "C:\Python34\lib\site-packages\django\db\models\fields\related.py", line 1740, in get_lookup_constraint
    lookup_class(target.get_col(alias, source), val), AND)
  File "C:\Python34\lib\site-packages\django\db\models\lookups.py", line 96, in __init__
    self.rhs = self.get_prep_lookup()
  File "C:\Python34\lib\site-packages\django\db\models\lookups.py", line 134, in get_prep_lookup
    return self.lhs.output_field.get_prep_lookup(self.lookup_name, self.rhs)
  File "C:\Python34\lib\site-packages\django\db\models\fields\__init__.py", line 727, in get_prep_lookup
    return self.get_prep_value(value)
  File "C:\Python34\lib\site-packages\django\db\models\fields\__init__.py", line 985, in get_prep_value
    return int(value)
TypeError: int() argument must be a string, a bytes-like object or a number, not 'AnonymousUser'
ERROR 2016-12-29 14:52:08,590 Internal Server Error: /API/job/
Traceback (most recent call last):
  File "C:\Python34\lib\site-packages\django\core\handlers\base.py", line 132, in get_response
    response = wrapped_callback(request, *callback_args, **callback_kwargs)
  File "C:\Python34\lib\site-packages\django\views\decorators\csrf.py", line 58, in wrapped_view
    return view_func(*args, **kwargs)
  File "C:\Python34\lib\site-packages\django\views\generic\base.py", line 71, in view
    return self.dispatch(request, *args, **kwargs)
  File "C:\Python34\lib\site-packages\rest_framework\views.py", line 466, in dispatch
    response = self.handle_exception(exc)
  File "C:\Python34\lib\site-packages\rest_framework\views.py", line 463, in dispatch
    response = handler(request, *args, **kwargs)
  File "C:\Python34\lib\site-packages\rest_framework\generics.py", line 243, in get
    return self.list(request, *args, **kwargs)
  File "C:\uav\model\views.py", line 270, in list
    queryset = Job.objects.filter(user=self.request.user)
  File "C:\Python34\lib\site-packages\django\db\models\manager.py", line 127, in manager_method
    return getattr(self.get_queryset(), name)(*args, **kwargs)
  File "C:\Python34\lib\site-packages\django\db\models\query.py", line 679, in filter
    return self._filter_or_exclude(False, *args, **kwargs)
  File "C:\Python34\lib\site-packages\django\db\models\query.py", line 697, in _filter_or_exclude
    clone.query.add_q(Q(*args, **kwargs))
  File "C:\Python34\lib\site-packages\django\db\models\sql\query.py", line 1304, in add_q
    clause, require_inner = self._add_q(where_part, self.used_aliases)
  File "C:\Python34\lib\site-packages\django\db\models\sql\query.py", line 1331, in _add_q
    current_negated=current_negated, connector=connector, allow_joins=allow_joins)
  File "C:\Python34\lib\site-packages\django\db\models\sql\query.py", line 1194, in build_filter
    lookups, value)
  File "C:\Python34\lib\site-packages\django\db\models\fields\related.py", line 1740, in get_lookup_constraint
    lookup_class(target.get_col(alias, source), val), AND)
  File "C:\Python34\lib\site-packages\django\db\models\lookups.py", line 96, in __init__
    self.rhs = self.get_prep_lookup()
  File "C:\Python34\lib\site-packages\django\db\models\lookups.py", line 134, in get_prep_lookup
    return self.lhs.output_field.get_prep_lookup(self.lookup_name, self.rhs)
  File "C:\Python34\lib\site-packages\django\db\models\fields\__init__.py", line 727, in get_prep_lookup
    return self.get_prep_value(value)
  File "C:\Python34\lib\site-packages\django\db\models\fields\__init__.py", line 985, in get_prep_value
    return int(value)
TypeError: int() argument must be a string, a bytes-like object or a number, not 'AnonymousUser'
ERROR 2016-12-29 14:52:09,344 Internal Server Error: /API/job/
Traceback (most recent call last):
  File "C:\Python34\lib\site-packages\django\core\handlers\base.py", line 132, in get_response
    response = wrapped_callback(request, *callback_args, **callback_kwargs)
  File "C:\Python34\lib\site-packages\django\views\decorators\csrf.py", line 58, in wrapped_view
    return view_func(*args, **kwargs)
  File "C:\Python34\lib\site-packages\django\views\generic\base.py", line 71, in view
    return self.dispatch(request, *args, **kwargs)
  File "C:\Python34\lib\site-packages\rest_framework\views.py", line 466, in dispatch
    response = self.handle_exception(exc)
  File "C:\Python34\lib\site-packages\rest_framework\views.py", line 463, in dispatch
    response = handler(request, *args, **kwargs)
  File "C:\Python34\lib\site-packages\rest_framework\generics.py", line 243, in get
    return self.list(request, *args, **kwargs)
  File "C:\uav\model\views.py", line 270, in list
    queryset = Job.objects.filter(user=self.request.user)
  File "C:\Python34\lib\site-packages\django\db\models\manager.py", line 127, in manager_method
    return getattr(self.get_queryset(), name)(*args, **kwargs)
  File "C:\Python34\lib\site-packages\django\db\models\query.py", line 679, in filter
    return self._filter_or_exclude(False, *args, **kwargs)
  File "C:\Python34\lib\site-packages\django\db\models\query.py", line 697, in _filter_or_exclude
    clone.query.add_q(Q(*args, **kwargs))
  File "C:\Python34\lib\site-packages\django\db\models\sql\query.py", line 1304, in add_q
    clause, require_inner = self._add_q(where_part, self.used_aliases)
  File "C:\Python34\lib\site-packages\django\db\models\sql\query.py", line 1331, in _add_q
    current_negated=current_negated, connector=connector, allow_joins=allow_joins)
  File "C:\Python34\lib\site-packages\django\db\models\sql\query.py", line 1194, in build_filter
    lookups, value)
  File "C:\Python34\lib\site-packages\django\db\models\fields\related.py", line 1740, in get_lookup_constraint
    lookup_class(target.get_col(alias, source), val), AND)
  File "C:\Python34\lib\site-packages\django\db\models\lookups.py", line 96, in __init__
    self.rhs = self.get_prep_lookup()
  File "C:\Python34\lib\site-packages\django\db\models\lookups.py", line 134, in get_prep_lookup
    return self.lhs.output_field.get_prep_lookup(self.lookup_name, self.rhs)
  File "C:\Python34\lib\site-packages\django\db\models\fields\__init__.py", line 727, in get_prep_lookup
    return self.get_prep_value(value)
  File "C:\Python34\lib\site-packages\django\db\models\fields\__init__.py", line 985, in get_prep_value
    return int(value)
TypeError: int() argument must be a string, a bytes-like object or a number, not 'AnonymousUser'
ERROR 2016-12-29 14:52:09,344 Internal Server Error: /API/job/
Traceback (most recent call last):
  File "C:\Python34\lib\site-packages\django\core\handlers\base.py", line 132, in get_response
    response = wrapped_callback(request, *callback_args, **callback_kwargs)
  File "C:\Python34\lib\site-packages\django\views\decorators\csrf.py", line 58, in wrapped_view
    return view_func(*args, **kwargs)
  File "C:\Python34\lib\site-packages\django\views\generic\base.py", line 71, in view
    return self.dispatch(request, *args, **kwargs)
  File "C:\Python34\lib\site-packages\rest_framework\views.py", line 466, in dispatch
    response = self.handle_exception(exc)
  File "C:\Python34\lib\site-packages\rest_framework\views.py", line 463, in dispatch
    response = handler(request, *args, **kwargs)
  File "C:\Python34\lib\site-packages\rest_framework\generics.py", line 243, in get
    return self.list(request, *args, **kwargs)
  File "C:\uav\model\views.py", line 270, in list
    queryset = Job.objects.filter(user=self.request.user)
  File "C:\Python34\lib\site-packages\django\db\models\manager.py", line 127, in manager_method
    return getattr(self.get_queryset(), name)(*args, **kwargs)
  File "C:\Python34\lib\site-packages\django\db\models\query.py", line 679, in filter
    return self._filter_or_exclude(False, *args, **kwargs)
  File "C:\Python34\lib\site-packages\django\db\models\query.py", line 697, in _filter_or_exclude
    clone.query.add_q(Q(*args, **kwargs))
  File "C:\Python34\lib\site-packages\django\db\models\sql\query.py", line 1304, in add_q
    clause, require_inner = self._add_q(where_part, self.used_aliases)
  File "C:\Python34\lib\site-packages\django\db\models\sql\query.py", line 1331, in _add_q
    current_negated=current_negated, connector=connector, allow_joins=allow_joins)
  File "C:\Python34\lib\site-packages\django\db\models\sql\query.py", line 1194, in build_filter
    lookups, value)
  File "C:\Python34\lib\site-packages\django\db\models\fields\related.py", line 1740, in get_lookup_constraint
    lookup_class(target.get_col(alias, source), val), AND)
  File "C:\Python34\lib\site-packages\django\db\models\lookups.py", line 96, in __init__
    self.rhs = self.get_prep_lookup()
  File "C:\Python34\lib\site-packages\django\db\models\lookups.py", line 134, in get_prep_lookup
    return self.lhs.output_field.get_prep_lookup(self.lookup_name, self.rhs)
  File "C:\Python34\lib\site-packages\django\db\models\fields\__init__.py", line 727, in get_prep_lookup
    return self.get_prep_value(value)
  File "C:\Python34\lib\site-packages\django\db\models\fields\__init__.py", line 985, in get_prep_value
    return int(value)
TypeError: int() argument must be a string, a bytes-like object or a number, not 'AnonymousUser'
ERROR 2016-12-29 14:52:10,269 Internal Server Error: /API/job/
Traceback (most recent call last):
  File "C:\Python34\lib\site-packages\django\core\handlers\base.py", line 132, in get_response
    response = wrapped_callback(request, *callback_args, **callback_kwargs)
  File "C:\Python34\lib\site-packages\django\views\decorators\csrf.py", line 58, in wrapped_view
    return view_func(*args, **kwargs)
  File "C:\Python34\lib\site-packages\django\views\generic\base.py", line 71, in view
    return self.dispatch(request, *args, **kwargs)
  File "C:\Python34\lib\site-packages\rest_framework\views.py", line 466, in dispatch
    response = self.handle_exception(exc)
  File "C:\Python34\lib\site-packages\rest_framework\views.py", line 463, in dispatch
    response = handler(request, *args, **kwargs)
  File "C:\Python34\lib\site-packages\rest_framework\generics.py", line 243, in get
    return self.list(request, *args, **kwargs)
  File "C:\uav\model\views.py", line 270, in list
    queryset = Job.objects.filter(user=self.request.user)
  File "C:\Python34\lib\site-packages\django\db\models\manager.py", line 127, in manager_method
    return getattr(self.get_queryset(), name)(*args, **kwargs)
  File "C:\Python34\lib\site-packages\django\db\models\query.py", line 679, in filter
    return self._filter_or_exclude(False, *args, **kwargs)
  File "C:\Python34\lib\site-packages\django\db\models\query.py", line 697, in _filter_or_exclude
    clone.query.add_q(Q(*args, **kwargs))
  File "C:\Python34\lib\site-packages\django\db\models\sql\query.py", line 1304, in add_q
    clause, require_inner = self._add_q(where_part, self.used_aliases)
  File "C:\Python34\lib\site-packages\django\db\models\sql\query.py", line 1331, in _add_q
    current_negated=current_negated, connector=connector, allow_joins=allow_joins)
  File "C:\Python34\lib\site-packages\django\db\models\sql\query.py", line 1194, in build_filter
    lookups, value)
  File "C:\Python34\lib\site-packages\django\db\models\fields\related.py", line 1740, in get_lookup_constraint
    lookup_class(target.get_col(alias, source), val), AND)
  File "C:\Python34\lib\site-packages\django\db\models\lookups.py", line 96, in __init__
    self.rhs = self.get_prep_lookup()
  File "C:\Python34\lib\site-packages\django\db\models\lookups.py", line 134, in get_prep_lookup
    return self.lhs.output_field.get_prep_lookup(self.lookup_name, self.rhs)
  File "C:\Python34\lib\site-packages\django\db\models\fields\__init__.py", line 727, in get_prep_lookup
    return self.get_prep_value(value)
  File "C:\Python34\lib\site-packages\django\db\models\fields\__init__.py", line 985, in get_prep_value
    return int(value)
TypeError: int() argument must be a string, a bytes-like object or a number, not 'AnonymousUser'
ERROR 2016-12-29 14:52:10,269 Internal Server Error: /API/job/
Traceback (most recent call last):
  File "C:\Python34\lib\site-packages\django\core\handlers\base.py", line 132, in get_response
    response = wrapped_callback(request, *callback_args, **callback_kwargs)
  File "C:\Python34\lib\site-packages\django\views\decorators\csrf.py", line 58, in wrapped_view
    return view_func(*args, **kwargs)
  File "C:\Python34\lib\site-packages\django\views\generic\base.py", line 71, in view
    return self.dispatch(request, *args, **kwargs)
  File "C:\Python34\lib\site-packages\rest_framework\views.py", line 466, in dispatch
    response = self.handle_exception(exc)
  File "C:\Python34\lib\site-packages\rest_framework\views.py", line 463, in dispatch
    response = handler(request, *args, **kwargs)
  File "C:\Python34\lib\site-packages\rest_framework\generics.py", line 243, in get
    return self.list(request, *args, **kwargs)
  File "C:\uav\model\views.py", line 270, in list
    queryset = Job.objects.filter(user=self.request.user)
  File "C:\Python34\lib\site-packages\django\db\models\manager.py", line 127, in manager_method
    return getattr(self.get_queryset(), name)(*args, **kwargs)
  File "C:\Python34\lib\site-packages\django\db\models\query.py", line 679, in filter
    return self._filter_or_exclude(False, *args, **kwargs)
  File "C:\Python34\lib\site-packages\django\db\models\query.py", line 697, in _filter_or_exclude
    clone.query.add_q(Q(*args, **kwargs))
  File "C:\Python34\lib\site-packages\django\db\models\sql\query.py", line 1304, in add_q
    clause, require_inner = self._add_q(where_part, self.used_aliases)
  File "C:\Python34\lib\site-packages\django\db\models\sql\query.py", line 1331, in _add_q
    current_negated=current_negated, connector=connector, allow_joins=allow_joins)
  File "C:\Python34\lib\site-packages\django\db\models\sql\query.py", line 1194, in build_filter
    lookups, value)
  File "C:\Python34\lib\site-packages\django\db\models\fields\related.py", line 1740, in get_lookup_constraint
    lookup_class(target.get_col(alias, source), val), AND)
  File "C:\Python34\lib\site-packages\django\db\models\lookups.py", line 96, in __init__
    self.rhs = self.get_prep_lookup()
  File "C:\Python34\lib\site-packages\django\db\models\lookups.py", line 134, in get_prep_lookup
    return self.lhs.output_field.get_prep_lookup(self.lookup_name, self.rhs)
  File "C:\Python34\lib\site-packages\django\db\models\fields\__init__.py", line 727, in get_prep_lookup
    return self.get_prep_value(value)
  File "C:\Python34\lib\site-packages\django\db\models\fields\__init__.py", line 985, in get_prep_value
    return int(value)
TypeError: int() argument must be a string, a bytes-like object or a number, not 'AnonymousUser'
ERROR 2016-12-29 14:53:13,736 Internal Server Error: /API/job/
Traceback (most recent call last):
  File "C:\Python34\lib\site-packages\django\core\handlers\base.py", line 132, in get_response
    response = wrapped_callback(request, *callback_args, **callback_kwargs)
  File "C:\Python34\lib\site-packages\django\views\decorators\csrf.py", line 58, in wrapped_view
    return view_func(*args, **kwargs)
  File "C:\Python34\lib\site-packages\django\views\generic\base.py", line 71, in view
    return self.dispatch(request, *args, **kwargs)
  File "C:\Python34\lib\site-packages\rest_framework\views.py", line 466, in dispatch
    response = self.handle_exception(exc)
  File "C:\Python34\lib\site-packages\rest_framework\views.py", line 463, in dispatch
    response = handler(request, *args, **kwargs)
  File "C:\Python34\lib\site-packages\rest_framework\generics.py", line 243, in get
    return self.list(request, *args, **kwargs)
  File "C:\uav\model\views.py", line 270, in list
    queryset = Job.objects.filter(user=self.request.user)
  File "C:\Python34\lib\site-packages\django\db\models\manager.py", line 127, in manager_method
    return getattr(self.get_queryset(), name)(*args, **kwargs)
  File "C:\Python34\lib\site-packages\django\db\models\query.py", line 679, in filter
    return self._filter_or_exclude(False, *args, **kwargs)
  File "C:\Python34\lib\site-packages\django\db\models\query.py", line 697, in _filter_or_exclude
    clone.query.add_q(Q(*args, **kwargs))
  File "C:\Python34\lib\site-packages\django\db\models\sql\query.py", line 1304, in add_q
    clause, require_inner = self._add_q(where_part, self.used_aliases)
  File "C:\Python34\lib\site-packages\django\db\models\sql\query.py", line 1331, in _add_q
    current_negated=current_negated, connector=connector, allow_joins=allow_joins)
  File "C:\Python34\lib\site-packages\django\db\models\sql\query.py", line 1194, in build_filter
    lookups, value)
  File "C:\Python34\lib\site-packages\django\db\models\fields\related.py", line 1740, in get_lookup_constraint
    lookup_class(target.get_col(alias, source), val), AND)
  File "C:\Python34\lib\site-packages\django\db\models\lookups.py", line 96, in __init__
    self.rhs = self.get_prep_lookup()
  File "C:\Python34\lib\site-packages\django\db\models\lookups.py", line 134, in get_prep_lookup
    return self.lhs.output_field.get_prep_lookup(self.lookup_name, self.rhs)
  File "C:\Python34\lib\site-packages\django\db\models\fields\__init__.py", line 727, in get_prep_lookup
    return self.get_prep_value(value)
  File "C:\Python34\lib\site-packages\django\db\models\fields\__init__.py", line 985, in get_prep_value
    return int(value)
TypeError: int() argument must be a string, a bytes-like object or a number, not 'AnonymousUser'
ERROR 2016-12-29 14:53:13,736 Internal Server Error: /API/job/
Traceback (most recent call last):
  File "C:\Python34\lib\site-packages\django\core\handlers\base.py", line 132, in get_response
    response = wrapped_callback(request, *callback_args, **callback_kwargs)
  File "C:\Python34\lib\site-packages\django\views\decorators\csrf.py", line 58, in wrapped_view
    return view_func(*args, **kwargs)
  File "C:\Python34\lib\site-packages\django\views\generic\base.py", line 71, in view
    return self.dispatch(request, *args, **kwargs)
  File "C:\Python34\lib\site-packages\rest_framework\views.py", line 466, in dispatch
    response = self.handle_exception(exc)
  File "C:\Python34\lib\site-packages\rest_framework\views.py", line 463, in dispatch
    response = handler(request, *args, **kwargs)
  File "C:\Python34\lib\site-packages\rest_framework\generics.py", line 243, in get
    return self.list(request, *args, **kwargs)
  File "C:\uav\model\views.py", line 270, in list
    queryset = Job.objects.filter(user=self.request.user)
  File "C:\Python34\lib\site-packages\django\db\models\manager.py", line 127, in manager_method
    return getattr(self.get_queryset(), name)(*args, **kwargs)
  File "C:\Python34\lib\site-packages\django\db\models\query.py", line 679, in filter
    return self._filter_or_exclude(False, *args, **kwargs)
  File "C:\Python34\lib\site-packages\django\db\models\query.py", line 697, in _filter_or_exclude
    clone.query.add_q(Q(*args, **kwargs))
  File "C:\Python34\lib\site-packages\django\db\models\sql\query.py", line 1304, in add_q
    clause, require_inner = self._add_q(where_part, self.used_aliases)
  File "C:\Python34\lib\site-packages\django\db\models\sql\query.py", line 1331, in _add_q
    current_negated=current_negated, connector=connector, allow_joins=allow_joins)
  File "C:\Python34\lib\site-packages\django\db\models\sql\query.py", line 1194, in build_filter
    lookups, value)
  File "C:\Python34\lib\site-packages\django\db\models\fields\related.py", line 1740, in get_lookup_constraint
    lookup_class(target.get_col(alias, source), val), AND)
  File "C:\Python34\lib\site-packages\django\db\models\lookups.py", line 96, in __init__
    self.rhs = self.get_prep_lookup()
  File "C:\Python34\lib\site-packages\django\db\models\lookups.py", line 134, in get_prep_lookup
    return self.lhs.output_field.get_prep_lookup(self.lookup_name, self.rhs)
  File "C:\Python34\lib\site-packages\django\db\models\fields\__init__.py", line 727, in get_prep_lookup
    return self.get_prep_value(value)
  File "C:\Python34\lib\site-packages\django\db\models\fields\__init__.py", line 985, in get_prep_value
    return int(value)
TypeError: int() argument must be a string, a bytes-like object or a number, not 'AnonymousUser'
WARNING 2016-12-29 14:53:20,494 Not Found: /announce.php
WARNING 2016-12-29 14:53:20,494 Not Found: /announce.php
WARNING 2016-12-29 14:53:38,452 Not Found: /announce.php
WARNING 2016-12-29 14:53:38,452 Not Found: /announce.php
WARNING 2016-12-29 14:54:08,485 Not Found: /announce.php
WARNING 2016-12-29 14:54:08,487 Not Found: /announce.php
WARNING 2016-12-29 14:54:08,488 Not Found: /announce.php
WARNING 2016-12-29 14:54:08,485 Not Found: /announce.php
WARNING 2016-12-29 14:54:08,487 Not Found: /announce.php
WARNING 2016-12-29 14:54:08,488 Not Found: /announce.php
WARNING 2016-12-29 14:54:11,449 Not Found: /announce.php
WARNING 2016-12-29 14:54:11,449 Not Found: /announce.php
WARNING 2016-12-29 14:54:20,444 Not Found: /announce.php
WARNING 2016-12-29 14:54:20,444 Not Found: /announce.php
ERROR 2016-12-29 14:55:52,701 Internal Server Error: /API/job/
Traceback (most recent call last):
  File "C:\Python34\lib\site-packages\django\core\handlers\base.py", line 132, in get_response
    response = wrapped_callback(request, *callback_args, **callback_kwargs)
  File "C:\Python34\lib\site-packages\django\views\decorators\csrf.py", line 58, in wrapped_view
    return view_func(*args, **kwargs)
  File "C:\Python34\lib\site-packages\django\views\generic\base.py", line 71, in view
    return self.dispatch(request, *args, **kwargs)
  File "C:\Python34\lib\site-packages\rest_framework\views.py", line 466, in dispatch
    response = self.handle_exception(exc)
  File "C:\Python34\lib\site-packages\rest_framework\views.py", line 463, in dispatch
    response = handler(request, *args, **kwargs)
  File "C:\Python34\lib\site-packages\rest_framework\generics.py", line 243, in get
    return self.list(request, *args, **kwargs)
  File "C:\uav\model\views.py", line 270, in list
    queryset = Job.objects.filter(user=self.request.user)
  File "C:\Python34\lib\site-packages\django\db\models\manager.py", line 127, in manager_method
    return getattr(self.get_queryset(), name)(*args, **kwargs)
  File "C:\Python34\lib\site-packages\django\db\models\query.py", line 679, in filter
    return self._filter_or_exclude(False, *args, **kwargs)
  File "C:\Python34\lib\site-packages\django\db\models\query.py", line 697, in _filter_or_exclude
    clone.query.add_q(Q(*args, **kwargs))
  File "C:\Python34\lib\site-packages\django\db\models\sql\query.py", line 1304, in add_q
    clause, require_inner = self._add_q(where_part, self.used_aliases)
  File "C:\Python34\lib\site-packages\django\db\models\sql\query.py", line 1331, in _add_q
    current_negated=current_negated, connector=connector, allow_joins=allow_joins)
  File "C:\Python34\lib\site-packages\django\db\models\sql\query.py", line 1194, in build_filter
    lookups, value)
  File "C:\Python34\lib\site-packages\django\db\models\fields\related.py", line 1740, in get_lookup_constraint
    lookup_class(target.get_col(alias, source), val), AND)
  File "C:\Python34\lib\site-packages\django\db\models\lookups.py", line 96, in __init__
    self.rhs = self.get_prep_lookup()
  File "C:\Python34\lib\site-packages\django\db\models\lookups.py", line 134, in get_prep_lookup
    return self.lhs.output_field.get_prep_lookup(self.lookup_name, self.rhs)
  File "C:\Python34\lib\site-packages\django\db\models\fields\__init__.py", line 727, in get_prep_lookup
    return self.get_prep_value(value)
  File "C:\Python34\lib\site-packages\django\db\models\fields\__init__.py", line 985, in get_prep_value
    return int(value)
TypeError: int() argument must be a string, a bytes-like object or a number, not 'AnonymousUser'
ERROR 2016-12-29 14:55:52,701 Internal Server Error: /API/job/
Traceback (most recent call last):
  File "C:\Python34\lib\site-packages\django\core\handlers\base.py", line 132, in get_response
    response = wrapped_callback(request, *callback_args, **callback_kwargs)
  File "C:\Python34\lib\site-packages\django\views\decorators\csrf.py", line 58, in wrapped_view
    return view_func(*args, **kwargs)
  File "C:\Python34\lib\site-packages\django\views\generic\base.py", line 71, in view
    return self.dispatch(request, *args, **kwargs)
  File "C:\Python34\lib\site-packages\rest_framework\views.py", line 466, in dispatch
    response = self.handle_exception(exc)
  File "C:\Python34\lib\site-packages\rest_framework\views.py", line 463, in dispatch
    response = handler(request, *args, **kwargs)
  File "C:\Python34\lib\site-packages\rest_framework\generics.py", line 243, in get
    return self.list(request, *args, **kwargs)
  File "C:\uav\model\views.py", line 270, in list
    queryset = Job.objects.filter(user=self.request.user)
  File "C:\Python34\lib\site-packages\django\db\models\manager.py", line 127, in manager_method
    return getattr(self.get_queryset(), name)(*args, **kwargs)
  File "C:\Python34\lib\site-packages\django\db\models\query.py", line 679, in filter
    return self._filter_or_exclude(False, *args, **kwargs)
  File "C:\Python34\lib\site-packages\django\db\models\query.py", line 697, in _filter_or_exclude
    clone.query.add_q(Q(*args, **kwargs))
  File "C:\Python34\lib\site-packages\django\db\models\sql\query.py", line 1304, in add_q
    clause, require_inner = self._add_q(where_part, self.used_aliases)
  File "C:\Python34\lib\site-packages\django\db\models\sql\query.py", line 1331, in _add_q
    current_negated=current_negated, connector=connector, allow_joins=allow_joins)
  File "C:\Python34\lib\site-packages\django\db\models\sql\query.py", line 1194, in build_filter
    lookups, value)
  File "C:\Python34\lib\site-packages\django\db\models\fields\related.py", line 1740, in get_lookup_constraint
    lookup_class(target.get_col(alias, source), val), AND)
  File "C:\Python34\lib\site-packages\django\db\models\lookups.py", line 96, in __init__
    self.rhs = self.get_prep_lookup()
  File "C:\Python34\lib\site-packages\django\db\models\lookups.py", line 134, in get_prep_lookup
    return self.lhs.output_field.get_prep_lookup(self.lookup_name, self.rhs)
  File "C:\Python34\lib\site-packages\django\db\models\fields\__init__.py", line 727, in get_prep_lookup
    return self.get_prep_value(value)
  File "C:\Python34\lib\site-packages\django\db\models\fields\__init__.py", line 985, in get_prep_value
    return int(value)
TypeError: int() argument must be a string, a bytes-like object or a number, not 'AnonymousUser'
ERROR 2016-12-29 14:58:47,089 Internal Server Error: /API/job/
Traceback (most recent call last):
  File "C:\Python34\lib\site-packages\django\core\handlers\base.py", line 132, in get_response
    response = wrapped_callback(request, *callback_args, **callback_kwargs)
  File "C:\Python34\lib\site-packages\django\views\decorators\csrf.py", line 58, in wrapped_view
    return view_func(*args, **kwargs)
  File "C:\Python34\lib\site-packages\django\views\generic\base.py", line 71, in view
    return self.dispatch(request, *args, **kwargs)
  File "C:\Python34\lib\site-packages\rest_framework\views.py", line 466, in dispatch
    response = self.handle_exception(exc)
  File "C:\Python34\lib\site-packages\rest_framework\views.py", line 463, in dispatch
    response = handler(request, *args, **kwargs)
  File "C:\Python34\lib\site-packages\rest_framework\generics.py", line 243, in get
    return self.list(request, *args, **kwargs)
  File "C:\uav\model\views.py", line 273, in list
    page = self.paginate_queryset(queryset)
UnboundLocalError: local variable 'queryset' referenced before assignment
ERROR 2016-12-29 14:58:47,089 Internal Server Error: /API/job/
Traceback (most recent call last):
  File "C:\Python34\lib\site-packages\django\core\handlers\base.py", line 132, in get_response
    response = wrapped_callback(request, *callback_args, **callback_kwargs)
  File "C:\Python34\lib\site-packages\django\views\decorators\csrf.py", line 58, in wrapped_view
    return view_func(*args, **kwargs)
  File "C:\Python34\lib\site-packages\django\views\generic\base.py", line 71, in view
    return self.dispatch(request, *args, **kwargs)
  File "C:\Python34\lib\site-packages\rest_framework\views.py", line 466, in dispatch
    response = self.handle_exception(exc)
  File "C:\Python34\lib\site-packages\rest_framework\views.py", line 463, in dispatch
    response = handler(request, *args, **kwargs)
  File "C:\Python34\lib\site-packages\rest_framework\generics.py", line 243, in get
    return self.list(request, *args, **kwargs)
  File "C:\uav\model\views.py", line 273, in list
    page = self.paginate_queryset(queryset)
UnboundLocalError: local variable 'queryset' referenced before assignment
WARNING 2016-12-29 15:09:51,643 Not Found: /upload/job/border/LLHT.txt
WARNING 2016-12-29 15:09:51,643 Not Found: /upload/job/border/LLHT.txt
WARNING 2016-12-29 15:17:29,505 Not Found: /announce.php
WARNING 2016-12-29 15:17:29,508 Not Found: /announce.php
WARNING 2016-12-29 15:17:29,505 Not Found: /announce.php
WARNING 2016-12-29 15:17:29,508 Not Found: /announce.php
WARNING 2016-12-29 15:17:32,468 Not Found: /announce.php
WARNING 2016-12-29 15:17:32,468 Not Found: /announce.php
WARNING 2016-12-29 15:17:35,456 Not Found: /announce.php
WARNING 2016-12-29 15:17:35,457 Not Found: /announce.php
WARNING 2016-12-29 15:17:35,458 Not Found: /announce.php
WARNING 2016-12-29 15:17:35,456 Not Found: /announce.php
WARNING 2016-12-29 15:17:35,457 Not Found: /announce.php
WARNING 2016-12-29 15:17:35,458 Not Found: /announce.php
WARNING 2016-12-29 15:17:37,464 Not Found: /announce.php
WARNING 2016-12-29 15:17:37,464 Not Found: /announce.php
WARNING 2016-12-29 15:19:32,466 Not Found: /announce.php
WARNING 2016-12-29 15:19:32,469 Not Found: /announce.php
WARNING 2016-12-29 15:19:32,466 Not Found: /announce.php
WARNING 2016-12-29 15:19:32,469 Not Found: /announce.php
WARNING 2016-12-29 15:19:35,463 Not Found: /announce.php
WARNING 2016-12-29 15:19:35,466 Not Found: /announce.php
WARNING 2016-12-29 15:19:35,468 Not Found: /announce.php
WARNING 2016-12-29 15:19:35,463 Not Found: /announce.php
WARNING 2016-12-29 15:19:35,466 Not Found: /announce.php
WARNING 2016-12-29 15:19:35,468 Not Found: /announce.php
WARNING 2016-12-29 15:19:38,475 Not Found: /announce.php
WARNING 2016-12-29 15:19:38,475 Not Found: /announce.php
WARNING 2016-12-29 15:19:41,479 Not Found: /announce.php
WARNING 2016-12-29 15:19:41,479 Not Found: /announce.php
WARNING 2016-12-29 15:21:02,462 Not Found: /announce.php
WARNING 2016-12-29 15:21:02,462 Not Found: /announce.php
WARNING 2016-12-29 15:21:23,474 Not Found: /announce.php
WARNING 2016-12-29 15:21:23,474 Not Found: /announce.php
WARNING 2016-12-29 15:21:53,462 Not Found: /announce.php
WARNING 2016-12-29 15:21:53,464 Not Found: /announce.php
WARNING 2016-12-29 15:21:53,466 Not Found: /announce.php
WARNING 2016-12-29 15:21:53,462 Not Found: /announce.php
WARNING 2016-12-29 15:21:53,468 Not Found: /announce.php
WARNING 2016-12-29 15:21:53,464 Not Found: /announce.php
WARNING 2016-12-29 15:21:53,466 Not Found: /announce.php
WARNING 2016-12-29 15:21:53,468 Not Found: /announce.php
WARNING 2016-12-29 15:21:56,479 Not Found: /announce.php
WARNING 2016-12-29 15:21:56,479 Not Found: /announce.php
WARNING 2016-12-29 15:22:02,478 Not Found: /announce.php
WARNING 2016-12-29 15:22:02,478 Not Found: /announce.php
WARNING 2016-12-29 15:23:23,468 Not Found: /announce.php
WARNING 2016-12-29 15:23:23,468 Not Found: /announce.php
WARNING 2016-12-29 15:23:41,482 Not Found: /announce.php
WARNING 2016-12-29 15:23:41,482 Not Found: /announce.php
WARNING 2016-12-29 15:24:11,461 Not Found: /announce.php
WARNING 2016-12-29 15:24:11,463 Not Found: /announce.php
WARNING 2016-12-29 15:24:11,464 Not Found: /announce.php
WARNING 2016-12-29 15:24:11,461 Not Found: /announce.php
WARNING 2016-12-29 15:24:11,463 Not Found: /announce.php
WARNING 2016-12-29 15:24:11,464 Not Found: /announce.php
WARNING 2016-12-29 15:24:14,482 Not Found: /announce.php
WARNING 2016-12-29 15:24:14,482 Not Found: /announce.php
WARNING 2016-12-29 15:24:23,480 Not Found: /announce.php
WARNING 2016-12-29 15:24:23,480 Not Found: /announce.php
WARNING 2016-12-29 15:47:31,104 Not Found: /announce.php
WARNING 2016-12-29 15:47:31,105 Not Found: /announce.php
WARNING 2016-12-29 15:47:31,104 Not Found: /announce.php
WARNING 2016-12-29 15:47:31,105 Not Found: /announce.php
WARNING 2016-12-29 15:47:34,100 Not Found: /announce.php
WARNING 2016-12-29 15:47:34,100 Not Found: /announce.php
WARNING 2016-12-29 15:47:37,123 Not Found: /announce.php
WARNING 2016-12-29 15:47:37,124 Not Found: /announce.php
WARNING 2016-12-29 15:47:37,126 Not Found: /announce.php
WARNING 2016-12-29 15:47:37,123 Not Found: /announce.php
WARNING 2016-12-29 15:47:37,124 Not Found: /announce.php
WARNING 2016-12-29 15:47:37,126 Not Found: /announce.php
WARNING 2016-12-29 15:47:39,138 Not Found: /announce.php
WARNING 2016-12-29 15:47:39,138 Not Found: /announce.php
WARNING 2016-12-29 15:49:34,143 Not Found: /announce.php
WARNING 2016-12-29 15:49:34,145 Not Found: /announce.php
WARNING 2016-12-29 15:49:34,143 Not Found: /announce.php
WARNING 2016-12-29 15:49:34,145 Not Found: /announce.php
WARNING 2016-12-29 15:49:37,127 Not Found: /announce.php
WARNING 2016-12-29 15:49:37,129 Not Found: /announce.php
WARNING 2016-12-29 15:49:37,131 Not Found: /announce.php
WARNING 2016-12-29 15:49:37,127 Not Found: /announce.php
WARNING 2016-12-29 15:49:37,129 Not Found: /announce.php
WARNING 2016-12-29 15:49:37,131 Not Found: /announce.php
WARNING 2016-12-29 15:49:40,146 Not Found: /announce.php
WARNING 2016-12-29 15:49:40,146 Not Found: /announce.php
WARNING 2016-12-29 15:49:43,127 Not Found: /announce.php
WARNING 2016-12-29 15:49:43,127 Not Found: /announce.php
WARNING 2016-12-29 15:51:04,105 Not Found: /announce.php
WARNING 2016-12-29 15:51:04,105 Not Found: /announce.php
WARNING 2016-12-29 15:51:25,135 Not Found: /announce.php
WARNING 2016-12-29 15:51:25,135 Not Found: /announce.php
WARNING 2016-12-29 15:51:55,121 Not Found: /announce.php
WARNING 2016-12-29 15:51:55,122 Not Found: /announce.php
WARNING 2016-12-29 15:51:55,122 Not Found: /announce.php
WARNING 2016-12-29 15:51:55,123 Not Found: /announce.php
WARNING 2016-12-29 15:51:55,121 Not Found: /announce.php
WARNING 2016-12-29 15:51:55,122 Not Found: /announce.php
WARNING 2016-12-29 15:51:55,122 Not Found: /announce.php
WARNING 2016-12-29 15:51:55,123 Not Found: /announce.php
WARNING 2016-12-29 15:51:58,114 Not Found: /announce.php
WARNING 2016-12-29 15:51:58,114 Not Found: /announce.php
WARNING 2016-12-29 15:52:04,131 Not Found: /announce.php
WARNING 2016-12-29 15:52:04,131 Not Found: /announce.php
WARNING 2016-12-29 15:53:25,126 Not Found: /announce.php
WARNING 2016-12-29 15:53:25,126 Not Found: /announce.php
WARNING 2016-12-29 15:53:43,100 Not Found: /announce.php
WARNING 2016-12-29 15:53:43,100 Not Found: /announce.php
WARNING 2016-12-29 15:54:13,128 Not Found: /announce.php
WARNING 2016-12-29 15:54:13,129 Not Found: /announce.php
WARNING 2016-12-29 15:54:13,130 Not Found: /announce.php
WARNING 2016-12-29 15:54:13,128 Not Found: /announce.php
WARNING 2016-12-29 15:54:13,129 Not Found: /announce.php
WARNING 2016-12-29 15:54:13,130 Not Found: /announce.php
WARNING 2016-12-29 15:54:16,131 Not Found: /announce.php
WARNING 2016-12-29 15:54:16,131 Not Found: /announce.php
WARNING 2016-12-29 15:54:25,120 Not Found: /announce.php
WARNING 2016-12-29 15:54:25,120 Not Found: /announce.php
WARNING 2016-12-29 16:17:34,168 Not Found: /announce.php
WARNING 2016-12-29 16:17:34,169 Not Found: /announce.php
WARNING 2016-12-29 16:17:34,168 Not Found: /announce.php
WARNING 2016-12-29 16:17:34,169 Not Found: /announce.php
WARNING 2016-12-29 16:17:37,114 Not Found: /announce.php
WARNING 2016-12-29 16:17:37,114 Not Found: /announce.php
WARNING 2016-12-29 16:17:40,132 Not Found: /announce.php
WARNING 2016-12-29 16:17:40,135 Not Found: /announce.php
WARNING 2016-12-29 16:17:40,137 Not Found: /announce.php
WARNING 2016-12-29 16:17:40,132 Not Found: /announce.php
WARNING 2016-12-29 16:17:40,135 Not Found: /announce.php
WARNING 2016-12-29 16:17:40,137 Not Found: /announce.php
WARNING 2016-12-29 16:17:42,135 Not Found: /announce.php
WARNING 2016-12-29 16:17:42,135 Not Found: /announce.php
WARNING 2016-12-29 16:19:37,130 Not Found: /announce.php
WARNING 2016-12-29 16:19:37,131 Not Found: /announce.php
WARNING 2016-12-29 16:19:37,130 Not Found: /announce.php
WARNING 2016-12-29 16:19:37,131 Not Found: /announce.php
WARNING 2016-12-29 16:19:40,110 Not Found: /announce.php
WARNING 2016-12-29 16:19:40,112 Not Found: /announce.php
WARNING 2016-12-29 16:19:40,114 Not Found: /announce.php
WARNING 2016-12-29 16:19:40,110 Not Found: /announce.php
WARNING 2016-12-29 16:19:40,112 Not Found: /announce.php
WARNING 2016-12-29 16:19:40,114 Not Found: /announce.php
WARNING 2016-12-29 16:19:43,118 Not Found: /announce.php
WARNING 2016-12-29 16:19:43,118 Not Found: /announce.php
WARNING 2016-12-29 16:19:46,133 Not Found: /announce.php
WARNING 2016-12-29 16:19:46,133 Not Found: /announce.php
WARNING 2016-12-29 16:21:07,129 Not Found: /announce.php
WARNING 2016-12-29 16:21:07,129 Not Found: /announce.php
WARNING 2016-12-29 16:21:28,143 Not Found: /announce.php
WARNING 2016-12-29 16:21:28,143 Not Found: /announce.php
WARNING 2016-12-29 16:21:58,127 Not Found: /announce.php
WARNING 2016-12-29 16:21:58,128 Not Found: /announce.php
WARNING 2016-12-29 16:21:58,128 Not Found: /announce.php
WARNING 2016-12-29 16:21:58,129 Not Found: /announce.php
WARNING 2016-12-29 16:21:58,127 Not Found: /announce.php
WARNING 2016-12-29 16:21:58,128 Not Found: /announce.php
WARNING 2016-12-29 16:21:58,128 Not Found: /announce.php
WARNING 2016-12-29 16:21:58,129 Not Found: /announce.php
WARNING 2016-12-29 16:22:01,131 Not Found: /announce.php
WARNING 2016-12-29 16:22:01,131 Not Found: /announce.php
WARNING 2016-12-29 16:22:07,126 Not Found: /announce.php
WARNING 2016-12-29 16:22:07,126 Not Found: /announce.php
WARNING 2016-12-29 16:23:28,111 Not Found: /announce.php
WARNING 2016-12-29 16:23:28,111 Not Found: /announce.php
WARNING 2016-12-29 16:23:46,137 Not Found: /announce.php
WARNING 2016-12-29 16:23:46,137 Not Found: /announce.php
WARNING 2016-12-29 16:24:16,117 Not Found: /announce.php
WARNING 2016-12-29 16:24:16,118 Not Found: /announce.php
WARNING 2016-12-29 16:24:16,119 Not Found: /announce.php
WARNING 2016-12-29 16:24:16,117 Not Found: /announce.php
WARNING 2016-12-29 16:24:16,118 Not Found: /announce.php
WARNING 2016-12-29 16:24:16,119 Not Found: /announce.php
WARNING 2016-12-29 16:24:19,154 Not Found: /announce.php
WARNING 2016-12-29 16:24:19,154 Not Found: /announce.php
WARNING 2016-12-29 16:24:28,123 Not Found: /announce.php
WARNING 2016-12-29 16:24:28,123 Not Found: /announce.php
WARNING 2016-12-29 16:47:37,121 Not Found: /announce.php
WARNING 2016-12-29 16:47:37,123 Not Found: /announce.php
WARNING 2016-12-29 16:47:37,121 Not Found: /announce.php
WARNING 2016-12-29 16:47:37,123 Not Found: /announce.php
WARNING 2016-12-29 16:47:40,146 Not Found: /announce.php
WARNING 2016-12-29 16:47:40,146 Not Found: /announce.php
WARNING 2016-12-29 16:47:43,122 Not Found: /announce.php
WARNING 2016-12-29 16:47:43,123 Not Found: /announce.php
WARNING 2016-12-29 16:47:43,124 Not Found: /announce.php
WARNING 2016-12-29 16:47:43,122 Not Found: /announce.php
WARNING 2016-12-29 16:47:43,123 Not Found: /announce.php
WARNING 2016-12-29 16:47:43,124 Not Found: /announce.php
WARNING 2016-12-29 16:47:45,134 Not Found: /announce.php
WARNING 2016-12-29 16:47:45,134 Not Found: /announce.php
WARNING 2016-12-29 16:49:40,149 Not Found: /announce.php
WARNING 2016-12-29 16:49:40,151 Not Found: /announce.php
WARNING 2016-12-29 16:49:40,149 Not Found: /announce.php
WARNING 2016-12-29 16:49:40,151 Not Found: /announce.php
WARNING 2016-12-29 16:49:43,139 Not Found: /announce.php
WARNING 2016-12-29 16:49:43,142 Not Found: /announce.php
WARNING 2016-12-29 16:49:43,145 Not Found: /announce.php
WARNING 2016-12-29 16:49:43,139 Not Found: /announce.php
WARNING 2016-12-29 16:49:43,142 Not Found: /announce.php
WARNING 2016-12-29 16:49:43,145 Not Found: /announce.php
WARNING 2016-12-29 16:49:46,127 Not Found: /announce.php
WARNING 2016-12-29 16:49:46,127 Not Found: /announce.php
WARNING 2016-12-29 16:49:49,117 Not Found: /announce.php
WARNING 2016-12-29 16:49:49,117 Not Found: /announce.php
WARNING 2016-12-29 16:51:10,138 Not Found: /announce.php
WARNING 2016-12-29 16:51:10,138 Not Found: /announce.php
WARNING 2016-12-29 16:51:31,119 Not Found: /announce.php
WARNING 2016-12-29 16:51:31,119 Not Found: /announce.php
WARNING 2016-12-29 16:52:01,147 Not Found: /announce.php
WARNING 2016-12-29 16:52:01,149 Not Found: /announce.php
WARNING 2016-12-29 16:52:01,151 Not Found: /announce.php
WARNING 2016-12-29 16:52:01,153 Not Found: /announce.php
WARNING 2016-12-29 16:52:01,147 Not Found: /announce.php
WARNING 2016-12-29 16:52:01,149 Not Found: /announce.php
WARNING 2016-12-29 16:52:01,151 Not Found: /announce.php
WARNING 2016-12-29 16:52:01,153 Not Found: /announce.php
WARNING 2016-12-29 16:52:04,143 Not Found: /announce.php
WARNING 2016-12-29 16:52:04,143 Not Found: /announce.php
WARNING 2016-12-29 16:52:10,118 Not Found: /announce.php
WARNING 2016-12-29 16:52:10,118 Not Found: /announce.php
WARNING 2016-12-29 16:53:31,128 Not Found: /announce.php
WARNING 2016-12-29 16:53:31,128 Not Found: /announce.php
WARNING 2016-12-29 16:53:49,096 Not Found: /announce.php
WARNING 2016-12-29 16:53:49,096 Not Found: /announce.php
WARNING 2016-12-29 16:54:19,136 Not Found: /announce.php
WARNING 2016-12-29 16:54:19,137 Not Found: /announce.php
WARNING 2016-12-29 16:54:19,138 Not Found: /announce.php
WARNING 2016-12-29 16:54:19,136 Not Found: /announce.php
WARNING 2016-12-29 16:54:19,137 Not Found: /announce.php
WARNING 2016-12-29 16:54:19,138 Not Found: /announce.php
WARNING 2016-12-29 16:54:22,134 Not Found: /announce.php
WARNING 2016-12-29 16:54:22,134 Not Found: /announce.php
WARNING 2016-12-29 16:54:31,148 Not Found: /announce.php
WARNING 2016-12-29 16:54:31,148 Not Found: /announce.php
WARNING 2016-12-29 17:17:40,185 Not Found: /announce.php
WARNING 2016-12-29 17:17:40,186 Not Found: /announce.php
WARNING 2016-12-29 17:17:40,185 Not Found: /announce.php
WARNING 2016-12-29 17:17:40,186 Not Found: /announce.php
WARNING 2016-12-29 17:17:43,131 Not Found: /announce.php
WARNING 2016-12-29 17:17:43,131 Not Found: /announce.php
WARNING 2016-12-29 17:17:46,126 Not Found: /announce.php
WARNING 2016-12-29 17:17:46,128 Not Found: /announce.php
WARNING 2016-12-29 17:17:46,131 Not Found: /announce.php
WARNING 2016-12-29 17:17:46,126 Not Found: /announce.php
WARNING 2016-12-29 17:17:46,128 Not Found: /announce.php
WARNING 2016-12-29 17:17:46,131 Not Found: /announce.php
WARNING 2016-12-29 17:17:48,119 Not Found: /announce.php
WARNING 2016-12-29 17:17:48,119 Not Found: /announce.php
WARNING 2016-12-29 17:19:43,127 Not Found: /announce.php
WARNING 2016-12-29 17:19:43,129 Not Found: /announce.php
WARNING 2016-12-29 17:19:43,127 Not Found: /announce.php
WARNING 2016-12-29 17:19:43,129 Not Found: /announce.php
WARNING 2016-12-29 17:19:46,124 Not Found: /announce.php
WARNING 2016-12-29 17:19:46,126 Not Found: /announce.php
WARNING 2016-12-29 17:19:46,128 Not Found: /announce.php
WARNING 2016-12-29 17:19:46,124 Not Found: /announce.php
WARNING 2016-12-29 17:19:46,126 Not Found: /announce.php
WARNING 2016-12-29 17:19:46,128 Not Found: /announce.php
WARNING 2016-12-29 17:19:49,131 Not Found: /announce.php
WARNING 2016-12-29 17:19:49,131 Not Found: /announce.php
WARNING 2016-12-29 17:19:52,123 Not Found: /announce.php
WARNING 2016-12-29 17:19:52,123 Not Found: /announce.php
WARNING 2016-12-29 17:21:13,100 Not Found: /announce.php
WARNING 2016-12-29 17:21:13,100 Not Found: /announce.php
WARNING 2016-12-29 17:21:34,119 Not Found: /announce.php
WARNING 2016-12-29 17:21:34,119 Not Found: /announce.php
WARNING 2016-12-29 17:22:04,121 Not Found: /announce.php
WARNING 2016-12-29 17:22:04,124 Not Found: /announce.php
WARNING 2016-12-29 17:22:04,126 Not Found: /announce.php
WARNING 2016-12-29 17:22:04,128 Not Found: /announce.php
WARNING 2016-12-29 17:22:04,121 Not Found: /announce.php
WARNING 2016-12-29 17:22:04,124 Not Found: /announce.php
WARNING 2016-12-29 17:22:04,126 Not Found: /announce.php
WARNING 2016-12-29 17:22:04,128 Not Found: /announce.php
WARNING 2016-12-29 17:22:07,159 Not Found: /announce.php
WARNING 2016-12-29 17:22:07,159 Not Found: /announce.php
WARNING 2016-12-29 17:22:13,132 Not Found: /announce.php
WARNING 2016-12-29 17:22:13,132 Not Found: /announce.php
WARNING 2016-12-29 17:23:34,148 Not Found: /announce.php
WARNING 2016-12-29 17:23:34,148 Not Found: /announce.php
WARNING 2016-12-29 17:23:52,128 Not Found: /announce.php
WARNING 2016-12-29 17:23:52,128 Not Found: /announce.php
WARNING 2016-12-29 17:24:22,127 Not Found: /announce.php
WARNING 2016-12-29 17:24:22,128 Not Found: /announce.php
WARNING 2016-12-29 17:24:22,129 Not Found: /announce.php
WARNING 2016-12-29 17:24:22,127 Not Found: /announce.php
WARNING 2016-12-29 17:24:22,128 Not Found: /announce.php
WARNING 2016-12-29 17:24:22,129 Not Found: /announce.php
WARNING 2016-12-29 17:24:25,101 Not Found: /announce.php
WARNING 2016-12-29 17:24:25,101 Not Found: /announce.php
WARNING 2016-12-29 17:24:34,134 Not Found: /announce.php
WARNING 2016-12-29 17:24:34,134 Not Found: /announce.php
WARNING 2016-12-29 17:47:43,135 Not Found: /announce.php
WARNING 2016-12-29 17:47:43,138 Not Found: /announce.php
WARNING 2016-12-29 17:47:43,135 Not Found: /announce.php
WARNING 2016-12-29 17:47:43,138 Not Found: /announce.php
WARNING 2016-12-29 17:47:46,112 Not Found: /announce.php
WARNING 2016-12-29 17:47:46,112 Not Found: /announce.php
WARNING 2016-12-29 17:47:49,134 Not Found: /announce.php
WARNING 2016-12-29 17:47:49,135 Not Found: /announce.php
WARNING 2016-12-29 17:47:49,135 Not Found: /announce.php
WARNING 2016-12-29 17:47:49,134 Not Found: /announce.php
WARNING 2016-12-29 17:47:49,135 Not Found: /announce.php
WARNING 2016-12-29 17:47:49,135 Not Found: /announce.php
WARNING 2016-12-29 17:47:51,135 Not Found: /announce.php
WARNING 2016-12-29 17:47:51,135 Not Found: /announce.php
WARNING 2016-12-29 17:49:46,146 Not Found: /announce.php
WARNING 2016-12-29 17:49:46,149 Not Found: /announce.php
WARNING 2016-12-29 17:49:46,146 Not Found: /announce.php
WARNING 2016-12-29 17:49:46,149 Not Found: /announce.php
WARNING 2016-12-29 17:49:49,134 Not Found: /announce.php
WARNING 2016-12-29 17:49:49,136 Not Found: /announce.php
WARNING 2016-12-29 17:49:49,138 Not Found: /announce.php
WARNING 2016-12-29 17:49:49,134 Not Found: /announce.php
WARNING 2016-12-29 17:49:49,136 Not Found: /announce.php
WARNING 2016-12-29 17:49:49,138 Not Found: /announce.php
WARNING 2016-12-29 17:49:52,123 Not Found: /announce.php
WARNING 2016-12-29 17:49:52,123 Not Found: /announce.php
WARNING 2016-12-29 17:49:55,109 Not Found: /announce.php
WARNING 2016-12-29 17:49:55,109 Not Found: /announce.php
WARNING 2016-12-29 17:51:16,136 Not Found: /announce.php
WARNING 2016-12-29 17:51:16,136 Not Found: /announce.php
WARNING 2016-12-29 17:51:37,131 Not Found: /announce.php
WARNING 2016-12-29 17:51:37,131 Not Found: /announce.php
WARNING 2016-12-29 17:52:07,135 Not Found: /announce.php
WARNING 2016-12-29 17:52:07,137 Not Found: /announce.php
WARNING 2016-12-29 17:52:07,139 Not Found: /announce.php
WARNING 2016-12-29 17:52:07,141 Not Found: /announce.php
WARNING 2016-12-29 17:52:07,135 Not Found: /announce.php
WARNING 2016-12-29 17:52:07,137 Not Found: /announce.php
WARNING 2016-12-29 17:52:07,139 Not Found: /announce.php
WARNING 2016-12-29 17:52:07,141 Not Found: /announce.php
WARNING 2016-12-29 17:52:10,126 Not Found: /announce.php
WARNING 2016-12-29 17:52:10,126 Not Found: /announce.php
WARNING 2016-12-29 17:52:16,109 Not Found: /announce.php
WARNING 2016-12-29 17:52:16,109 Not Found: /announce.php
WARNING 2016-12-29 17:53:37,126 Not Found: /announce.php
WARNING 2016-12-29 17:53:37,126 Not Found: /announce.php
WARNING 2016-12-29 17:53:55,129 Not Found: /announce.php
WARNING 2016-12-29 17:53:55,129 Not Found: /announce.php
WARNING 2016-12-29 17:54:25,148 Not Found: /announce.php
WARNING 2016-12-29 17:54:25,148 Not Found: /announce.php
WARNING 2016-12-29 17:54:25,149 Not Found: /announce.php
WARNING 2016-12-29 17:54:25,148 Not Found: /announce.php
WARNING 2016-12-29 17:54:25,148 Not Found: /announce.php
WARNING 2016-12-29 17:54:25,149 Not Found: /announce.php
WARNING 2016-12-29 17:54:28,121 Not Found: /announce.php
WARNING 2016-12-29 17:54:28,121 Not Found: /announce.php
WARNING 2016-12-29 17:54:37,129 Not Found: /announce.php
WARNING 2016-12-29 17:54:37,129 Not Found: /announce.php
WARNING 2016-12-29 18:17:46,224 Not Found: /announce.php
WARNING 2016-12-29 18:17:46,228 Not Found: /announce.php
WARNING 2016-12-29 18:17:46,224 Not Found: /announce.php
WARNING 2016-12-29 18:17:46,228 Not Found: /announce.php
WARNING 2016-12-29 18:17:49,123 Not Found: /announce.php
WARNING 2016-12-29 18:17:49,123 Not Found: /announce.php
WARNING 2016-12-29 18:17:52,133 Not Found: /announce.php
WARNING 2016-12-29 18:17:52,133 Not Found: /announce.php
WARNING 2016-12-29 18:17:52,134 Not Found: /announce.php
WARNING 2016-12-29 18:17:52,133 Not Found: /announce.php
WARNING 2016-12-29 18:17:52,133 Not Found: /announce.php
WARNING 2016-12-29 18:17:52,134 Not Found: /announce.php
WARNING 2016-12-29 18:17:54,136 Not Found: /announce.php
WARNING 2016-12-29 18:17:54,136 Not Found: /announce.php
WARNING 2016-12-29 18:19:49,131 Not Found: /announce.php
WARNING 2016-12-29 18:19:49,132 Not Found: /announce.php
WARNING 2016-12-29 18:19:49,131 Not Found: /announce.php
WARNING 2016-12-29 18:19:49,132 Not Found: /announce.php
WARNING 2016-12-29 18:19:52,119 Not Found: /announce.php
WARNING 2016-12-29 18:19:52,121 Not Found: /announce.php
WARNING 2016-12-29 18:19:52,124 Not Found: /announce.php
WARNING 2016-12-29 18:19:52,119 Not Found: /announce.php
WARNING 2016-12-29 18:19:52,121 Not Found: /announce.php
WARNING 2016-12-29 18:19:52,124 Not Found: /announce.php
WARNING 2016-12-29 18:19:55,123 Not Found: /announce.php
WARNING 2016-12-29 18:19:55,123 Not Found: /announce.php
WARNING 2016-12-29 18:19:58,118 Not Found: /announce.php
WARNING 2016-12-29 18:19:58,118 Not Found: /announce.php
WARNING 2016-12-29 18:21:19,104 Not Found: /announce.php
WARNING 2016-12-29 18:21:19,104 Not Found: /announce.php
WARNING 2016-12-29 18:21:40,145 Not Found: /announce.php
WARNING 2016-12-29 18:21:40,145 Not Found: /announce.php
WARNING 2016-12-29 18:22:10,135 Not Found: /announce.php
WARNING 2016-12-29 18:22:10,136 Not Found: /announce.php
WARNING 2016-12-29 18:22:10,137 Not Found: /announce.php
WARNING 2016-12-29 18:22:10,137 Not Found: /announce.php
WARNING 2016-12-29 18:22:10,135 Not Found: /announce.php
WARNING 2016-12-29 18:22:10,136 Not Found: /announce.php
WARNING 2016-12-29 18:22:10,137 Not Found: /announce.php
WARNING 2016-12-29 18:22:10,137 Not Found: /announce.php
WARNING 2016-12-29 18:22:13,133 Not Found: /announce.php
WARNING 2016-12-29 18:22:13,133 Not Found: /announce.php
WARNING 2016-12-29 18:22:19,103 Not Found: /announce.php
WARNING 2016-12-29 18:22:19,103 Not Found: /announce.php
WARNING 2016-12-29 18:23:40,144 Not Found: /announce.php
WARNING 2016-12-29 18:23:40,144 Not Found: /announce.php
WARNING 2016-12-29 18:23:58,119 Not Found: /announce.php
WARNING 2016-12-29 18:23:58,119 Not Found: /announce.php
WARNING 2016-12-29 18:24:28,107 Not Found: /announce.php
WARNING 2016-12-29 18:24:28,108 Not Found: /announce.php
WARNING 2016-12-29 18:24:28,109 Not Found: /announce.php
WARNING 2016-12-29 18:24:28,107 Not Found: /announce.php
WARNING 2016-12-29 18:24:28,108 Not Found: /announce.php
WARNING 2016-12-29 18:24:28,109 Not Found: /announce.php
WARNING 2016-12-29 18:24:31,118 Not Found: /announce.php
WARNING 2016-12-29 18:24:31,118 Not Found: /announce.php
WARNING 2016-12-29 18:24:40,104 Not Found: /announce.php
WARNING 2016-12-29 18:24:40,104 Not Found: /announce.php
WARNING 2016-12-29 18:47:49,116 Not Found: /announce.php
WARNING 2016-12-29 18:47:49,117 Not Found: /announce.php
WARNING 2016-12-29 18:47:49,116 Not Found: /announce.php
WARNING 2016-12-29 18:47:49,117 Not Found: /announce.php
WARNING 2016-12-29 18:47:52,128 Not Found: /announce.php
WARNING 2016-12-29 18:47:52,128 Not Found: /announce.php
WARNING 2016-12-29 18:47:55,151 Not Found: /announce.php
WARNING 2016-12-29 18:47:55,153 Not Found: /announce.php
WARNING 2016-12-29 18:47:55,151 Not Found: /announce.php
WARNING 2016-12-29 18:47:55,153 Not Found: /announce.php
WARNING 2016-12-29 18:47:55,160 Not Found: /announce.php
WARNING 2016-12-29 18:47:55,160 Not Found: /announce.php
WARNING 2016-12-29 18:47:57,131 Not Found: /announce.php
WARNING 2016-12-29 18:47:57,131 Not Found: /announce.php
WARNING 2016-12-29 18:49:52,146 Not Found: /announce.php
WARNING 2016-12-29 18:49:52,147 Not Found: /announce.php
WARNING 2016-12-29 18:49:52,146 Not Found: /announce.php
WARNING 2016-12-29 18:49:52,147 Not Found: /announce.php
WARNING 2016-12-29 18:49:55,123 Not Found: /announce.php
WARNING 2016-12-29 18:49:55,124 Not Found: /announce.php
WARNING 2016-12-29 18:49:55,123 Not Found: /announce.php
WARNING 2016-12-29 18:49:55,124 Not Found: /announce.php
WARNING 2016-12-29 18:49:55,135 Not Found: /announce.php
WARNING 2016-12-29 18:49:55,135 Not Found: /announce.php
WARNING 2016-12-29 18:49:58,116 Not Found: /announce.php
WARNING 2016-12-29 18:49:58,116 Not Found: /announce.php
WARNING 2016-12-29 18:50:01,137 Not Found: /announce.php
WARNING 2016-12-29 18:50:01,137 Not Found: /announce.php
WARNING 2016-12-29 18:51:22,129 Not Found: /announce.php
WARNING 2016-12-29 18:51:22,129 Not Found: /announce.php
WARNING 2016-12-29 18:51:43,131 Not Found: /announce.php
WARNING 2016-12-29 18:51:43,131 Not Found: /announce.php
WARNING 2016-12-29 18:52:13,147 Not Found: /announce.php
WARNING 2016-12-29 18:52:13,148 Not Found: /announce.php
WARNING 2016-12-29 18:52:13,149 Not Found: /announce.php
WARNING 2016-12-29 18:52:13,147 Not Found: /announce.php
WARNING 2016-12-29 18:52:13,150 Not Found: /announce.php
WARNING 2016-12-29 18:52:13,148 Not Found: /announce.php
WARNING 2016-12-29 18:52:13,149 Not Found: /announce.php
WARNING 2016-12-29 18:52:13,150 Not Found: /announce.php
WARNING 2016-12-29 18:52:16,136 Not Found: /announce.php
WARNING 2016-12-29 18:52:16,136 Not Found: /announce.php
WARNING 2016-12-29 18:52:22,118 Not Found: /announce.php
WARNING 2016-12-29 18:52:22,118 Not Found: /announce.php
WARNING 2016-12-29 18:53:43,125 Not Found: /announce.php
WARNING 2016-12-29 18:53:43,125 Not Found: /announce.php
WARNING 2016-12-29 18:54:01,143 Not Found: /announce.php
WARNING 2016-12-29 18:54:01,143 Not Found: /announce.php
WARNING 2016-12-29 18:54:31,115 Not Found: /announce.php
WARNING 2016-12-29 18:54:31,116 Not Found: /announce.php
WARNING 2016-12-29 18:54:31,117 Not Found: /announce.php
WARNING 2016-12-29 18:54:31,115 Not Found: /announce.php
WARNING 2016-12-29 18:54:31,116 Not Found: /announce.php
WARNING 2016-12-29 18:54:31,117 Not Found: /announce.php
WARNING 2016-12-29 18:54:34,134 Not Found: /announce.php
WARNING 2016-12-29 18:54:34,134 Not Found: /announce.php
WARNING 2016-12-29 18:54:43,130 Not Found: /announce.php
WARNING 2016-12-29 18:54:43,130 Not Found: /announce.php
WARNING 2016-12-29 19:17:52,172 Not Found: /announce.php
WARNING 2016-12-29 19:17:52,172 Not Found: /announce.php
WARNING 2016-12-29 19:17:52,173 Not Found: /announce.php
WARNING 2016-12-29 19:17:52,173 Not Found: /announce.php
WARNING 2016-12-29 19:17:55,132 Not Found: /announce.php
WARNING 2016-12-29 19:17:55,132 Not Found: /announce.php
WARNING 2016-12-29 19:17:58,134 Not Found: /announce.php
WARNING 2016-12-29 19:17:58,135 Not Found: /announce.php
WARNING 2016-12-29 19:17:58,137 Not Found: /announce.php
WARNING 2016-12-29 19:17:58,134 Not Found: /announce.php
WARNING 2016-12-29 19:17:58,135 Not Found: /announce.php
WARNING 2016-12-29 19:17:58,137 Not Found: /announce.php
WARNING 2016-12-29 19:18:00,114 Not Found: /announce.php
WARNING 2016-12-29 19:18:00,114 Not Found: /announce.php
WARNING 2016-12-29 19:19:55,122 Not Found: /announce.php
WARNING 2016-12-29 19:19:55,123 Not Found: /announce.php
WARNING 2016-12-29 19:19:55,122 Not Found: /announce.php
WARNING 2016-12-29 19:19:55,123 Not Found: /announce.php
WARNING 2016-12-29 19:19:58,133 Not Found: /announce.php
WARNING 2016-12-29 19:19:58,134 Not Found: /announce.php
WARNING 2016-12-29 19:19:58,134 Not Found: /announce.php
WARNING 2016-12-29 19:19:58,133 Not Found: /announce.php
WARNING 2016-12-29 19:19:58,134 Not Found: /announce.php
WARNING 2016-12-29 19:19:58,134 Not Found: /announce.php
WARNING 2016-12-29 19:20:01,139 Not Found: /announce.php
WARNING 2016-12-29 19:20:01,139 Not Found: /announce.php
WARNING 2016-12-29 19:20:04,119 Not Found: /announce.php
WARNING 2016-12-29 19:20:04,119 Not Found: /announce.php
WARNING 2016-12-29 19:21:25,124 Not Found: /announce.php
WARNING 2016-12-29 19:21:25,124 Not Found: /announce.php
WARNING 2016-12-29 19:21:46,134 Not Found: /announce.php
WARNING 2016-12-29 19:21:46,134 Not Found: /announce.php
WARNING 2016-12-29 19:22:16,137 Not Found: /announce.php
WARNING 2016-12-29 19:22:16,139 Not Found: /announce.php
WARNING 2016-12-29 19:22:16,140 Not Found: /announce.php
WARNING 2016-12-29 19:22:16,142 Not Found: /announce.php
WARNING 2016-12-29 19:22:16,137 Not Found: /announce.php
WARNING 2016-12-29 19:22:16,139 Not Found: /announce.php
WARNING 2016-12-29 19:22:16,140 Not Found: /announce.php
WARNING 2016-12-29 19:22:16,142 Not Found: /announce.php
WARNING 2016-12-29 19:22:19,149 Not Found: /announce.php
WARNING 2016-12-29 19:22:19,149 Not Found: /announce.php
WARNING 2016-12-29 19:22:25,134 Not Found: /announce.php
WARNING 2016-12-29 19:22:25,134 Not Found: /announce.php
WARNING 2016-12-29 19:23:46,125 Not Found: /announce.php
WARNING 2016-12-29 19:23:46,125 Not Found: /announce.php
WARNING 2016-12-29 19:24:04,125 Not Found: /announce.php
WARNING 2016-12-29 19:24:04,125 Not Found: /announce.php
WARNING 2016-12-29 19:24:34,128 Not Found: /announce.php
WARNING 2016-12-29 19:24:34,129 Not Found: /announce.php
WARNING 2016-12-29 19:24:34,129 Not Found: /announce.php
WARNING 2016-12-29 19:24:34,128 Not Found: /announce.php
WARNING 2016-12-29 19:24:34,129 Not Found: /announce.php
WARNING 2016-12-29 19:24:34,129 Not Found: /announce.php
WARNING 2016-12-29 19:24:37,106 Not Found: /announce.php
WARNING 2016-12-29 19:24:37,106 Not Found: /announce.php
WARNING 2016-12-29 19:24:46,136 Not Found: /announce.php
WARNING 2016-12-29 19:24:46,136 Not Found: /announce.php
WARNING 2016-12-29 19:47:55,114 Not Found: /announce.php
WARNING 2016-12-29 19:47:55,115 Not Found: /announce.php
WARNING 2016-12-29 19:47:55,114 Not Found: /announce.php
WARNING 2016-12-29 19:47:55,115 Not Found: /announce.php
WARNING 2016-12-29 19:47:58,129 Not Found: /announce.php
WARNING 2016-12-29 19:47:58,129 Not Found: /announce.php
WARNING 2016-12-29 19:48:01,130 Not Found: /announce.php
WARNING 2016-12-29 19:48:01,133 Not Found: /announce.php
WARNING 2016-12-29 19:48:01,135 Not Found: /announce.php
WARNING 2016-12-29 19:48:01,130 Not Found: /announce.php
WARNING 2016-12-29 19:48:01,133 Not Found: /announce.php
WARNING 2016-12-29 19:48:01,135 Not Found: /announce.php
WARNING 2016-12-29 19:48:03,093 Not Found: /announce.php
WARNING 2016-12-29 19:48:03,093 Not Found: /announce.php
