ERROR 2017-01-26 15:01:37,761 Internal Server Error: /alljob/
Traceback (most recent call last):
  File "C:\Python34\lib\site-packages\django\core\handlers\base.py", line 119, in get_response
    resolver_match = resolver.resolve(request.path_info)
  File "C:\Python34\lib\site-packages\django\core\urlresolvers.py", line 368, in resolve
    sub_match = pattern.resolve(new_path)
  File "C:\Python34\lib\site-packages\django\core\urlresolvers.py", line 240, in resolve
    return ResolverMatch(self.callback, args, kwargs, self.name)
  File "C:\Python34\lib\site-packages\django\core\urlresolvers.py", line 247, in callback
    self._callback = get_callable(self._callback_str)
  File "C:\Python34\lib\functools.py", line 448, in wrapper
    result = user_function(*args, **kwds)
  File "C:\Python34\lib\site-packages\django\core\urlresolvers.py", line 106, in get_callable
    mod = import_module(mod_name)
  File "C:\Python34\lib\importlib\__init__.py", line 109, in import_module
    return _bootstrap._gcd_import(name[level:], package, level)
  File "<frozen importlib._bootstrap>", line 2254, in _gcd_import
  File "<frozen importlib._bootstrap>", line 2237, in _find_and_load
  File "<frozen importlib._bootstrap>", line 2226, in _find_and_load_unlocked
  File "<frozen importlib._bootstrap>", line 1200, in _load_unlocked
  File "<frozen importlib._bootstrap>", line 1129, in _exec
  File "<frozen importlib._bootstrap>", line 1471, in exec_module
  File "<frozen importlib._bootstrap>", line 321, in _call_with_frames_removed
  File "C:\uav\frontend\views\all_job\frontend_all_job.py", line 13, in <module>
    from common.tasks import *
  File "C:\uav\common\tasks.py", line 170
    @task
        ^
IndentationError: expected an indented block
ERROR 2017-01-26 15:01:37,761 Internal Server Error: /alljob/
Traceback (most recent call last):
  File "C:\Python34\lib\site-packages\django\core\handlers\base.py", line 119, in get_response
    resolver_match = resolver.resolve(request.path_info)
  File "C:\Python34\lib\site-packages\django\core\urlresolvers.py", line 368, in resolve
    sub_match = pattern.resolve(new_path)
  File "C:\Python34\lib\site-packages\django\core\urlresolvers.py", line 240, in resolve
    return ResolverMatch(self.callback, args, kwargs, self.name)
  File "C:\Python34\lib\site-packages\django\core\urlresolvers.py", line 247, in callback
    self._callback = get_callable(self._callback_str)
  File "C:\Python34\lib\functools.py", line 448, in wrapper
    result = user_function(*args, **kwds)
  File "C:\Python34\lib\site-packages\django\core\urlresolvers.py", line 106, in get_callable
    mod = import_module(mod_name)
  File "C:\Python34\lib\importlib\__init__.py", line 109, in import_module
    return _bootstrap._gcd_import(name[level:], package, level)
  File "<frozen importlib._bootstrap>", line 2254, in _gcd_import
  File "<frozen importlib._bootstrap>", line 2237, in _find_and_load
  File "<frozen importlib._bootstrap>", line 2226, in _find_and_load_unlocked
  File "<frozen importlib._bootstrap>", line 1200, in _load_unlocked
  File "<frozen importlib._bootstrap>", line 1129, in _exec
  File "<frozen importlib._bootstrap>", line 1471, in exec_module
  File "<frozen importlib._bootstrap>", line 321, in _call_with_frames_removed
  File "C:\uav\frontend\views\all_job\frontend_all_job.py", line 13, in <module>
    from common.tasks import *
  File "C:\uav\common\tasks.py", line 170
    @task
        ^
IndentationError: expected an indented block
WARNING 2017-01-26 15:01:38,103 Not Found: /favicon.ico
WARNING 2017-01-26 15:01:38,103 Not Found: /favicon.ico
ERROR 2017-01-26 15:02:17,318 Internal Server Error: /alljob/
Traceback (most recent call last):
  File "C:\Python34\lib\site-packages\django\core\handlers\base.py", line 119, in get_response
    resolver_match = resolver.resolve(request.path_info)
  File "C:\Python34\lib\site-packages\django\core\urlresolvers.py", line 368, in resolve
    sub_match = pattern.resolve(new_path)
  File "C:\Python34\lib\site-packages\django\core\urlresolvers.py", line 240, in resolve
    return ResolverMatch(self.callback, args, kwargs, self.name)
  File "C:\Python34\lib\site-packages\django\core\urlresolvers.py", line 247, in callback
    self._callback = get_callable(self._callback_str)
  File "C:\Python34\lib\functools.py", line 448, in wrapper
    result = user_function(*args, **kwds)
  File "C:\Python34\lib\site-packages\django\core\urlresolvers.py", line 106, in get_callable
    mod = import_module(mod_name)
  File "C:\Python34\lib\importlib\__init__.py", line 109, in import_module
    return _bootstrap._gcd_import(name[level:], package, level)
  File "<frozen importlib._bootstrap>", line 2254, in _gcd_import
  File "<frozen importlib._bootstrap>", line 2237, in _find_and_load
  File "<frozen importlib._bootstrap>", line 2226, in _find_and_load_unlocked
  File "<frozen importlib._bootstrap>", line 1200, in _load_unlocked
  File "<frozen importlib._bootstrap>", line 1129, in _exec
  File "<frozen importlib._bootstrap>", line 1471, in exec_module
  File "<frozen importlib._bootstrap>", line 321, in _call_with_frames_removed
  File "C:\uav\frontend\views\all_job\frontend_all_job.py", line 13, in <module>
    from common.tasks import *
  File "C:\uav\common\tasks.py", line 170
    @task
        ^
IndentationError: expected an indented block
ERROR 2017-01-26 15:02:17,318 Internal Server Error: /alljob/
Traceback (most recent call last):
  File "C:\Python34\lib\site-packages\django\core\handlers\base.py", line 119, in get_response
    resolver_match = resolver.resolve(request.path_info)
  File "C:\Python34\lib\site-packages\django\core\urlresolvers.py", line 368, in resolve
    sub_match = pattern.resolve(new_path)
  File "C:\Python34\lib\site-packages\django\core\urlresolvers.py", line 240, in resolve
    return ResolverMatch(self.callback, args, kwargs, self.name)
  File "C:\Python34\lib\site-packages\django\core\urlresolvers.py", line 247, in callback
    self._callback = get_callable(self._callback_str)
  File "C:\Python34\lib\functools.py", line 448, in wrapper
    result = user_function(*args, **kwds)
  File "C:\Python34\lib\site-packages\django\core\urlresolvers.py", line 106, in get_callable
    mod = import_module(mod_name)
  File "C:\Python34\lib\importlib\__init__.py", line 109, in import_module
    return _bootstrap._gcd_import(name[level:], package, level)
  File "<frozen importlib._bootstrap>", line 2254, in _gcd_import
  File "<frozen importlib._bootstrap>", line 2237, in _find_and_load
  File "<frozen importlib._bootstrap>", line 2226, in _find_and_load_unlocked
  File "<frozen importlib._bootstrap>", line 1200, in _load_unlocked
  File "<frozen importlib._bootstrap>", line 1129, in _exec
  File "<frozen importlib._bootstrap>", line 1471, in exec_module
  File "<frozen importlib._bootstrap>", line 321, in _call_with_frames_removed
  File "C:\uav\frontend\views\all_job\frontend_all_job.py", line 13, in <module>
    from common.tasks import *
  File "C:\uav\common\tasks.py", line 170
    @task
        ^
IndentationError: expected an indented block
ERROR 2017-01-26 15:02:18,847 Internal Server Error: /alljob/
Traceback (most recent call last):
  File "C:\Python34\lib\site-packages\django\core\handlers\base.py", line 119, in get_response
    resolver_match = resolver.resolve(request.path_info)
  File "C:\Python34\lib\site-packages\django\core\urlresolvers.py", line 368, in resolve
    sub_match = pattern.resolve(new_path)
  File "C:\Python34\lib\site-packages\django\core\urlresolvers.py", line 240, in resolve
    return ResolverMatch(self.callback, args, kwargs, self.name)
  File "C:\Python34\lib\site-packages\django\core\urlresolvers.py", line 247, in callback
    self._callback = get_callable(self._callback_str)
  File "C:\Python34\lib\functools.py", line 448, in wrapper
    result = user_function(*args, **kwds)
  File "C:\Python34\lib\site-packages\django\core\urlresolvers.py", line 106, in get_callable
    mod = import_module(mod_name)
  File "C:\Python34\lib\importlib\__init__.py", line 109, in import_module
    return _bootstrap._gcd_import(name[level:], package, level)
  File "<frozen importlib._bootstrap>", line 2254, in _gcd_import
  File "<frozen importlib._bootstrap>", line 2237, in _find_and_load
  File "<frozen importlib._bootstrap>", line 2226, in _find_and_load_unlocked
  File "<frozen importlib._bootstrap>", line 1200, in _load_unlocked
  File "<frozen importlib._bootstrap>", line 1129, in _exec
  File "<frozen importlib._bootstrap>", line 1471, in exec_module
  File "<frozen importlib._bootstrap>", line 321, in _call_with_frames_removed
  File "C:\uav\frontend\views\all_job\frontend_all_job.py", line 13, in <module>
    from common.tasks import *
  File "C:\uav\common\tasks.py", line 170
    @task
        ^
IndentationError: expected an indented block
ERROR 2017-01-26 15:02:18,847 Internal Server Error: /alljob/
Traceback (most recent call last):
  File "C:\Python34\lib\site-packages\django\core\handlers\base.py", line 119, in get_response
    resolver_match = resolver.resolve(request.path_info)
  File "C:\Python34\lib\site-packages\django\core\urlresolvers.py", line 368, in resolve
    sub_match = pattern.resolve(new_path)
  File "C:\Python34\lib\site-packages\django\core\urlresolvers.py", line 240, in resolve
    return ResolverMatch(self.callback, args, kwargs, self.name)
  File "C:\Python34\lib\site-packages\django\core\urlresolvers.py", line 247, in callback
    self._callback = get_callable(self._callback_str)
  File "C:\Python34\lib\functools.py", line 448, in wrapper
    result = user_function(*args, **kwds)
  File "C:\Python34\lib\site-packages\django\core\urlresolvers.py", line 106, in get_callable
    mod = import_module(mod_name)
  File "C:\Python34\lib\importlib\__init__.py", line 109, in import_module
    return _bootstrap._gcd_import(name[level:], package, level)
  File "<frozen importlib._bootstrap>", line 2254, in _gcd_import
  File "<frozen importlib._bootstrap>", line 2237, in _find_and_load
  File "<frozen importlib._bootstrap>", line 2226, in _find_and_load_unlocked
  File "<frozen importlib._bootstrap>", line 1200, in _load_unlocked
  File "<frozen importlib._bootstrap>", line 1129, in _exec
  File "<frozen importlib._bootstrap>", line 1471, in exec_module
  File "<frozen importlib._bootstrap>", line 321, in _call_with_frames_removed
  File "C:\uav\frontend\views\all_job\frontend_all_job.py", line 13, in <module>
    from common.tasks import *
  File "C:\uav\common\tasks.py", line 170
    @task
        ^
IndentationError: expected an indented block
ERROR 2017-01-26 15:02:20,280 Internal Server Error: /alljob/
Traceback (most recent call last):
  File "C:\Python34\lib\site-packages\django\core\handlers\base.py", line 119, in get_response
    resolver_match = resolver.resolve(request.path_info)
  File "C:\Python34\lib\site-packages\django\core\urlresolvers.py", line 368, in resolve
    sub_match = pattern.resolve(new_path)
  File "C:\Python34\lib\site-packages\django\core\urlresolvers.py", line 240, in resolve
    return ResolverMatch(self.callback, args, kwargs, self.name)
  File "C:\Python34\lib\site-packages\django\core\urlresolvers.py", line 247, in callback
    self._callback = get_callable(self._callback_str)
  File "C:\Python34\lib\functools.py", line 448, in wrapper
    result = user_function(*args, **kwds)
  File "C:\Python34\lib\site-packages\django\core\urlresolvers.py", line 106, in get_callable
    mod = import_module(mod_name)
  File "C:\Python34\lib\importlib\__init__.py", line 109, in import_module
    return _bootstrap._gcd_import(name[level:], package, level)
  File "<frozen importlib._bootstrap>", line 2254, in _gcd_import
  File "<frozen importlib._bootstrap>", line 2237, in _find_and_load
  File "<frozen importlib._bootstrap>", line 2226, in _find_and_load_unlocked
  File "<frozen importlib._bootstrap>", line 1200, in _load_unlocked
  File "<frozen importlib._bootstrap>", line 1129, in _exec
  File "<frozen importlib._bootstrap>", line 1471, in exec_module
  File "<frozen importlib._bootstrap>", line 321, in _call_with_frames_removed
  File "C:\uav\frontend\views\all_job\frontend_all_job.py", line 13, in <module>
    from common.tasks import *
  File "C:\uav\common\tasks.py", line 170
    @task
        ^
IndentationError: expected an indented block
ERROR 2017-01-26 15:02:20,280 Internal Server Error: /alljob/
Traceback (most recent call last):
  File "C:\Python34\lib\site-packages\django\core\handlers\base.py", line 119, in get_response
    resolver_match = resolver.resolve(request.path_info)
  File "C:\Python34\lib\site-packages\django\core\urlresolvers.py", line 368, in resolve
    sub_match = pattern.resolve(new_path)
  File "C:\Python34\lib\site-packages\django\core\urlresolvers.py", line 240, in resolve
    return ResolverMatch(self.callback, args, kwargs, self.name)
  File "C:\Python34\lib\site-packages\django\core\urlresolvers.py", line 247, in callback
    self._callback = get_callable(self._callback_str)
  File "C:\Python34\lib\functools.py", line 448, in wrapper
    result = user_function(*args, **kwds)
  File "C:\Python34\lib\site-packages\django\core\urlresolvers.py", line 106, in get_callable
    mod = import_module(mod_name)
  File "C:\Python34\lib\importlib\__init__.py", line 109, in import_module
    return _bootstrap._gcd_import(name[level:], package, level)
  File "<frozen importlib._bootstrap>", line 2254, in _gcd_import
  File "<frozen importlib._bootstrap>", line 2237, in _find_and_load
  File "<frozen importlib._bootstrap>", line 2226, in _find_and_load_unlocked
  File "<frozen importlib._bootstrap>", line 1200, in _load_unlocked
  File "<frozen importlib._bootstrap>", line 1129, in _exec
  File "<frozen importlib._bootstrap>", line 1471, in exec_module
  File "<frozen importlib._bootstrap>", line 321, in _call_with_frames_removed
  File "C:\uav\frontend\views\all_job\frontend_all_job.py", line 13, in <module>
    from common.tasks import *
  File "C:\uav\common\tasks.py", line 170
    @task
        ^
IndentationError: expected an indented block
ERROR 2017-01-26 15:02:58,808 Internal Server Error: /alljob/
Traceback (most recent call last):
  File "C:\Python34\lib\site-packages\django\core\handlers\base.py", line 119, in get_response
    resolver_match = resolver.resolve(request.path_info)
  File "C:\Python34\lib\site-packages\django\core\urlresolvers.py", line 368, in resolve
    sub_match = pattern.resolve(new_path)
  File "C:\Python34\lib\site-packages\django\core\urlresolvers.py", line 240, in resolve
    return ResolverMatch(self.callback, args, kwargs, self.name)
  File "C:\Python34\lib\site-packages\django\core\urlresolvers.py", line 247, in callback
    self._callback = get_callable(self._callback_str)
  File "C:\Python34\lib\functools.py", line 448, in wrapper
    result = user_function(*args, **kwds)
  File "C:\Python34\lib\site-packages\django\core\urlresolvers.py", line 106, in get_callable
    mod = import_module(mod_name)
  File "C:\Python34\lib\importlib\__init__.py", line 109, in import_module
    return _bootstrap._gcd_import(name[level:], package, level)
  File "<frozen importlib._bootstrap>", line 2254, in _gcd_import
  File "<frozen importlib._bootstrap>", line 2237, in _find_and_load
  File "<frozen importlib._bootstrap>", line 2226, in _find_and_load_unlocked
  File "<frozen importlib._bootstrap>", line 1200, in _load_unlocked
  File "<frozen importlib._bootstrap>", line 1129, in _exec
  File "<frozen importlib._bootstrap>", line 1471, in exec_module
  File "<frozen importlib._bootstrap>", line 321, in _call_with_frames_removed
  File "C:\uav\frontend\views\all_job\frontend_all_job.py", line 13, in <module>
    from common.tasks import *
  File "C:\uav\common\tasks.py", line 170
    @task
        ^
IndentationError: expected an indented block
ERROR 2017-01-26 15:02:58,808 Internal Server Error: /alljob/
Traceback (most recent call last):
  File "C:\Python34\lib\site-packages\django\core\handlers\base.py", line 119, in get_response
    resolver_match = resolver.resolve(request.path_info)
  File "C:\Python34\lib\site-packages\django\core\urlresolvers.py", line 368, in resolve
    sub_match = pattern.resolve(new_path)
  File "C:\Python34\lib\site-packages\django\core\urlresolvers.py", line 240, in resolve
    return ResolverMatch(self.callback, args, kwargs, self.name)
  File "C:\Python34\lib\site-packages\django\core\urlresolvers.py", line 247, in callback
    self._callback = get_callable(self._callback_str)
  File "C:\Python34\lib\functools.py", line 448, in wrapper
    result = user_function(*args, **kwds)
  File "C:\Python34\lib\site-packages\django\core\urlresolvers.py", line 106, in get_callable
    mod = import_module(mod_name)
  File "C:\Python34\lib\importlib\__init__.py", line 109, in import_module
    return _bootstrap._gcd_import(name[level:], package, level)
  File "<frozen importlib._bootstrap>", line 2254, in _gcd_import
  File "<frozen importlib._bootstrap>", line 2237, in _find_and_load
  File "<frozen importlib._bootstrap>", line 2226, in _find_and_load_unlocked
  File "<frozen importlib._bootstrap>", line 1200, in _load_unlocked
  File "<frozen importlib._bootstrap>", line 1129, in _exec
  File "<frozen importlib._bootstrap>", line 1471, in exec_module
  File "<frozen importlib._bootstrap>", line 321, in _call_with_frames_removed
  File "C:\uav\frontend\views\all_job\frontend_all_job.py", line 13, in <module>
    from common.tasks import *
  File "C:\uav\common\tasks.py", line 170
    @task
        ^
IndentationError: expected an indented block
ERROR 2017-01-26 15:03:08,425 Internal Server Error: /alljob/
Traceback (most recent call last):
  File "C:\Python34\lib\site-packages\django\core\handlers\base.py", line 119, in get_response
    resolver_match = resolver.resolve(request.path_info)
  File "C:\Python34\lib\site-packages\django\core\urlresolvers.py", line 368, in resolve
    sub_match = pattern.resolve(new_path)
  File "C:\Python34\lib\site-packages\django\core\urlresolvers.py", line 240, in resolve
    return ResolverMatch(self.callback, args, kwargs, self.name)
  File "C:\Python34\lib\site-packages\django\core\urlresolvers.py", line 247, in callback
    self._callback = get_callable(self._callback_str)
  File "C:\Python34\lib\functools.py", line 448, in wrapper
    result = user_function(*args, **kwds)
  File "C:\Python34\lib\site-packages\django\core\urlresolvers.py", line 106, in get_callable
    mod = import_module(mod_name)
  File "C:\Python34\lib\importlib\__init__.py", line 109, in import_module
    return _bootstrap._gcd_import(name[level:], package, level)
  File "<frozen importlib._bootstrap>", line 2254, in _gcd_import
  File "<frozen importlib._bootstrap>", line 2237, in _find_and_load
  File "<frozen importlib._bootstrap>", line 2226, in _find_and_load_unlocked
  File "<frozen importlib._bootstrap>", line 1200, in _load_unlocked
  File "<frozen importlib._bootstrap>", line 1129, in _exec
  File "<frozen importlib._bootstrap>", line 1471, in exec_module
  File "<frozen importlib._bootstrap>", line 321, in _call_with_frames_removed
  File "C:\uav\frontend\views\all_job\frontend_all_job.py", line 14, in <module>
    from common.tasks import *
  File "C:\uav\common\tasks.py", line 170
    @task
        ^
IndentationError: expected an indented block
ERROR 2017-01-26 15:03:08,425 Internal Server Error: /alljob/
Traceback (most recent call last):
  File "C:\Python34\lib\site-packages\django\core\handlers\base.py", line 119, in get_response
    resolver_match = resolver.resolve(request.path_info)
  File "C:\Python34\lib\site-packages\django\core\urlresolvers.py", line 368, in resolve
    sub_match = pattern.resolve(new_path)
  File "C:\Python34\lib\site-packages\django\core\urlresolvers.py", line 240, in resolve
    return ResolverMatch(self.callback, args, kwargs, self.name)
  File "C:\Python34\lib\site-packages\django\core\urlresolvers.py", line 247, in callback
    self._callback = get_callable(self._callback_str)
  File "C:\Python34\lib\functools.py", line 448, in wrapper
    result = user_function(*args, **kwds)
  File "C:\Python34\lib\site-packages\django\core\urlresolvers.py", line 106, in get_callable
    mod = import_module(mod_name)
  File "C:\Python34\lib\importlib\__init__.py", line 109, in import_module
    return _bootstrap._gcd_import(name[level:], package, level)
  File "<frozen importlib._bootstrap>", line 2254, in _gcd_import
  File "<frozen importlib._bootstrap>", line 2237, in _find_and_load
  File "<frozen importlib._bootstrap>", line 2226, in _find_and_load_unlocked
  File "<frozen importlib._bootstrap>", line 1200, in _load_unlocked
  File "<frozen importlib._bootstrap>", line 1129, in _exec
  File "<frozen importlib._bootstrap>", line 1471, in exec_module
  File "<frozen importlib._bootstrap>", line 321, in _call_with_frames_removed
  File "C:\uav\frontend\views\all_job\frontend_all_job.py", line 14, in <module>
    from common.tasks import *
  File "C:\uav\common\tasks.py", line 170
    @task
        ^
IndentationError: expected an indented block
ERROR 2017-01-26 15:03:10,676 Internal Server Error: /alljob/
Traceback (most recent call last):
  File "C:\Python34\lib\site-packages\django\core\handlers\base.py", line 119, in get_response
    resolver_match = resolver.resolve(request.path_info)
  File "C:\Python34\lib\site-packages\django\core\urlresolvers.py", line 368, in resolve
    sub_match = pattern.resolve(new_path)
  File "C:\Python34\lib\site-packages\django\core\urlresolvers.py", line 240, in resolve
    return ResolverMatch(self.callback, args, kwargs, self.name)
  File "C:\Python34\lib\site-packages\django\core\urlresolvers.py", line 247, in callback
    self._callback = get_callable(self._callback_str)
  File "C:\Python34\lib\functools.py", line 448, in wrapper
    result = user_function(*args, **kwds)
  File "C:\Python34\lib\site-packages\django\core\urlresolvers.py", line 106, in get_callable
    mod = import_module(mod_name)
  File "C:\Python34\lib\importlib\__init__.py", line 109, in import_module
    return _bootstrap._gcd_import(name[level:], package, level)
  File "<frozen importlib._bootstrap>", line 2254, in _gcd_import
  File "<frozen importlib._bootstrap>", line 2237, in _find_and_load
  File "<frozen importlib._bootstrap>", line 2226, in _find_and_load_unlocked
  File "<frozen importlib._bootstrap>", line 1200, in _load_unlocked
  File "<frozen importlib._bootstrap>", line 1129, in _exec
  File "<frozen importlib._bootstrap>", line 1471, in exec_module
  File "<frozen importlib._bootstrap>", line 321, in _call_with_frames_removed
  File "C:\uav\frontend\views\all_job\frontend_all_job.py", line 14, in <module>
    from common.tasks import *
  File "C:\uav\common\tasks.py", line 170
    @task
        ^
IndentationError: expected an indented block
ERROR 2017-01-26 15:03:10,676 Internal Server Error: /alljob/
Traceback (most recent call last):
  File "C:\Python34\lib\site-packages\django\core\handlers\base.py", line 119, in get_response
    resolver_match = resolver.resolve(request.path_info)
  File "C:\Python34\lib\site-packages\django\core\urlresolvers.py", line 368, in resolve
    sub_match = pattern.resolve(new_path)
  File "C:\Python34\lib\site-packages\django\core\urlresolvers.py", line 240, in resolve
    return ResolverMatch(self.callback, args, kwargs, self.name)
  File "C:\Python34\lib\site-packages\django\core\urlresolvers.py", line 247, in callback
    self._callback = get_callable(self._callback_str)
  File "C:\Python34\lib\functools.py", line 448, in wrapper
    result = user_function(*args, **kwds)
  File "C:\Python34\lib\site-packages\django\core\urlresolvers.py", line 106, in get_callable
    mod = import_module(mod_name)
  File "C:\Python34\lib\importlib\__init__.py", line 109, in import_module
    return _bootstrap._gcd_import(name[level:], package, level)
  File "<frozen importlib._bootstrap>", line 2254, in _gcd_import
  File "<frozen importlib._bootstrap>", line 2237, in _find_and_load
  File "<frozen importlib._bootstrap>", line 2226, in _find_and_load_unlocked
  File "<frozen importlib._bootstrap>", line 1200, in _load_unlocked
  File "<frozen importlib._bootstrap>", line 1129, in _exec
  File "<frozen importlib._bootstrap>", line 1471, in exec_module
  File "<frozen importlib._bootstrap>", line 321, in _call_with_frames_removed
  File "C:\uav\frontend\views\all_job\frontend_all_job.py", line 14, in <module>
    from common.tasks import *
  File "C:\uav\common\tasks.py", line 170
    @task
        ^
IndentationError: expected an indented block
