ERROR 2017-02-24 14:02:15,242 Internal Server Error: /test
Traceback (most recent call last):
  File "C:\Python34\lib\site-packages\django\core\handlers\base.py", line 108, in get_response
    response = middleware_method(request)
  File "C:\Python34\lib\site-packages\django\middleware\common.py", line 75, in process_request
    urlresolvers.is_valid_path("%s/" % request.path_info, urlconf)):
  File "C:\Python34\lib\site-packages\django\core\urlresolvers.py", line 647, in is_valid_path
    resolve(path, urlconf)
  File "C:\Python34\lib\site-packages\django\core\urlresolvers.py", line 522, in resolve
    return get_resolver(urlconf).resolve(path)
  File "C:\Python34\lib\site-packages\django\core\urlresolvers.py", line 368, in resolve
    sub_match = pattern.resolve(new_path)
  File "C:\Python34\lib\site-packages\django\core\urlresolvers.py", line 240, in resolve
    return ResolverMatch(self.callback, args, kwargs, self.name)
  File "C:\Python34\lib\site-packages\django\core\urlresolvers.py", line 247, in callback
    self._callback = get_callable(self._callback_str)
  File "C:\Python34\lib\functools.py", line 448, in wrapper
    result = user_function(*args, **kwds)
  File "C:\Python34\lib\site-packages\django\core\urlresolvers.py", line 106, in get_callable
    mod = import_module(mod_name)
  File "C:\Python34\lib\importlib\__init__.py", line 109, in import_module
    return _bootstrap._gcd_import(name[level:], package, level)
  File "<frozen importlib._bootstrap>", line 2254, in _gcd_import
  File "<frozen importlib._bootstrap>", line 2237, in _find_and_load
  File "<frozen importlib._bootstrap>", line 2212, in _find_and_load_unlocked
  File "<frozen importlib._bootstrap>", line 321, in _call_with_frames_removed
  File "<frozen importlib._bootstrap>", line 2254, in _gcd_import
  File "<frozen importlib._bootstrap>", line 2237, in _find_and_load
  File "<frozen importlib._bootstrap>", line 2226, in _find_and_load_unlocked
  File "<frozen importlib._bootstrap>", line 1200, in _load_unlocked
  File "<frozen importlib._bootstrap>", line 1129, in _exec
  File "<frozen importlib._bootstrap>", line 1471, in exec_module
  File "<frozen importlib._bootstrap>", line 321, in _call_with_frames_removed
  File "C:\uav\common\views\__init__.py", line 5, in <module>
    from common.views.test import *
  File "C:\uav\common\views\test.py", line 30
    return render_to_response('test.html',{
                                          ^
IndentationError: unindent does not match any outer indentation level
ERROR 2017-02-24 14:02:15,242 Internal Server Error: /test
Traceback (most recent call last):
  File "C:\Python34\lib\site-packages\django\core\handlers\base.py", line 108, in get_response
    response = middleware_method(request)
  File "C:\Python34\lib\site-packages\django\middleware\common.py", line 75, in process_request
    urlresolvers.is_valid_path("%s/" % request.path_info, urlconf)):
  File "C:\Python34\lib\site-packages\django\core\urlresolvers.py", line 647, in is_valid_path
    resolve(path, urlconf)
  File "C:\Python34\lib\site-packages\django\core\urlresolvers.py", line 522, in resolve
    return get_resolver(urlconf).resolve(path)
  File "C:\Python34\lib\site-packages\django\core\urlresolvers.py", line 368, in resolve
    sub_match = pattern.resolve(new_path)
  File "C:\Python34\lib\site-packages\django\core\urlresolvers.py", line 240, in resolve
    return ResolverMatch(self.callback, args, kwargs, self.name)
  File "C:\Python34\lib\site-packages\django\core\urlresolvers.py", line 247, in callback
    self._callback = get_callable(self._callback_str)
  File "C:\Python34\lib\functools.py", line 448, in wrapper
    result = user_function(*args, **kwds)
  File "C:\Python34\lib\site-packages\django\core\urlresolvers.py", line 106, in get_callable
    mod = import_module(mod_name)
  File "C:\Python34\lib\importlib\__init__.py", line 109, in import_module
    return _bootstrap._gcd_import(name[level:], package, level)
  File "<frozen importlib._bootstrap>", line 2254, in _gcd_import
  File "<frozen importlib._bootstrap>", line 2237, in _find_and_load
  File "<frozen importlib._bootstrap>", line 2212, in _find_and_load_unlocked
  File "<frozen importlib._bootstrap>", line 321, in _call_with_frames_removed
  File "<frozen importlib._bootstrap>", line 2254, in _gcd_import
  File "<frozen importlib._bootstrap>", line 2237, in _find_and_load
  File "<frozen importlib._bootstrap>", line 2226, in _find_and_load_unlocked
  File "<frozen importlib._bootstrap>", line 1200, in _load_unlocked
  File "<frozen importlib._bootstrap>", line 1129, in _exec
  File "<frozen importlib._bootstrap>", line 1471, in exec_module
  File "<frozen importlib._bootstrap>", line 321, in _call_with_frames_removed
  File "C:\uav\common\views\__init__.py", line 5, in <module>
    from common.views.test import *
  File "C:\uav\common\views\test.py", line 30
    return render_to_response('test.html',{
                                          ^
IndentationError: unindent does not match any outer indentation level
WARNING 2017-02-24 14:02:15,676 Not Found: /favicon.ico
WARNING 2017-02-24 14:02:15,676 Not Found: /favicon.ico
ERROR 2017-02-24 14:02:28,619 Internal Server Error: /test/
Traceback (most recent call last):
  File "C:\Python34\lib\site-packages\kombu\utils\__init__.py", line 423, in __call__
    return self.__value__
AttributeError: 'ChannelPromise' object has no attribute '__value__'

During handling of the above exception, another exception occurred:

Traceback (most recent call last):
  File "C:\Python34\lib\site-packages\kombu\transport\virtual\__init__.py", line 789, in create_channel
    return self._avail_channels.pop()
IndexError: pop from empty list

During handling of the above exception, another exception occurred:

Traceback (most recent call last):
  File "C:\Python34\lib\site-packages\redis\connection.py", line 143, in _read_from_socket
    data = recv(self._sock, socket_read_size)
  File "C:\Python34\lib\site-packages\redis\_compat.py", line 60, in recv
    return _retryable_call(sock, sock.recv, *args, **kwargs)
  File "C:\Python34\lib\site-packages\redis\_compat.py", line 48, in _retryable_call
    return func(*args, **kwargs)
ConnectionResetError: [WinError 10054] 远程主机强迫关闭了一个现有的连接。

During handling of the above exception, another exception occurred:

Traceback (most recent call last):
  File "C:\Python34\lib\site-packages\redis\connection.py", line 612, in read_response
    response = self._parser.read_response()
  File "C:\Python34\lib\site-packages\redis\connection.py", line 255, in read_response
    response = self._buffer.readline()
  File "C:\Python34\lib\site-packages\redis\connection.py", line 185, in readline
    self._read_from_socket()
  File "C:\Python34\lib\site-packages\redis\connection.py", line 160, in _read_from_socket
    (e.args,))
redis.exceptions.ConnectionError: Error while reading from socket: (10054, '远程主机强迫关闭了一个现有的连接。', None, 10054, None)

During handling of the above exception, another exception occurred:

Traceback (most recent call last):
  File "C:\Python34\lib\site-packages\redis\client.py", line 661, in execute_command
    return self.parse_response(connection, command_name, **options)
  File "C:\Python34\lib\site-packages\redis\client.py", line 673, in parse_response
    response = connection.read_response()
  File "C:\Python34\lib\site-packages\redis\connection.py", line 614, in read_response
    self.disconnect()
  File "C:\Python34\lib\site-packages\kombu\transport\redis.py", line 819, in disconnect
    channel._on_connection_disconnect(self)
  File "C:\Python34\lib\site-packages\kombu\transport\redis.py", line 476, in _on_connection_disconnect
    raise get_redis_ConnectionError()
redis.exceptions.ConnectionError

During handling of the above exception, another exception occurred:

Traceback (most recent call last):
  File "C:\Python34\lib\site-packages\kombu\connection.py", line 436, in _ensured
    return fun(*args, **kwargs)
  File "C:\Python34\lib\site-packages\kombu\messaging.py", line 177, in _publish
    channel = self.channel
  File "C:\Python34\lib\site-packages\kombu\messaging.py", line 194, in _get_channel
    channel = self._channel = channel()
  File "C:\Python34\lib\site-packages\kombu\utils\__init__.py", line 425, in __call__
    value = self.__value__ = self.__contract__()
  File "C:\Python34\lib\site-packages\kombu\messaging.py", line 209, in <lambda>
    channel = ChannelPromise(lambda: connection.default_channel)
  File "C:\Python34\lib\site-packages\kombu\connection.py", line 756, in default_channel
    self.connection
  File "C:\Python34\lib\site-packages\kombu\connection.py", line 741, in connection
    self._connection = self._establish_connection()
  File "C:\Python34\lib\site-packages\kombu\connection.py", line 696, in _establish_connection
    conn = self.transport.establish_connection()
  File "C:\Python34\lib\site-packages\kombu\transport\virtual\__init__.py", line 809, in establish_connection
    self._avail_channels.append(self.create_channel(self))
  File "C:\Python34\lib\site-packages\kombu\transport\virtual\__init__.py", line 791, in create_channel
    channel = self.Channel(connection)
  File "C:\Python34\lib\site-packages\kombu\transport\redis.py", line 453, in __init__
    self.client.info()
  File "C:\Python34\lib\site-packages\redis\client.py", line 753, in info
    return self.execute_command('INFO')
  File "C:\Python34\lib\site-packages\redis\client.py", line 663, in execute_command
    connection.disconnect()
  File "C:\Python34\lib\site-packages\kombu\transport\redis.py", line 819, in disconnect
    channel._on_connection_disconnect(self)
  File "C:\Python34\lib\site-packages\kombu\transport\redis.py", line 476, in _on_connection_disconnect
    raise get_redis_ConnectionError()
redis.exceptions.ConnectionError

During handling of the above exception, another exception occurred:

Traceback (most recent call last):
  File "C:\Python34\lib\site-packages\kombu\transport\virtual\__init__.py", line 789, in create_channel
    return self._avail_channels.pop()
IndexError: pop from empty list

During handling of the above exception, another exception occurred:

Traceback (most recent call last):
  File "C:\Python34\lib\site-packages\redis\connection.py", line 143, in _read_from_socket
    data = recv(self._sock, socket_read_size)
  File "C:\Python34\lib\site-packages\redis\_compat.py", line 60, in recv
    return _retryable_call(sock, sock.recv, *args, **kwargs)
  File "C:\Python34\lib\site-packages\redis\_compat.py", line 48, in _retryable_call
    return func(*args, **kwargs)
ConnectionResetError: [WinError 10054] 远程主机强迫关闭了一个现有的连接。

During handling of the above exception, another exception occurred:

Traceback (most recent call last):
  File "C:\Python34\lib\site-packages\redis\connection.py", line 612, in read_response
    response = self._parser.read_response()
  File "C:\Python34\lib\site-packages\redis\connection.py", line 255, in read_response
    response = self._buffer.readline()
  File "C:\Python34\lib\site-packages\redis\connection.py", line 185, in readline
    self._read_from_socket()
  File "C:\Python34\lib\site-packages\redis\connection.py", line 160, in _read_from_socket
    (e.args,))
redis.exceptions.ConnectionError: Error while reading from socket: (10054, '远程主机强迫关闭了一个现有的连接。', None, 10054, None)

During handling of the above exception, another exception occurred:

Traceback (most recent call last):
  File "C:\Python34\lib\site-packages\redis\client.py", line 661, in execute_command
    return self.parse_response(connection, command_name, **options)
  File "C:\Python34\lib\site-packages\redis\client.py", line 673, in parse_response
    response = connection.read_response()
  File "C:\Python34\lib\site-packages\redis\connection.py", line 614, in read_response
    self.disconnect()
  File "C:\Python34\lib\site-packages\kombu\transport\redis.py", line 819, in disconnect
    channel._on_connection_disconnect(self)
  File "C:\Python34\lib\site-packages\kombu\transport\redis.py", line 476, in _on_connection_disconnect
    raise get_redis_ConnectionError()
redis.exceptions.ConnectionError

During handling of the above exception, another exception occurred:

Traceback (most recent call last):
  File "C:\Python34\lib\site-packages\django\core\handlers\base.py", line 132, in get_response
    response = wrapped_callback(request, *callback_args, **callback_kwargs)
  File "C:\Python34\lib\site-packages\django\contrib\auth\decorators.py", line 22, in _wrapped_view
    return view_func(request, *args, **kwargs)
  File "C:\uav\common\views\test.py", line 29, in test
    Sent_All_Job_Log_To_Flume.delay()
  File "C:\Python34\lib\site-packages\celery\app\task.py", line 453, in delay
    return self.apply_async(args, kwargs)
  File "C:\Python34\lib\site-packages\celery\app\task.py", line 560, in apply_async
    **dict(self._get_exec_options(), **options)
  File "C:\Python34\lib\site-packages\celery\app\base.py", line 354, in send_task
    reply_to=reply_to or self.oid, **options
  File "C:\Python34\lib\site-packages\celery\app\amqp.py", line 305, in publish_task
    **kwargs
  File "C:\Python34\lib\site-packages\kombu\messaging.py", line 172, in publish
    routing_key, mandatory, immediate, exchange, declare)
  File "C:\Python34\lib\site-packages\kombu\connection.py", line 457, in _ensured
    interval_max)
  File "C:\Python34\lib\site-packages\kombu\connection.py", line 369, in ensure_connection
    interval_start, interval_step, interval_max, callback)
  File "C:\Python34\lib\site-packages\kombu\utils\__init__.py", line 246, in retry_over_time
    return fun(*args, **kwargs)
  File "C:\Python34\lib\site-packages\kombu\connection.py", line 237, in connect
    return self.connection
  File "C:\Python34\lib\site-packages\kombu\connection.py", line 741, in connection
    self._connection = self._establish_connection()
  File "C:\Python34\lib\site-packages\kombu\connection.py", line 696, in _establish_connection
    conn = self.transport.establish_connection()
  File "C:\Python34\lib\site-packages\kombu\transport\virtual\__init__.py", line 809, in establish_connection
    self._avail_channels.append(self.create_channel(self))
  File "C:\Python34\lib\site-packages\kombu\transport\virtual\__init__.py", line 791, in create_channel
    channel = self.Channel(connection)
  File "C:\Python34\lib\site-packages\kombu\transport\redis.py", line 453, in __init__
    self.client.info()
  File "C:\Python34\lib\site-packages\redis\client.py", line 753, in info
    return self.execute_command('INFO')
  File "C:\Python34\lib\site-packages\redis\client.py", line 663, in execute_command
    connection.disconnect()
  File "C:\Python34\lib\site-packages\kombu\transport\redis.py", line 819, in disconnect
    channel._on_connection_disconnect(self)
  File "C:\Python34\lib\site-packages\kombu\transport\redis.py", line 476, in _on_connection_disconnect
    raise get_redis_ConnectionError()
redis.exceptions.ConnectionError
ERROR 2017-02-24 14:02:28,619 Internal Server Error: /test/
Traceback (most recent call last):
  File "C:\Python34\lib\site-packages\kombu\utils\__init__.py", line 423, in __call__
    return self.__value__
AttributeError: 'ChannelPromise' object has no attribute '__value__'

During handling of the above exception, another exception occurred:

Traceback (most recent call last):
  File "C:\Python34\lib\site-packages\kombu\transport\virtual\__init__.py", line 789, in create_channel
    return self._avail_channels.pop()
IndexError: pop from empty list

During handling of the above exception, another exception occurred:

Traceback (most recent call last):
  File "C:\Python34\lib\site-packages\redis\connection.py", line 143, in _read_from_socket
    data = recv(self._sock, socket_read_size)
  File "C:\Python34\lib\site-packages\redis\_compat.py", line 60, in recv
    return _retryable_call(sock, sock.recv, *args, **kwargs)
  File "C:\Python34\lib\site-packages\redis\_compat.py", line 48, in _retryable_call
    return func(*args, **kwargs)
ConnectionResetError: [WinError 10054] 远程主机强迫关闭了一个现有的连接。

During handling of the above exception, another exception occurred:

Traceback (most recent call last):
  File "C:\Python34\lib\site-packages\redis\connection.py", line 612, in read_response
    response = self._parser.read_response()
  File "C:\Python34\lib\site-packages\redis\connection.py", line 255, in read_response
    response = self._buffer.readline()
  File "C:\Python34\lib\site-packages\redis\connection.py", line 185, in readline
    self._read_from_socket()
  File "C:\Python34\lib\site-packages\redis\connection.py", line 160, in _read_from_socket
    (e.args,))
redis.exceptions.ConnectionError: Error while reading from socket: (10054, '远程主机强迫关闭了一个现有的连接。', None, 10054, None)

During handling of the above exception, another exception occurred:

Traceback (most recent call last):
  File "C:\Python34\lib\site-packages\redis\client.py", line 661, in execute_command
    return self.parse_response(connection, command_name, **options)
  File "C:\Python34\lib\site-packages\redis\client.py", line 673, in parse_response
    response = connection.read_response()
  File "C:\Python34\lib\site-packages\redis\connection.py", line 614, in read_response
    self.disconnect()
  File "C:\Python34\lib\site-packages\kombu\transport\redis.py", line 819, in disconnect
    channel._on_connection_disconnect(self)
  File "C:\Python34\lib\site-packages\kombu\transport\redis.py", line 476, in _on_connection_disconnect
    raise get_redis_ConnectionError()
redis.exceptions.ConnectionError

During handling of the above exception, another exception occurred:

Traceback (most recent call last):
  File "C:\Python34\lib\site-packages\kombu\connection.py", line 436, in _ensured
    return fun(*args, **kwargs)
  File "C:\Python34\lib\site-packages\kombu\messaging.py", line 177, in _publish
    channel = self.channel
  File "C:\Python34\lib\site-packages\kombu\messaging.py", line 194, in _get_channel
    channel = self._channel = channel()
  File "C:\Python34\lib\site-packages\kombu\utils\__init__.py", line 425, in __call__
    value = self.__value__ = self.__contract__()
  File "C:\Python34\lib\site-packages\kombu\messaging.py", line 209, in <lambda>
    channel = ChannelPromise(lambda: connection.default_channel)
  File "C:\Python34\lib\site-packages\kombu\connection.py", line 756, in default_channel
    self.connection
  File "C:\Python34\lib\site-packages\kombu\connection.py", line 741, in connection
    self._connection = self._establish_connection()
  File "C:\Python34\lib\site-packages\kombu\connection.py", line 696, in _establish_connection
    conn = self.transport.establish_connection()
  File "C:\Python34\lib\site-packages\kombu\transport\virtual\__init__.py", line 809, in establish_connection
    self._avail_channels.append(self.create_channel(self))
  File "C:\Python34\lib\site-packages\kombu\transport\virtual\__init__.py", line 791, in create_channel
    channel = self.Channel(connection)
  File "C:\Python34\lib\site-packages\kombu\transport\redis.py", line 453, in __init__
    self.client.info()
  File "C:\Python34\lib\site-packages\redis\client.py", line 753, in info
    return self.execute_command('INFO')
  File "C:\Python34\lib\site-packages\redis\client.py", line 663, in execute_command
    connection.disconnect()
  File "C:\Python34\lib\site-packages\kombu\transport\redis.py", line 819, in disconnect
    channel._on_connection_disconnect(self)
  File "C:\Python34\lib\site-packages\kombu\transport\redis.py", line 476, in _on_connection_disconnect
    raise get_redis_ConnectionError()
redis.exceptions.ConnectionError

During handling of the above exception, another exception occurred:

Traceback (most recent call last):
  File "C:\Python34\lib\site-packages\kombu\transport\virtual\__init__.py", line 789, in create_channel
    return self._avail_channels.pop()
IndexError: pop from empty list

During handling of the above exception, another exception occurred:

Traceback (most recent call last):
  File "C:\Python34\lib\site-packages\redis\connection.py", line 143, in _read_from_socket
    data = recv(self._sock, socket_read_size)
  File "C:\Python34\lib\site-packages\redis\_compat.py", line 60, in recv
    return _retryable_call(sock, sock.recv, *args, **kwargs)
  File "C:\Python34\lib\site-packages\redis\_compat.py", line 48, in _retryable_call
    return func(*args, **kwargs)
ConnectionResetError: [WinError 10054] 远程主机强迫关闭了一个现有的连接。

During handling of the above exception, another exception occurred:

Traceback (most recent call last):
  File "C:\Python34\lib\site-packages\redis\connection.py", line 612, in read_response
    response = self._parser.read_response()
  File "C:\Python34\lib\site-packages\redis\connection.py", line 255, in read_response
    response = self._buffer.readline()
  File "C:\Python34\lib\site-packages\redis\connection.py", line 185, in readline
    self._read_from_socket()
  File "C:\Python34\lib\site-packages\redis\connection.py", line 160, in _read_from_socket
    (e.args,))
redis.exceptions.ConnectionError: Error while reading from socket: (10054, '远程主机强迫关闭了一个现有的连接。', None, 10054, None)

During handling of the above exception, another exception occurred:

Traceback (most recent call last):
  File "C:\Python34\lib\site-packages\redis\client.py", line 661, in execute_command
    return self.parse_response(connection, command_name, **options)
  File "C:\Python34\lib\site-packages\redis\client.py", line 673, in parse_response
    response = connection.read_response()
  File "C:\Python34\lib\site-packages\redis\connection.py", line 614, in read_response
    self.disconnect()
  File "C:\Python34\lib\site-packages\kombu\transport\redis.py", line 819, in disconnect
    channel._on_connection_disconnect(self)
  File "C:\Python34\lib\site-packages\kombu\transport\redis.py", line 476, in _on_connection_disconnect
    raise get_redis_ConnectionError()
redis.exceptions.ConnectionError

During handling of the above exception, another exception occurred:

Traceback (most recent call last):
  File "C:\Python34\lib\site-packages\django\core\handlers\base.py", line 132, in get_response
    response = wrapped_callback(request, *callback_args, **callback_kwargs)
  File "C:\Python34\lib\site-packages\django\contrib\auth\decorators.py", line 22, in _wrapped_view
    return view_func(request, *args, **kwargs)
  File "C:\uav\common\views\test.py", line 29, in test
    Sent_All_Job_Log_To_Flume.delay()
  File "C:\Python34\lib\site-packages\celery\app\task.py", line 453, in delay
    return self.apply_async(args, kwargs)
  File "C:\Python34\lib\site-packages\celery\app\task.py", line 560, in apply_async
    **dict(self._get_exec_options(), **options)
  File "C:\Python34\lib\site-packages\celery\app\base.py", line 354, in send_task
    reply_to=reply_to or self.oid, **options
  File "C:\Python34\lib\site-packages\celery\app\amqp.py", line 305, in publish_task
    **kwargs
  File "C:\Python34\lib\site-packages\kombu\messaging.py", line 172, in publish
    routing_key, mandatory, immediate, exchange, declare)
  File "C:\Python34\lib\site-packages\kombu\connection.py", line 457, in _ensured
    interval_max)
  File "C:\Python34\lib\site-packages\kombu\connection.py", line 369, in ensure_connection
    interval_start, interval_step, interval_max, callback)
  File "C:\Python34\lib\site-packages\kombu\utils\__init__.py", line 246, in retry_over_time
    return fun(*args, **kwargs)
  File "C:\Python34\lib\site-packages\kombu\connection.py", line 237, in connect
    return self.connection
  File "C:\Python34\lib\site-packages\kombu\connection.py", line 741, in connection
    self._connection = self._establish_connection()
  File "C:\Python34\lib\site-packages\kombu\connection.py", line 696, in _establish_connection
    conn = self.transport.establish_connection()
  File "C:\Python34\lib\site-packages\kombu\transport\virtual\__init__.py", line 809, in establish_connection
    self._avail_channels.append(self.create_channel(self))
  File "C:\Python34\lib\site-packages\kombu\transport\virtual\__init__.py", line 791, in create_channel
    channel = self.Channel(connection)
  File "C:\Python34\lib\site-packages\kombu\transport\redis.py", line 453, in __init__
    self.client.info()
  File "C:\Python34\lib\site-packages\redis\client.py", line 753, in info
    return self.execute_command('INFO')
  File "C:\Python34\lib\site-packages\redis\client.py", line 663, in execute_command
    connection.disconnect()
  File "C:\Python34\lib\site-packages\kombu\transport\redis.py", line 819, in disconnect
    channel._on_connection_disconnect(self)
  File "C:\Python34\lib\site-packages\kombu\transport\redis.py", line 476, in _on_connection_disconnect
    raise get_redis_ConnectionError()
redis.exceptions.ConnectionError
ERROR 2017-02-24 14:03:26,064 Internal Server Error: /test/
Traceback (most recent call last):
  File "C:\Python34\lib\site-packages\kombu\utils\__init__.py", line 423, in __call__
    return self.__value__
AttributeError: 'ChannelPromise' object has no attribute '__value__'

During handling of the above exception, another exception occurred:

Traceback (most recent call last):
  File "C:\Python34\lib\site-packages\kombu\transport\virtual\__init__.py", line 789, in create_channel
    return self._avail_channels.pop()
IndexError: pop from empty list

During handling of the above exception, another exception occurred:

Traceback (most recent call last):
  File "C:\Python34\lib\site-packages\redis\connection.py", line 143, in _read_from_socket
    data = recv(self._sock, socket_read_size)
  File "C:\Python34\lib\site-packages\redis\_compat.py", line 60, in recv
    return _retryable_call(sock, sock.recv, *args, **kwargs)
  File "C:\Python34\lib\site-packages\redis\_compat.py", line 48, in _retryable_call
    return func(*args, **kwargs)
ConnectionResetError: [WinError 10054] 远程主机强迫关闭了一个现有的连接。

During handling of the above exception, another exception occurred:

Traceback (most recent call last):
  File "C:\Python34\lib\site-packages\redis\connection.py", line 612, in read_response
    response = self._parser.read_response()
  File "C:\Python34\lib\site-packages\redis\connection.py", line 255, in read_response
    response = self._buffer.readline()
  File "C:\Python34\lib\site-packages\redis\connection.py", line 185, in readline
    self._read_from_socket()
  File "C:\Python34\lib\site-packages\redis\connection.py", line 160, in _read_from_socket
    (e.args,))
redis.exceptions.ConnectionError: Error while reading from socket: (10054, '远程主机强迫关闭了一个现有的连接。', None, 10054, None)

During handling of the above exception, another exception occurred:

Traceback (most recent call last):
  File "C:\Python34\lib\site-packages\redis\client.py", line 661, in execute_command
    return self.parse_response(connection, command_name, **options)
  File "C:\Python34\lib\site-packages\redis\client.py", line 673, in parse_response
    response = connection.read_response()
  File "C:\Python34\lib\site-packages\redis\connection.py", line 614, in read_response
    self.disconnect()
  File "C:\Python34\lib\site-packages\kombu\transport\redis.py", line 819, in disconnect
    channel._on_connection_disconnect(self)
  File "C:\Python34\lib\site-packages\kombu\transport\redis.py", line 476, in _on_connection_disconnect
    raise get_redis_ConnectionError()
redis.exceptions.ConnectionError

During handling of the above exception, another exception occurred:

Traceback (most recent call last):
  File "C:\Python34\lib\site-packages\kombu\connection.py", line 436, in _ensured
    return fun(*args, **kwargs)
  File "C:\Python34\lib\site-packages\kombu\messaging.py", line 177, in _publish
    channel = self.channel
  File "C:\Python34\lib\site-packages\kombu\messaging.py", line 194, in _get_channel
    channel = self._channel = channel()
  File "C:\Python34\lib\site-packages\kombu\utils\__init__.py", line 425, in __call__
    value = self.__value__ = self.__contract__()
  File "C:\Python34\lib\site-packages\kombu\messaging.py", line 209, in <lambda>
    channel = ChannelPromise(lambda: connection.default_channel)
  File "C:\Python34\lib\site-packages\kombu\connection.py", line 756, in default_channel
    self.connection
  File "C:\Python34\lib\site-packages\kombu\connection.py", line 741, in connection
    self._connection = self._establish_connection()
  File "C:\Python34\lib\site-packages\kombu\connection.py", line 696, in _establish_connection
    conn = self.transport.establish_connection()
  File "C:\Python34\lib\site-packages\kombu\transport\virtual\__init__.py", line 809, in establish_connection
    self._avail_channels.append(self.create_channel(self))
  File "C:\Python34\lib\site-packages\kombu\transport\virtual\__init__.py", line 791, in create_channel
    channel = self.Channel(connection)
  File "C:\Python34\lib\site-packages\kombu\transport\redis.py", line 453, in __init__
    self.client.info()
  File "C:\Python34\lib\site-packages\redis\client.py", line 753, in info
    return self.execute_command('INFO')
  File "C:\Python34\lib\site-packages\redis\client.py", line 663, in execute_command
    connection.disconnect()
  File "C:\Python34\lib\site-packages\kombu\transport\redis.py", line 819, in disconnect
    channel._on_connection_disconnect(self)
  File "C:\Python34\lib\site-packages\kombu\transport\redis.py", line 476, in _on_connection_disconnect
    raise get_redis_ConnectionError()
redis.exceptions.ConnectionError

During handling of the above exception, another exception occurred:

Traceback (most recent call last):
  File "C:\Python34\lib\site-packages\kombu\transport\virtual\__init__.py", line 789, in create_channel
    return self._avail_channels.pop()
IndexError: pop from empty list

During handling of the above exception, another exception occurred:

Traceback (most recent call last):
  File "C:\Python34\lib\site-packages\redis\connection.py", line 143, in _read_from_socket
    data = recv(self._sock, socket_read_size)
  File "C:\Python34\lib\site-packages\redis\_compat.py", line 60, in recv
    return _retryable_call(sock, sock.recv, *args, **kwargs)
  File "C:\Python34\lib\site-packages\redis\_compat.py", line 48, in _retryable_call
    return func(*args, **kwargs)
ConnectionResetError: [WinError 10054] 远程主机强迫关闭了一个现有的连接。

During handling of the above exception, another exception occurred:

Traceback (most recent call last):
  File "C:\Python34\lib\site-packages\redis\connection.py", line 612, in read_response
    response = self._parser.read_response()
  File "C:\Python34\lib\site-packages\redis\connection.py", line 255, in read_response
    response = self._buffer.readline()
  File "C:\Python34\lib\site-packages\redis\connection.py", line 185, in readline
    self._read_from_socket()
  File "C:\Python34\lib\site-packages\redis\connection.py", line 160, in _read_from_socket
    (e.args,))
redis.exceptions.ConnectionError: Error while reading from socket: (10054, '远程主机强迫关闭了一个现有的连接。', None, 10054, None)

During handling of the above exception, another exception occurred:

Traceback (most recent call last):
  File "C:\Python34\lib\site-packages\redis\client.py", line 661, in execute_command
    return self.parse_response(connection, command_name, **options)
  File "C:\Python34\lib\site-packages\redis\client.py", line 673, in parse_response
    response = connection.read_response()
  File "C:\Python34\lib\site-packages\redis\connection.py", line 614, in read_response
    self.disconnect()
  File "C:\Python34\lib\site-packages\kombu\transport\redis.py", line 819, in disconnect
    channel._on_connection_disconnect(self)
  File "C:\Python34\lib\site-packages\kombu\transport\redis.py", line 476, in _on_connection_disconnect
    raise get_redis_ConnectionError()
redis.exceptions.ConnectionError

During handling of the above exception, another exception occurred:

Traceback (most recent call last):
  File "C:\Python34\lib\site-packages\django\core\handlers\base.py", line 132, in get_response
    response = wrapped_callback(request, *callback_args, **callback_kwargs)
  File "C:\Python34\lib\site-packages\django\contrib\auth\decorators.py", line 22, in _wrapped_view
    return view_func(request, *args, **kwargs)
  File "C:\uav\common\views\test.py", line 29, in test
    Sent_All_Job_Log_To_Flume.delay()
  File "C:\Python34\lib\site-packages\celery\app\task.py", line 453, in delay
    return self.apply_async(args, kwargs)
  File "C:\Python34\lib\site-packages\celery\app\task.py", line 560, in apply_async
    **dict(self._get_exec_options(), **options)
  File "C:\Python34\lib\site-packages\celery\app\base.py", line 354, in send_task
    reply_to=reply_to or self.oid, **options
  File "C:\Python34\lib\site-packages\celery\app\amqp.py", line 305, in publish_task
    **kwargs
  File "C:\Python34\lib\site-packages\kombu\messaging.py", line 172, in publish
    routing_key, mandatory, immediate, exchange, declare)
  File "C:\Python34\lib\site-packages\kombu\connection.py", line 457, in _ensured
    interval_max)
  File "C:\Python34\lib\site-packages\kombu\connection.py", line 369, in ensure_connection
    interval_start, interval_step, interval_max, callback)
  File "C:\Python34\lib\site-packages\kombu\utils\__init__.py", line 246, in retry_over_time
    return fun(*args, **kwargs)
  File "C:\Python34\lib\site-packages\kombu\connection.py", line 237, in connect
    return self.connection
  File "C:\Python34\lib\site-packages\kombu\connection.py", line 741, in connection
    self._connection = self._establish_connection()
  File "C:\Python34\lib\site-packages\kombu\connection.py", line 696, in _establish_connection
    conn = self.transport.establish_connection()
  File "C:\Python34\lib\site-packages\kombu\transport\virtual\__init__.py", line 809, in establish_connection
    self._avail_channels.append(self.create_channel(self))
  File "C:\Python34\lib\site-packages\kombu\transport\virtual\__init__.py", line 791, in create_channel
    channel = self.Channel(connection)
  File "C:\Python34\lib\site-packages\kombu\transport\redis.py", line 453, in __init__
    self.client.info()
  File "C:\Python34\lib\site-packages\redis\client.py", line 753, in info
    return self.execute_command('INFO')
  File "C:\Python34\lib\site-packages\redis\client.py", line 663, in execute_command
    connection.disconnect()
  File "C:\Python34\lib\site-packages\kombu\transport\redis.py", line 819, in disconnect
    channel._on_connection_disconnect(self)
  File "C:\Python34\lib\site-packages\kombu\transport\redis.py", line 476, in _on_connection_disconnect
    raise get_redis_ConnectionError()
redis.exceptions.ConnectionError
ERROR 2017-02-24 14:03:26,064 Internal Server Error: /test/
Traceback (most recent call last):
  File "C:\Python34\lib\site-packages\kombu\utils\__init__.py", line 423, in __call__
    return self.__value__
AttributeError: 'ChannelPromise' object has no attribute '__value__'

During handling of the above exception, another exception occurred:

Traceback (most recent call last):
  File "C:\Python34\lib\site-packages\kombu\transport\virtual\__init__.py", line 789, in create_channel
    return self._avail_channels.pop()
IndexError: pop from empty list

During handling of the above exception, another exception occurred:

Traceback (most recent call last):
  File "C:\Python34\lib\site-packages\redis\connection.py", line 143, in _read_from_socket
    data = recv(self._sock, socket_read_size)
  File "C:\Python34\lib\site-packages\redis\_compat.py", line 60, in recv
    return _retryable_call(sock, sock.recv, *args, **kwargs)
  File "C:\Python34\lib\site-packages\redis\_compat.py", line 48, in _retryable_call
    return func(*args, **kwargs)
ConnectionResetError: [WinError 10054] 远程主机强迫关闭了一个现有的连接。

During handling of the above exception, another exception occurred:

Traceback (most recent call last):
  File "C:\Python34\lib\site-packages\redis\connection.py", line 612, in read_response
    response = self._parser.read_response()
  File "C:\Python34\lib\site-packages\redis\connection.py", line 255, in read_response
    response = self._buffer.readline()
  File "C:\Python34\lib\site-packages\redis\connection.py", line 185, in readline
    self._read_from_socket()
  File "C:\Python34\lib\site-packages\redis\connection.py", line 160, in _read_from_socket
    (e.args,))
redis.exceptions.ConnectionError: Error while reading from socket: (10054, '远程主机强迫关闭了一个现有的连接。', None, 10054, None)

During handling of the above exception, another exception occurred:

Traceback (most recent call last):
  File "C:\Python34\lib\site-packages\redis\client.py", line 661, in execute_command
    return self.parse_response(connection, command_name, **options)
  File "C:\Python34\lib\site-packages\redis\client.py", line 673, in parse_response
    response = connection.read_response()
  File "C:\Python34\lib\site-packages\redis\connection.py", line 614, in read_response
    self.disconnect()
  File "C:\Python34\lib\site-packages\kombu\transport\redis.py", line 819, in disconnect
    channel._on_connection_disconnect(self)
  File "C:\Python34\lib\site-packages\kombu\transport\redis.py", line 476, in _on_connection_disconnect
    raise get_redis_ConnectionError()
redis.exceptions.ConnectionError

During handling of the above exception, another exception occurred:

Traceback (most recent call last):
  File "C:\Python34\lib\site-packages\kombu\connection.py", line 436, in _ensured
    return fun(*args, **kwargs)
  File "C:\Python34\lib\site-packages\kombu\messaging.py", line 177, in _publish
    channel = self.channel
  File "C:\Python34\lib\site-packages\kombu\messaging.py", line 194, in _get_channel
    channel = self._channel = channel()
  File "C:\Python34\lib\site-packages\kombu\utils\__init__.py", line 425, in __call__
    value = self.__value__ = self.__contract__()
  File "C:\Python34\lib\site-packages\kombu\messaging.py", line 209, in <lambda>
    channel = ChannelPromise(lambda: connection.default_channel)
  File "C:\Python34\lib\site-packages\kombu\connection.py", line 756, in default_channel
    self.connection
  File "C:\Python34\lib\site-packages\kombu\connection.py", line 741, in connection
    self._connection = self._establish_connection()
  File "C:\Python34\lib\site-packages\kombu\connection.py", line 696, in _establish_connection
    conn = self.transport.establish_connection()
  File "C:\Python34\lib\site-packages\kombu\transport\virtual\__init__.py", line 809, in establish_connection
    self._avail_channels.append(self.create_channel(self))
  File "C:\Python34\lib\site-packages\kombu\transport\virtual\__init__.py", line 791, in create_channel
    channel = self.Channel(connection)
  File "C:\Python34\lib\site-packages\kombu\transport\redis.py", line 453, in __init__
    self.client.info()
  File "C:\Python34\lib\site-packages\redis\client.py", line 753, in info
    return self.execute_command('INFO')
  File "C:\Python34\lib\site-packages\redis\client.py", line 663, in execute_command
    connection.disconnect()
  File "C:\Python34\lib\site-packages\kombu\transport\redis.py", line 819, in disconnect
    channel._on_connection_disconnect(self)
  File "C:\Python34\lib\site-packages\kombu\transport\redis.py", line 476, in _on_connection_disconnect
    raise get_redis_ConnectionError()
redis.exceptions.ConnectionError

During handling of the above exception, another exception occurred:

Traceback (most recent call last):
  File "C:\Python34\lib\site-packages\kombu\transport\virtual\__init__.py", line 789, in create_channel
    return self._avail_channels.pop()
IndexError: pop from empty list

During handling of the above exception, another exception occurred:

Traceback (most recent call last):
  File "C:\Python34\lib\site-packages\redis\connection.py", line 143, in _read_from_socket
    data = recv(self._sock, socket_read_size)
  File "C:\Python34\lib\site-packages\redis\_compat.py", line 60, in recv
    return _retryable_call(sock, sock.recv, *args, **kwargs)
  File "C:\Python34\lib\site-packages\redis\_compat.py", line 48, in _retryable_call
    return func(*args, **kwargs)
ConnectionResetError: [WinError 10054] 远程主机强迫关闭了一个现有的连接。

During handling of the above exception, another exception occurred:

Traceback (most recent call last):
  File "C:\Python34\lib\site-packages\redis\connection.py", line 612, in read_response
    response = self._parser.read_response()
  File "C:\Python34\lib\site-packages\redis\connection.py", line 255, in read_response
    response = self._buffer.readline()
  File "C:\Python34\lib\site-packages\redis\connection.py", line 185, in readline
    self._read_from_socket()
  File "C:\Python34\lib\site-packages\redis\connection.py", line 160, in _read_from_socket
    (e.args,))
redis.exceptions.ConnectionError: Error while reading from socket: (10054, '远程主机强迫关闭了一个现有的连接。', None, 10054, None)

During handling of the above exception, another exception occurred:

Traceback (most recent call last):
  File "C:\Python34\lib\site-packages\redis\client.py", line 661, in execute_command
    return self.parse_response(connection, command_name, **options)
  File "C:\Python34\lib\site-packages\redis\client.py", line 673, in parse_response
    response = connection.read_response()
  File "C:\Python34\lib\site-packages\redis\connection.py", line 614, in read_response
    self.disconnect()
  File "C:\Python34\lib\site-packages\kombu\transport\redis.py", line 819, in disconnect
    channel._on_connection_disconnect(self)
  File "C:\Python34\lib\site-packages\kombu\transport\redis.py", line 476, in _on_connection_disconnect
    raise get_redis_ConnectionError()
redis.exceptions.ConnectionError

During handling of the above exception, another exception occurred:

Traceback (most recent call last):
  File "C:\Python34\lib\site-packages\django\core\handlers\base.py", line 132, in get_response
    response = wrapped_callback(request, *callback_args, **callback_kwargs)
  File "C:\Python34\lib\site-packages\django\contrib\auth\decorators.py", line 22, in _wrapped_view
    return view_func(request, *args, **kwargs)
  File "C:\uav\common\views\test.py", line 29, in test
    Sent_All_Job_Log_To_Flume.delay()
  File "C:\Python34\lib\site-packages\celery\app\task.py", line 453, in delay
    return self.apply_async(args, kwargs)
  File "C:\Python34\lib\site-packages\celery\app\task.py", line 560, in apply_async
    **dict(self._get_exec_options(), **options)
  File "C:\Python34\lib\site-packages\celery\app\base.py", line 354, in send_task
    reply_to=reply_to or self.oid, **options
  File "C:\Python34\lib\site-packages\celery\app\amqp.py", line 305, in publish_task
    **kwargs
  File "C:\Python34\lib\site-packages\kombu\messaging.py", line 172, in publish
    routing_key, mandatory, immediate, exchange, declare)
  File "C:\Python34\lib\site-packages\kombu\connection.py", line 457, in _ensured
    interval_max)
  File "C:\Python34\lib\site-packages\kombu\connection.py", line 369, in ensure_connection
    interval_start, interval_step, interval_max, callback)
  File "C:\Python34\lib\site-packages\kombu\utils\__init__.py", line 246, in retry_over_time
    return fun(*args, **kwargs)
  File "C:\Python34\lib\site-packages\kombu\connection.py", line 237, in connect
    return self.connection
  File "C:\Python34\lib\site-packages\kombu\connection.py", line 741, in connection
    self._connection = self._establish_connection()
  File "C:\Python34\lib\site-packages\kombu\connection.py", line 696, in _establish_connection
    conn = self.transport.establish_connection()
  File "C:\Python34\lib\site-packages\kombu\transport\virtual\__init__.py", line 809, in establish_connection
    self._avail_channels.append(self.create_channel(self))
  File "C:\Python34\lib\site-packages\kombu\transport\virtual\__init__.py", line 791, in create_channel
    channel = self.Channel(connection)
  File "C:\Python34\lib\site-packages\kombu\transport\redis.py", line 453, in __init__
    self.client.info()
  File "C:\Python34\lib\site-packages\redis\client.py", line 753, in info
    return self.execute_command('INFO')
  File "C:\Python34\lib\site-packages\redis\client.py", line 663, in execute_command
    connection.disconnect()
  File "C:\Python34\lib\site-packages\kombu\transport\redis.py", line 819, in disconnect
    channel._on_connection_disconnect(self)
  File "C:\Python34\lib\site-packages\kombu\transport\redis.py", line 476, in _on_connection_disconnect
    raise get_redis_ConnectionError()
redis.exceptions.ConnectionError
WARNING 2017-02-24 14:08:04,027 Not Found: /test/profile.png
WARNING 2017-02-24 14:08:04,027 Not Found: /test/profile.png
WARNING 2017-02-24 14:08:04,048 Not Found: /test/cabin.png
WARNING 2017-02-24 14:08:04,048 Not Found: /test/cabin.png
WARNING 2017-02-24 14:08:04,056 Not Found: /test/cake.png
WARNING 2017-02-24 14:08:04,056 Not Found: /test/cake.png
WARNING 2017-02-24 14:08:04,362 Not Found: /test/game.png
WARNING 2017-02-24 14:08:04,364 Not Found: /test/circus.png
WARNING 2017-02-24 14:08:04,365 Not Found: /test/user.png
WARNING 2017-02-24 14:08:04,362 Not Found: /test/game.png
WARNING 2017-02-24 14:08:04,364 Not Found: /test/circus.png
WARNING 2017-02-24 14:08:04,365 Not Found: /test/user.png
WARNING 2017-02-24 14:08:53,259 Not Found: /test/profile.png
WARNING 2017-02-24 14:08:53,259 Not Found: /test/profile.png
WARNING 2017-02-24 14:08:53,273 Not Found: /test/cabin.png
WARNING 2017-02-24 14:08:53,273 Not Found: /test/cabin.png
WARNING 2017-02-24 14:08:53,283 Not Found: /test/cake.png
WARNING 2017-02-24 14:08:53,283 Not Found: /test/cake.png
WARNING 2017-02-24 14:08:53,289 Not Found: /test/game.png
WARNING 2017-02-24 14:08:53,289 Not Found: /test/game.png
WARNING 2017-02-24 14:08:53,468 Not Found: /test/circus.png
WARNING 2017-02-24 14:08:53,468 Not Found: /test/circus.png
WARNING 2017-02-24 14:08:53,589 Not Found: /test/user.png
WARNING 2017-02-24 14:08:53,589 Not Found: /test/user.png
WARNING 2017-02-24 14:21:01,167 Not Found: /test/profile.png
WARNING 2017-02-24 14:21:01,167 Not Found: /test/profile.png
WARNING 2017-02-24 14:21:01,188 Not Found: /test/cabin.png
WARNING 2017-02-24 14:21:01,189 Not Found: /test/cake.png
WARNING 2017-02-24 14:21:01,189 Not Found: /test/cake.png
WARNING 2017-02-24 14:21:01,192 Not Found: /test/circus.png
WARNING 2017-02-24 14:21:01,188 Not Found: /test/cabin.png
WARNING 2017-02-24 14:21:01,190 Not Found: /test/game.png
WARNING 2017-02-24 14:21:01,192 Not Found: /test/circus.png
WARNING 2017-02-24 14:21:01,190 Not Found: /test/game.png
WARNING 2017-02-24 14:21:01,493 Not Found: /test/user.png
WARNING 2017-02-24 14:21:01,493 Not Found: /test/user.png
WARNING 2017-02-24 14:21:18,211 Not Found: /test/profile.png
WARNING 2017-02-24 14:21:18,211 Not Found: /test/profile.png
WARNING 2017-02-24 14:21:18,224 Not Found: /test/cabin.png
WARNING 2017-02-24 14:21:18,224 Not Found: /test/cabin.png
WARNING 2017-02-24 14:21:18,236 Not Found: /test/cake.png
WARNING 2017-02-24 14:21:18,237 Not Found: /test/game.png
WARNING 2017-02-24 14:21:18,238 Not Found: /test/circus.png
WARNING 2017-02-24 14:21:18,236 Not Found: /test/cake.png
WARNING 2017-02-24 14:21:18,237 Not Found: /test/game.png
WARNING 2017-02-24 14:21:18,238 Not Found: /test/circus.png
WARNING 2017-02-24 14:21:18,542 Not Found: /test/user.png
WARNING 2017-02-24 14:21:18,542 Not Found: /test/user.png
WARNING 2017-02-24 14:21:21,045 Not Found: /test/profile.png
WARNING 2017-02-24 14:21:21,045 Not Found: /test/profile.png
WARNING 2017-02-24 14:21:21,060 Not Found: /test/cabin.png
WARNING 2017-02-24 14:21:21,061 Not Found: /test/game.png
WARNING 2017-02-24 14:21:21,063 Not Found: /test/circus.png
WARNING 2017-02-24 14:21:21,063 Not Found: /test/circus.png
WARNING 2017-02-24 14:21:21,060 Not Found: /test/cabin.png
WARNING 2017-02-24 14:21:21,061 Not Found: /test/game.png
WARNING 2017-02-24 14:21:21,065 Not Found: /test/cake.png
WARNING 2017-02-24 14:21:21,065 Not Found: /test/cake.png
WARNING 2017-02-24 14:21:21,367 Not Found: /test/user.png
WARNING 2017-02-24 14:21:21,367 Not Found: /test/user.png
WARNING 2017-02-24 14:21:23,722 Not Found: /test/profile.png
WARNING 2017-02-24 14:21:23,722 Not Found: /test/profile.png
WARNING 2017-02-24 14:21:23,750 Not Found: /test/cabin.png
WARNING 2017-02-24 14:21:23,752 Not Found: /test/game.png
WARNING 2017-02-24 14:21:23,753 Not Found: /test/circus.png
WARNING 2017-02-24 14:21:23,750 Not Found: /test/cabin.png
WARNING 2017-02-24 14:21:23,755 Not Found: /test/cake.png
WARNING 2017-02-24 14:21:23,752 Not Found: /test/game.png
WARNING 2017-02-24 14:21:23,753 Not Found: /test/circus.png
WARNING 2017-02-24 14:21:23,755 Not Found: /test/cake.png
WARNING 2017-02-24 14:21:24,055 Not Found: /test/user.png
WARNING 2017-02-24 14:21:24,055 Not Found: /test/user.png
WARNING 2017-02-24 14:21:45,754 Not Found: /test/profile.png
WARNING 2017-02-24 14:21:45,754 Not Found: /test/profile.png
WARNING 2017-02-24 14:21:45,772 Not Found: /test/cabin.png
WARNING 2017-02-24 14:21:45,772 Not Found: /test/cabin.png
WARNING 2017-02-24 14:21:45,775 Not Found: /test/cake.png
WARNING 2017-02-24 14:21:45,782 Not Found: /test/circus.png
WARNING 2017-02-24 14:21:45,775 Not Found: /test/cake.png
WARNING 2017-02-24 14:21:45,783 Not Found: /test/game.png
WARNING 2017-02-24 14:21:45,782 Not Found: /test/circus.png
WARNING 2017-02-24 14:21:45,783 Not Found: /test/game.png
WARNING 2017-02-24 14:21:46,078 Not Found: /test/user.png
WARNING 2017-02-24 14:21:46,078 Not Found: /test/user.png
WARNING 2017-02-24 14:28:33,032 Not Found: /test/profile.png
WARNING 2017-02-24 14:28:33,032 Not Found: /test/profile.png
WARNING 2017-02-24 14:28:33,046 Not Found: /test/cabin.png
WARNING 2017-02-24 14:28:33,046 Not Found: /test/cabin.png
WARNING 2017-02-24 14:28:33,053 Not Found: /test/game.png
WARNING 2017-02-24 14:28:33,055 Not Found: /test/circus.png
WARNING 2017-02-24 14:28:33,056 Not Found: /test/cake.png
WARNING 2017-02-24 14:28:33,053 Not Found: /test/game.png
WARNING 2017-02-24 14:28:33,055 Not Found: /test/circus.png
WARNING 2017-02-24 14:28:33,056 Not Found: /test/cake.png
WARNING 2017-02-24 14:28:33,358 Not Found: /test/user.png
WARNING 2017-02-24 14:28:33,358 Not Found: /test/user.png
