ERROR 2017-01-09 14:42:11,786 Internal Server Error: /alljobsrecommend/
Traceback (most recent call last):
  File "C:\Python34\lib\site-packages\django\core\handlers\base.py", line 132, in get_response
    response = wrapped_callback(request, *callback_args, **callback_kwargs)
  File "C:\Python34\lib\site-packages\django\contrib\auth\decorators.py", line 22, in _wrapped_view
    return view_func(request, *args, **kwargs)
  File "C:\uav\frontend\views\all_job\frontend_all_job_recommend_rtree.py", line 41, in frontend_all_job_recommend_rtree
    +'\n%s' % traceback.format_exc())
  File "C:\Python34\lib\traceback.py", line 256, in format_exc
    return "".join(format_exception(*sys.exc_info(), limit=limit, chain=chain))
  File "C:\Python34\lib\traceback.py", line 181, in format_exception
    return list(_format_exception_iter(etype, value, tb, limit, chain))
  File "C:\Python34\lib\traceback.py", line 146, in _format_exception_iter
    for value, tb in values:
  File "C:\Python34\lib\traceback.py", line 125, in _iter_chain
    context = exc.__context__
AttributeError: 'NoneType' object has no attribute '__context__'
ERROR 2017-01-09 14:42:11,786 Internal Server Error: /alljobsrecommend/
Traceback (most recent call last):
  File "C:\Python34\lib\site-packages\django\core\handlers\base.py", line 132, in get_response
    response = wrapped_callback(request, *callback_args, **callback_kwargs)
  File "C:\Python34\lib\site-packages\django\contrib\auth\decorators.py", line 22, in _wrapped_view
    return view_func(request, *args, **kwargs)
  File "C:\uav\frontend\views\all_job\frontend_all_job_recommend_rtree.py", line 41, in frontend_all_job_recommend_rtree
    +'\n%s' % traceback.format_exc())
  File "C:\Python34\lib\traceback.py", line 256, in format_exc
    return "".join(format_exception(*sys.exc_info(), limit=limit, chain=chain))
  File "C:\Python34\lib\traceback.py", line 181, in format_exception
    return list(_format_exception_iter(etype, value, tb, limit, chain))
  File "C:\Python34\lib\traceback.py", line 146, in _format_exception_iter
    for value, tb in values:
  File "C:\Python34\lib\traceback.py", line 125, in _iter_chain
    context = exc.__context__
AttributeError: 'NoneType' object has no attribute '__context__'
WARNING 2017-01-09 14:42:12,087 Not Found: /favicon.ico
WARNING 2017-01-09 14:42:12,087 Not Found: /favicon.ico
ERROR 2017-01-09 14:45:02,290 Internal Server Error: /alljobsrecommend/
Traceback (most recent call last):
  File "C:\Python34\lib\site-packages\django\core\handlers\base.py", line 132, in get_response
    response = wrapped_callback(request, *callback_args, **callback_kwargs)
  File "C:\Python34\lib\site-packages\django\contrib\auth\decorators.py", line 22, in _wrapped_view
    return view_func(request, *args, **kwargs)
  File "C:\uav\frontend\views\all_job\frontend_all_job_recommend_rtree.py", line 41, in frontend_all_job_recommend_rtree
    +'\n%s' % traceback.format_exc())
  File "C:\Python34\lib\traceback.py", line 256, in format_exc
    return "".join(format_exception(*sys.exc_info(), limit=limit, chain=chain))
  File "C:\Python34\lib\traceback.py", line 181, in format_exception
    return list(_format_exception_iter(etype, value, tb, limit, chain))
  File "C:\Python34\lib\traceback.py", line 146, in _format_exception_iter
    for value, tb in values:
  File "C:\Python34\lib\traceback.py", line 125, in _iter_chain
    context = exc.__context__
AttributeError: 'NoneType' object has no attribute '__context__'
ERROR 2017-01-09 14:45:02,290 Internal Server Error: /alljobsrecommend/
Traceback (most recent call last):
  File "C:\Python34\lib\site-packages\django\core\handlers\base.py", line 132, in get_response
    response = wrapped_callback(request, *callback_args, **callback_kwargs)
  File "C:\Python34\lib\site-packages\django\contrib\auth\decorators.py", line 22, in _wrapped_view
    return view_func(request, *args, **kwargs)
  File "C:\uav\frontend\views\all_job\frontend_all_job_recommend_rtree.py", line 41, in frontend_all_job_recommend_rtree
    +'\n%s' % traceback.format_exc())
  File "C:\Python34\lib\traceback.py", line 256, in format_exc
    return "".join(format_exception(*sys.exc_info(), limit=limit, chain=chain))
  File "C:\Python34\lib\traceback.py", line 181, in format_exception
    return list(_format_exception_iter(etype, value, tb, limit, chain))
  File "C:\Python34\lib\traceback.py", line 146, in _format_exception_iter
    for value, tb in values:
  File "C:\Python34\lib\traceback.py", line 125, in _iter_chain
    context = exc.__context__
AttributeError: 'NoneType' object has no attribute '__context__'
ERROR 2017-01-09 14:45:03,337 Internal Server Error: /alljobsrecommend/
Traceback (most recent call last):
  File "C:\Python34\lib\site-packages\django\core\handlers\base.py", line 132, in get_response
    response = wrapped_callback(request, *callback_args, **callback_kwargs)
  File "C:\Python34\lib\site-packages\django\contrib\auth\decorators.py", line 22, in _wrapped_view
    return view_func(request, *args, **kwargs)
  File "C:\uav\frontend\views\all_job\frontend_all_job_recommend_rtree.py", line 41, in frontend_all_job_recommend_rtree
    +'\n%s' % traceback.format_exc())
  File "C:\Python34\lib\traceback.py", line 256, in format_exc
    return "".join(format_exception(*sys.exc_info(), limit=limit, chain=chain))
  File "C:\Python34\lib\traceback.py", line 181, in format_exception
    return list(_format_exception_iter(etype, value, tb, limit, chain))
  File "C:\Python34\lib\traceback.py", line 146, in _format_exception_iter
    for value, tb in values:
  File "C:\Python34\lib\traceback.py", line 125, in _iter_chain
    context = exc.__context__
AttributeError: 'NoneType' object has no attribute '__context__'
ERROR 2017-01-09 14:45:03,337 Internal Server Error: /alljobsrecommend/
Traceback (most recent call last):
  File "C:\Python34\lib\site-packages\django\core\handlers\base.py", line 132, in get_response
    response = wrapped_callback(request, *callback_args, **callback_kwargs)
  File "C:\Python34\lib\site-packages\django\contrib\auth\decorators.py", line 22, in _wrapped_view
    return view_func(request, *args, **kwargs)
  File "C:\uav\frontend\views\all_job\frontend_all_job_recommend_rtree.py", line 41, in frontend_all_job_recommend_rtree
    +'\n%s' % traceback.format_exc())
  File "C:\Python34\lib\traceback.py", line 256, in format_exc
    return "".join(format_exception(*sys.exc_info(), limit=limit, chain=chain))
  File "C:\Python34\lib\traceback.py", line 181, in format_exception
    return list(_format_exception_iter(etype, value, tb, limit, chain))
  File "C:\Python34\lib\traceback.py", line 146, in _format_exception_iter
    for value, tb in values:
  File "C:\Python34\lib\traceback.py", line 125, in _iter_chain
    context = exc.__context__
AttributeError: 'NoneType' object has no attribute '__context__'
ERROR 2017-01-09 14:51:13,824 Internal Server Error: /alljobsrecommend/
Traceback (most recent call last):
  File "C:\Python34\lib\site-packages\django\core\handlers\base.py", line 151, in get_response
    % (callback.__module__, view_name))
ValueError: The view frontend.views.all_job.frontend_all_job_recommend_rtree.frontend_all_job_recommend_rtree didn't return an HttpResponse object. It returned None instead.
ERROR 2017-01-09 14:51:13,824 Internal Server Error: /alljobsrecommend/
Traceback (most recent call last):
  File "C:\Python34\lib\site-packages\django\core\handlers\base.py", line 151, in get_response
    % (callback.__module__, view_name))
ValueError: The view frontend.views.all_job.frontend_all_job_recommend_rtree.frontend_all_job_recommend_rtree didn't return an HttpResponse object. It returned None instead.
ERROR 2017-01-09 14:53:15,106 Internal Server Error: /alljobsrecommend/
Traceback (most recent call last):
  File "C:\Python34\lib\site-packages\django\core\handlers\base.py", line 132, in get_response
    response = wrapped_callback(request, *callback_args, **callback_kwargs)
  File "C:\Python34\lib\site-packages\django\contrib\auth\decorators.py", line 22, in _wrapped_view
    return view_func(request, *args, **kwargs)
  File "C:\uav\frontend\views\all_job\frontend_all_job_recommend_rtree.py", line 28, in frontend_all_job_recommend_rtree
    j = Rtree_Jobs_Recommend(nowuser)
  File "C:\uav\common\myRtree.py", line 20, in Rtree_Jobs_Recommend
    j,temp,border_temp = {}
ValueError: need more than 0 values to unpack
ERROR 2017-01-09 14:53:15,106 Internal Server Error: /alljobsrecommend/
Traceback (most recent call last):
  File "C:\Python34\lib\site-packages\django\core\handlers\base.py", line 132, in get_response
    response = wrapped_callback(request, *callback_args, **callback_kwargs)
  File "C:\Python34\lib\site-packages\django\contrib\auth\decorators.py", line 22, in _wrapped_view
    return view_func(request, *args, **kwargs)
  File "C:\uav\frontend\views\all_job\frontend_all_job_recommend_rtree.py", line 28, in frontend_all_job_recommend_rtree
    j = Rtree_Jobs_Recommend(nowuser)
  File "C:\uav\common\myRtree.py", line 20, in Rtree_Jobs_Recommend
    j,temp,border_temp = {}
ValueError: need more than 0 values to unpack
ERROR 2017-01-09 14:56:20,651 Internal Server Error: /alljobsrecommend/
Traceback (most recent call last):
  File "C:\Python34\lib\site-packages\django\core\handlers\base.py", line 132, in get_response
    response = wrapped_callback(request, *callback_args, **callback_kwargs)
  File "C:\Python34\lib\site-packages\django\contrib\auth\decorators.py", line 22, in _wrapped_view
    return view_func(request, *args, **kwargs)
  File "C:\uav\frontend\views\all_job\frontend_all_job_recommend_rtree.py", line 28, in frontend_all_job_recommend_rtree
    j = Rtree_Jobs_Recommend(nowuser)
  File "C:\uav\common\myRtree.py", line 27, in Rtree_Jobs_Recommend
    district = Nation.objects.get(code=job.nation)
NameError: name 'job' is not defined
ERROR 2017-01-09 14:56:20,651 Internal Server Error: /alljobsrecommend/
Traceback (most recent call last):
  File "C:\Python34\lib\site-packages\django\core\handlers\base.py", line 132, in get_response
    response = wrapped_callback(request, *callback_args, **callback_kwargs)
  File "C:\Python34\lib\site-packages\django\contrib\auth\decorators.py", line 22, in _wrapped_view
    return view_func(request, *args, **kwargs)
  File "C:\uav\frontend\views\all_job\frontend_all_job_recommend_rtree.py", line 28, in frontend_all_job_recommend_rtree
    j = Rtree_Jobs_Recommend(nowuser)
  File "C:\uav\common\myRtree.py", line 27, in Rtree_Jobs_Recommend
    district = Nation.objects.get(code=job.nation)
NameError: name 'job' is not defined
ERROR 2017-01-09 14:58:03,929 Internal Server Error: /alljobsrecommend/
Traceback (most recent call last):
  File "C:\Python34\lib\site-packages\django\core\handlers\base.py", line 119, in get_response
    resolver_match = resolver.resolve(request.path_info)
  File "C:\Python34\lib\site-packages\django\core\urlresolvers.py", line 368, in resolve
    sub_match = pattern.resolve(new_path)
  File "C:\Python34\lib\site-packages\django\core\urlresolvers.py", line 240, in resolve
    return ResolverMatch(self.callback, args, kwargs, self.name)
  File "C:\Python34\lib\site-packages\django\core\urlresolvers.py", line 247, in callback
    self._callback = get_callable(self._callback_str)
  File "C:\Python34\lib\functools.py", line 448, in wrapper
    result = user_function(*args, **kwds)
  File "C:\Python34\lib\site-packages\django\core\urlresolvers.py", line 106, in get_callable
    mod = import_module(mod_name)
  File "C:\Python34\lib\importlib\__init__.py", line 109, in import_module
    return _bootstrap._gcd_import(name[level:], package, level)
  File "<frozen importlib._bootstrap>", line 2254, in _gcd_import
  File "<frozen importlib._bootstrap>", line 2237, in _find_and_load
  File "<frozen importlib._bootstrap>", line 2226, in _find_and_load_unlocked
  File "<frozen importlib._bootstrap>", line 1200, in _load_unlocked
  File "<frozen importlib._bootstrap>", line 1129, in _exec
  File "<frozen importlib._bootstrap>", line 1471, in exec_module
  File "<frozen importlib._bootstrap>", line 321, in _call_with_frames_removed
  File "C:\uav\frontend\views\all_job\frontend_all_job_recommend_rtree.py", line 13, in <module>
    from common.myRtree import *
  File "C:\uav\common\myRtree.py", line 20
    generator=(for i in job_list)
                 ^
SyntaxError: invalid syntax
ERROR 2017-01-09 14:58:03,929 Internal Server Error: /alljobsrecommend/
Traceback (most recent call last):
  File "C:\Python34\lib\site-packages\django\core\handlers\base.py", line 119, in get_response
    resolver_match = resolver.resolve(request.path_info)
  File "C:\Python34\lib\site-packages\django\core\urlresolvers.py", line 368, in resolve
    sub_match = pattern.resolve(new_path)
  File "C:\Python34\lib\site-packages\django\core\urlresolvers.py", line 240, in resolve
    return ResolverMatch(self.callback, args, kwargs, self.name)
  File "C:\Python34\lib\site-packages\django\core\urlresolvers.py", line 247, in callback
    self._callback = get_callable(self._callback_str)
  File "C:\Python34\lib\functools.py", line 448, in wrapper
    result = user_function(*args, **kwds)
  File "C:\Python34\lib\site-packages\django\core\urlresolvers.py", line 106, in get_callable
    mod = import_module(mod_name)
  File "C:\Python34\lib\importlib\__init__.py", line 109, in import_module
    return _bootstrap._gcd_import(name[level:], package, level)
  File "<frozen importlib._bootstrap>", line 2254, in _gcd_import
  File "<frozen importlib._bootstrap>", line 2237, in _find_and_load
  File "<frozen importlib._bootstrap>", line 2226, in _find_and_load_unlocked
  File "<frozen importlib._bootstrap>", line 1200, in _load_unlocked
  File "<frozen importlib._bootstrap>", line 1129, in _exec
  File "<frozen importlib._bootstrap>", line 1471, in exec_module
  File "<frozen importlib._bootstrap>", line 321, in _call_with_frames_removed
  File "C:\uav\frontend\views\all_job\frontend_all_job_recommend_rtree.py", line 13, in <module>
    from common.myRtree import *
  File "C:\uav\common\myRtree.py", line 20
    generator=(for i in job_list)
                 ^
SyntaxError: invalid syntax
ERROR 2017-01-09 14:58:37,434 Internal Server Error: /alljobsrecommend/
Traceback (most recent call last):
  File "C:\Python34\lib\site-packages\django\core\handlers\base.py", line 119, in get_response
    resolver_match = resolver.resolve(request.path_info)
  File "C:\Python34\lib\site-packages\django\core\urlresolvers.py", line 368, in resolve
    sub_match = pattern.resolve(new_path)
  File "C:\Python34\lib\site-packages\django\core\urlresolvers.py", line 240, in resolve
    return ResolverMatch(self.callback, args, kwargs, self.name)
  File "C:\Python34\lib\site-packages\django\core\urlresolvers.py", line 247, in callback
    self._callback = get_callable(self._callback_str)
  File "C:\Python34\lib\functools.py", line 448, in wrapper
    result = user_function(*args, **kwds)
  File "C:\Python34\lib\site-packages\django\core\urlresolvers.py", line 106, in get_callable
    mod = import_module(mod_name)
  File "C:\Python34\lib\importlib\__init__.py", line 109, in import_module
    return _bootstrap._gcd_import(name[level:], package, level)
  File "<frozen importlib._bootstrap>", line 2254, in _gcd_import
  File "<frozen importlib._bootstrap>", line 2237, in _find_and_load
  File "<frozen importlib._bootstrap>", line 2226, in _find_and_load_unlocked
  File "<frozen importlib._bootstrap>", line 1200, in _load_unlocked
  File "<frozen importlib._bootstrap>", line 1129, in _exec
  File "<frozen importlib._bootstrap>", line 1471, in exec_module
  File "<frozen importlib._bootstrap>", line 321, in _call_with_frames_removed
  File "C:\uav\frontend\views\all_job\frontend_all_job_recommend_rtree.py", line 13, in <module>
    from common.myRtree import *
  File "C:\uav\common\myRtree.py", line 20
    generator=(for i in job_list)
                 ^
SyntaxError: invalid syntax
ERROR 2017-01-09 14:58:37,434 Internal Server Error: /alljobsrecommend/
Traceback (most recent call last):
  File "C:\Python34\lib\site-packages\django\core\handlers\base.py", line 119, in get_response
    resolver_match = resolver.resolve(request.path_info)
  File "C:\Python34\lib\site-packages\django\core\urlresolvers.py", line 368, in resolve
    sub_match = pattern.resolve(new_path)
  File "C:\Python34\lib\site-packages\django\core\urlresolvers.py", line 240, in resolve
    return ResolverMatch(self.callback, args, kwargs, self.name)
  File "C:\Python34\lib\site-packages\django\core\urlresolvers.py", line 247, in callback
    self._callback = get_callable(self._callback_str)
  File "C:\Python34\lib\functools.py", line 448, in wrapper
    result = user_function(*args, **kwds)
  File "C:\Python34\lib\site-packages\django\core\urlresolvers.py", line 106, in get_callable
    mod = import_module(mod_name)
  File "C:\Python34\lib\importlib\__init__.py", line 109, in import_module
    return _bootstrap._gcd_import(name[level:], package, level)
  File "<frozen importlib._bootstrap>", line 2254, in _gcd_import
  File "<frozen importlib._bootstrap>", line 2237, in _find_and_load
  File "<frozen importlib._bootstrap>", line 2226, in _find_and_load_unlocked
  File "<frozen importlib._bootstrap>", line 1200, in _load_unlocked
  File "<frozen importlib._bootstrap>", line 1129, in _exec
  File "<frozen importlib._bootstrap>", line 1471, in exec_module
  File "<frozen importlib._bootstrap>", line 321, in _call_with_frames_removed
  File "C:\uav\frontend\views\all_job\frontend_all_job_recommend_rtree.py", line 13, in <module>
    from common.myRtree import *
  File "C:\uav\common\myRtree.py", line 20
    generator=(for i in job_list)
                 ^
SyntaxError: invalid syntax
ERROR 2017-01-09 14:58:56,947 Internal Server Error: /alljobsrecommend/
Traceback (most recent call last):
  File "C:\Python34\lib\site-packages\django\core\handlers\base.py", line 119, in get_response
    resolver_match = resolver.resolve(request.path_info)
  File "C:\Python34\lib\site-packages\django\core\urlresolvers.py", line 368, in resolve
    sub_match = pattern.resolve(new_path)
  File "C:\Python34\lib\site-packages\django\core\urlresolvers.py", line 240, in resolve
    return ResolverMatch(self.callback, args, kwargs, self.name)
  File "C:\Python34\lib\site-packages\django\core\urlresolvers.py", line 247, in callback
    self._callback = get_callable(self._callback_str)
  File "C:\Python34\lib\functools.py", line 448, in wrapper
    result = user_function(*args, **kwds)
  File "C:\Python34\lib\site-packages\django\core\urlresolvers.py", line 106, in get_callable
    mod = import_module(mod_name)
  File "C:\Python34\lib\importlib\__init__.py", line 109, in import_module
    return _bootstrap._gcd_import(name[level:], package, level)
  File "<frozen importlib._bootstrap>", line 2254, in _gcd_import
  File "<frozen importlib._bootstrap>", line 2237, in _find_and_load
  File "<frozen importlib._bootstrap>", line 2226, in _find_and_load_unlocked
  File "<frozen importlib._bootstrap>", line 1200, in _load_unlocked
  File "<frozen importlib._bootstrap>", line 1129, in _exec
  File "<frozen importlib._bootstrap>", line 1471, in exec_module
  File "<frozen importlib._bootstrap>", line 321, in _call_with_frames_removed
  File "C:\uav\frontend\views\all_job\frontend_all_job_recommend_rtree.py", line 13, in <module>
    from common.myRtree import *
  File "C:\uav\common\myRtree.py", line 20
    generator=(for i in job_list)
                 ^
SyntaxError: invalid syntax
ERROR 2017-01-09 14:58:56,947 Internal Server Error: /alljobsrecommend/
Traceback (most recent call last):
  File "C:\Python34\lib\site-packages\django\core\handlers\base.py", line 119, in get_response
    resolver_match = resolver.resolve(request.path_info)
  File "C:\Python34\lib\site-packages\django\core\urlresolvers.py", line 368, in resolve
    sub_match = pattern.resolve(new_path)
  File "C:\Python34\lib\site-packages\django\core\urlresolvers.py", line 240, in resolve
    return ResolverMatch(self.callback, args, kwargs, self.name)
  File "C:\Python34\lib\site-packages\django\core\urlresolvers.py", line 247, in callback
    self._callback = get_callable(self._callback_str)
  File "C:\Python34\lib\functools.py", line 448, in wrapper
    result = user_function(*args, **kwds)
  File "C:\Python34\lib\site-packages\django\core\urlresolvers.py", line 106, in get_callable
    mod = import_module(mod_name)
  File "C:\Python34\lib\importlib\__init__.py", line 109, in import_module
    return _bootstrap._gcd_import(name[level:], package, level)
  File "<frozen importlib._bootstrap>", line 2254, in _gcd_import
  File "<frozen importlib._bootstrap>", line 2237, in _find_and_load
  File "<frozen importlib._bootstrap>", line 2226, in _find_and_load_unlocked
  File "<frozen importlib._bootstrap>", line 1200, in _load_unlocked
  File "<frozen importlib._bootstrap>", line 1129, in _exec
  File "<frozen importlib._bootstrap>", line 1471, in exec_module
  File "<frozen importlib._bootstrap>", line 321, in _call_with_frames_removed
  File "C:\uav\frontend\views\all_job\frontend_all_job_recommend_rtree.py", line 13, in <module>
    from common.myRtree import *
  File "C:\uav\common\myRtree.py", line 20
    generator=(for i in job_list)
                 ^
SyntaxError: invalid syntax
ERROR 2017-01-09 14:58:58,455 Internal Server Error: /alljobsrecommend/
Traceback (most recent call last):
  File "C:\Python34\lib\site-packages\django\core\handlers\base.py", line 119, in get_response
    resolver_match = resolver.resolve(request.path_info)
  File "C:\Python34\lib\site-packages\django\core\urlresolvers.py", line 368, in resolve
    sub_match = pattern.resolve(new_path)
  File "C:\Python34\lib\site-packages\django\core\urlresolvers.py", line 240, in resolve
    return ResolverMatch(self.callback, args, kwargs, self.name)
  File "C:\Python34\lib\site-packages\django\core\urlresolvers.py", line 247, in callback
    self._callback = get_callable(self._callback_str)
  File "C:\Python34\lib\functools.py", line 448, in wrapper
    result = user_function(*args, **kwds)
  File "C:\Python34\lib\site-packages\django\core\urlresolvers.py", line 106, in get_callable
    mod = import_module(mod_name)
  File "C:\Python34\lib\importlib\__init__.py", line 109, in import_module
    return _bootstrap._gcd_import(name[level:], package, level)
  File "<frozen importlib._bootstrap>", line 2254, in _gcd_import
  File "<frozen importlib._bootstrap>", line 2237, in _find_and_load
  File "<frozen importlib._bootstrap>", line 2226, in _find_and_load_unlocked
  File "<frozen importlib._bootstrap>", line 1200, in _load_unlocked
  File "<frozen importlib._bootstrap>", line 1129, in _exec
  File "<frozen importlib._bootstrap>", line 1471, in exec_module
  File "<frozen importlib._bootstrap>", line 321, in _call_with_frames_removed
  File "C:\uav\frontend\views\all_job\frontend_all_job_recommend_rtree.py", line 13, in <module>
    from common.myRtree import *
  File "C:\uav\common\myRtree.py", line 20
    generator=(for i in job_list)
                 ^
SyntaxError: invalid syntax
ERROR 2017-01-09 14:58:58,455 Internal Server Error: /alljobsrecommend/
Traceback (most recent call last):
  File "C:\Python34\lib\site-packages\django\core\handlers\base.py", line 119, in get_response
    resolver_match = resolver.resolve(request.path_info)
  File "C:\Python34\lib\site-packages\django\core\urlresolvers.py", line 368, in resolve
    sub_match = pattern.resolve(new_path)
  File "C:\Python34\lib\site-packages\django\core\urlresolvers.py", line 240, in resolve
    return ResolverMatch(self.callback, args, kwargs, self.name)
  File "C:\Python34\lib\site-packages\django\core\urlresolvers.py", line 247, in callback
    self._callback = get_callable(self._callback_str)
  File "C:\Python34\lib\functools.py", line 448, in wrapper
    result = user_function(*args, **kwds)
  File "C:\Python34\lib\site-packages\django\core\urlresolvers.py", line 106, in get_callable
    mod = import_module(mod_name)
  File "C:\Python34\lib\importlib\__init__.py", line 109, in import_module
    return _bootstrap._gcd_import(name[level:], package, level)
  File "<frozen importlib._bootstrap>", line 2254, in _gcd_import
  File "<frozen importlib._bootstrap>", line 2237, in _find_and_load
  File "<frozen importlib._bootstrap>", line 2226, in _find_and_load_unlocked
  File "<frozen importlib._bootstrap>", line 1200, in _load_unlocked
  File "<frozen importlib._bootstrap>", line 1129, in _exec
  File "<frozen importlib._bootstrap>", line 1471, in exec_module
  File "<frozen importlib._bootstrap>", line 321, in _call_with_frames_removed
  File "C:\uav\frontend\views\all_job\frontend_all_job_recommend_rtree.py", line 13, in <module>
    from common.myRtree import *
  File "C:\uav\common\myRtree.py", line 20
    generator=(for i in job_list)
                 ^
SyntaxError: invalid syntax
ERROR 2017-01-09 15:14:10,395 Internal Server Error: /alljobsrecommend/
Traceback (most recent call last):
  File "C:\Python34\lib\site-packages\django\core\handlers\base.py", line 132, in get_response
    response = wrapped_callback(request, *callback_args, **callback_kwargs)
  File "C:\Python34\lib\site-packages\django\contrib\auth\decorators.py", line 22, in _wrapped_view
    return view_func(request, *args, **kwargs)
  File "C:\uav\frontend\views\all_job\frontend_all_job_recommend_rtree.py", line 28, in frontend_all_job_recommend_rtree
    j = Rtree_Jobs_Recommend(nowuser)
  File "C:\uav\common\myRtree.py", line 20, in Rtree_Jobs_Recommend
    g = job_list_generator()
TypeError: job_list_generator() missing 1 required positional argument: 'job_list'
ERROR 2017-01-09 15:14:10,395 Internal Server Error: /alljobsrecommend/
Traceback (most recent call last):
  File "C:\Python34\lib\site-packages\django\core\handlers\base.py", line 132, in get_response
    response = wrapped_callback(request, *callback_args, **callback_kwargs)
  File "C:\Python34\lib\site-packages\django\contrib\auth\decorators.py", line 22, in _wrapped_view
    return view_func(request, *args, **kwargs)
  File "C:\uav\frontend\views\all_job\frontend_all_job_recommend_rtree.py", line 28, in frontend_all_job_recommend_rtree
    j = Rtree_Jobs_Recommend(nowuser)
  File "C:\uav\common\myRtree.py", line 20, in Rtree_Jobs_Recommend
    g = job_list_generator()
TypeError: job_list_generator() missing 1 required positional argument: 'job_list'
ERROR 2017-01-09 15:25:21,629 Internal Server Error: /alljobsrecommend/
Traceback (most recent call last):
  File "C:\Python34\lib\site-packages\django\core\handlers\base.py", line 132, in get_response
    response = wrapped_callback(request, *callback_args, **callback_kwargs)
  File "C:\Python34\lib\site-packages\django\contrib\auth\decorators.py", line 22, in _wrapped_view
    return view_func(request, *args, **kwargs)
  File "C:\uav\frontend\views\all_job\frontend_all_job_recommend_rtree.py", line 28, in frontend_all_job_recommend_rtree
    j = Rtree_Jobs_Recommend(nowuser)
  File "C:\uav\common\myRtree.py", line 21, in Rtree_Jobs_Recommend
    for job_border in job_list_enerator:
  File "C:\uav\common\myRtree.py", line 43, in Job_List_Generator
    job = Job.objects.get(id=g)
NameError: name 'g' is not defined
ERROR 2017-01-09 15:25:21,629 Internal Server Error: /alljobsrecommend/
Traceback (most recent call last):
  File "C:\Python34\lib\site-packages\django\core\handlers\base.py", line 132, in get_response
    response = wrapped_callback(request, *callback_args, **callback_kwargs)
  File "C:\Python34\lib\site-packages\django\contrib\auth\decorators.py", line 22, in _wrapped_view
    return view_func(request, *args, **kwargs)
  File "C:\uav\frontend\views\all_job\frontend_all_job_recommend_rtree.py", line 28, in frontend_all_job_recommend_rtree
    j = Rtree_Jobs_Recommend(nowuser)
  File "C:\uav\common\myRtree.py", line 21, in Rtree_Jobs_Recommend
    for job_border in job_list_enerator:
  File "C:\uav\common\myRtree.py", line 43, in Job_List_Generator
    job = Job.objects.get(id=g)
NameError: name 'g' is not defined
ERROR 2017-01-09 15:25:35,598 Internal Server Error: /alljobsrecommend/
Traceback (most recent call last):
  File "C:\Python34\lib\site-packages\django\core\handlers\base.py", line 132, in get_response
    response = wrapped_callback(request, *callback_args, **callback_kwargs)
  File "C:\Python34\lib\site-packages\django\contrib\auth\decorators.py", line 22, in _wrapped_view
    return view_func(request, *args, **kwargs)
  File "C:\uav\frontend\views\all_job\frontend_all_job_recommend_rtree.py", line 28, in frontend_all_job_recommend_rtree
    j = Rtree_Jobs_Recommend(nowuser)
  File "C:\uav\common\myRtree.py", line 21, in Rtree_Jobs_Recommend
    for job_border in job_list_enerator:
  File "C:\uav\common\myRtree.py", line 43, in Job_List_Generator
    job = Job.objects.get(id=i)
NameError: name 'g' is not defined
ERROR 2017-01-09 15:25:35,598 Internal Server Error: /alljobsrecommend/
Traceback (most recent call last):
  File "C:\Python34\lib\site-packages\django\core\handlers\base.py", line 132, in get_response
    response = wrapped_callback(request, *callback_args, **callback_kwargs)
  File "C:\Python34\lib\site-packages\django\contrib\auth\decorators.py", line 22, in _wrapped_view
    return view_func(request, *args, **kwargs)
  File "C:\uav\frontend\views\all_job\frontend_all_job_recommend_rtree.py", line 28, in frontend_all_job_recommend_rtree
    j = Rtree_Jobs_Recommend(nowuser)
  File "C:\uav\common\myRtree.py", line 21, in Rtree_Jobs_Recommend
    for job_border in job_list_enerator:
  File "C:\uav\common\myRtree.py", line 43, in Job_List_Generator
    job = Job.objects.get(id=i)
NameError: name 'g' is not defined
ERROR 2017-01-09 15:25:38,262 Internal Server Error: /alljobsrecommend/
Traceback (most recent call last):
  File "C:\Python34\lib\site-packages\django\core\handlers\base.py", line 132, in get_response
    response = wrapped_callback(request, *callback_args, **callback_kwargs)
  File "C:\Python34\lib\site-packages\django\contrib\auth\decorators.py", line 22, in _wrapped_view
    return view_func(request, *args, **kwargs)
  File "C:\uav\frontend\views\all_job\frontend_all_job_recommend_rtree.py", line 28, in frontend_all_job_recommend_rtree
    j = Rtree_Jobs_Recommend(nowuser)
  File "C:\uav\common\myRtree.py", line 29, in Rtree_Jobs_Recommend
    district = Nation.objects.get(code=job.nation)
NameError: name 'job' is not defined
ERROR 2017-01-09 15:25:38,262 Internal Server Error: /alljobsrecommend/
Traceback (most recent call last):
  File "C:\Python34\lib\site-packages\django\core\handlers\base.py", line 132, in get_response
    response = wrapped_callback(request, *callback_args, **callback_kwargs)
  File "C:\Python34\lib\site-packages\django\contrib\auth\decorators.py", line 22, in _wrapped_view
    return view_func(request, *args, **kwargs)
  File "C:\uav\frontend\views\all_job\frontend_all_job_recommend_rtree.py", line 28, in frontend_all_job_recommend_rtree
    j = Rtree_Jobs_Recommend(nowuser)
  File "C:\uav\common\myRtree.py", line 29, in Rtree_Jobs_Recommend
    district = Nation.objects.get(code=job.nation)
NameError: name 'job' is not defined
